File: MAE_3272/Module_1/Aluminum.csv
1/28/2016,
12:25 PM,
Sampling Frequency:,10Hz
Group:,TA
Extensometer:,E85191
Sample:,T0 Aluminum
Sample width [inch]:,0.494
Sample thickness [inch]:,0.119
--------,--------
,
Extensometer,Load
[Inches],[Lbs]
0,-0.2
0,0.2
-0.00001,-0.1
-0.00001,0.3
0,0.9
0,0.2
-0.00001,0.7
0,0.2
0,0.7
0.00001,0.3
0,-0.2
0,0.1
0.00001,-0.2
0.00001,-1.3
-0.00001,0.5
0.00001,0.6
-0.00001,0
-0.00002,1.4
-0.00002,0
-0.00001,-1.1
0,0.3
0.00001,0
0,0
0,-0.6
-0.00001,-0.5
-0.00002,0.8
-0.00001,-0.1
0,1
-0.00001,1.3
0,1.6
0,3.1
0,3.1
0,4.1
0.00003,5.2
0.00002,6
0.00005,7.7
0.00004,8.8
0.00005,10.2
0.00005,10.1
0.00003,10.9
0.00004,11.9
0.00008,12.5
0.00009,13.8
0.00011,14.4
0.00011,16
0.00012,18.1
0.00014,18.8
0.00015,20.3
0.00015,21.8
0.00016,24
0.00017,26.1
0.00018,27.9
0.0002,29.7
0.0002,31.7
0.00022,33.1
0.0002,35.6
0.00023,38
0.00024,41.3
0.00026,43.5
0.00026,45.9
0.00027,49.5
0.00029,51.4
0.00032,54.7
0.00032,57.8
0.00033,60.1
0.00035,62.9
0.00034,66.5
0.00038,70
0.00037,71.7
0.00039,75.7
0.00042,78.8
0.00041,81.8
0.00043,87
0.00044,89.5
0.00046,93.9
0.00048,97
0.00049,101.4
0.00051,105.4
0.00053,108.2
0.00053,112.9
0.00054,117.1
0.00057,120
0.00057,124.6
0.0006,129.2
0.0006,132
0.00063,137
0.00064,141
0.00066,145.1
0.00069,149.3
0.00069,153.3
0.00072,157.8
0.00073,160.9
0.00077,165.4
0.00078,170.2
0.00084,174.7
0.00088,176.9
0.00091,182.3
0.00096,186.6
0.001,189.8
0.00105,192.2
0.0011,196.8
0.00115,199.5
0.00122,203.3
0.00128,204.7
0.00136,208.4
0.00145,212.3
0.00152,215.7
0.0016,218.1
0.00169,220.5
0.00177,224.5
0.00186,227.1
0.00195,229.8
0.00206,232.6
0.00213,236
0.00222,238.5
0.00231,240.5
0.00243,242.8
0.00254,245.4
0.00266,248
0.00274,250.3
0.00286,253.2
0.00296,255
0.00306,257.3
0.00317,259.3
0.00328,261.3
0.0034,264.4
0.00352,265.6
0.00365,268.5
0.00375,271.4
0.00389,274.1
0.004,275.7
0.00412,277.5
0.00426,279.8
0.00438,282.2
0.00449,284.3
0.00463,285.8
0.00476,288
0.00489,290
0.00501,292.5
0.00515,293.7
0.00528,296.4
0.0054,298.1
0.00553,301.1
0.00567,302.3
0.00578,305.3
0.00593,306.4
0.00605,307.8
0.0062,310.5
0.00635,312.8
0.00649,314.1
0.00661,315.6
0.00678,316.7
0.00689,319.7
0.00704,321.1
0.00717,322.9
0.00731,325.1
0.00744,326.9
0.0076,327.7
0.00773,329.3
0.00787,331.9
0.00803,333.8
0.00816,336.2
0.00831,338.7
0.00846,339
0.0086,341.9
0.00877,343.7
0.00892,345
0.00905,346.8
0.00921,348.2
0.00935,349.4
0.0095,351.8
0.00964,352.8
0.0098,356.2
0.00993,357.9
0.01008,359.2
0.01024,361.6
0.01037,362.2
0.01053,364.4
0.01067,366.7
0.01081,367.5
0.01096,368.7
0.01113,371.2
0.01126,372.1
0.01141,374.5
0.01158,375.9
0.0117,377
0.01185,379.8
0.01201,380.8
0.01217,382.7
0.01231,384.3
0.01244,386.3
0.0126,387.1
0.01276,389.7
0.01294,391.9
0.01313,392.9
0.01333,396.2
0.01354,397.1
0.01373,399.9
0.01396,401.3
0.01417,404.2
0.01442,405.5
0.01469,408.7
0.01496,410.4
0.01524,413.9
0.01554,415.5
0.01581,418.2
0.01612,421.2
0.0164,425
0.01668,428
0.01699,430.2
0.01728,433.4
0.01757,435.7
0.01787,438.6
0.01818,440.7
0.01846,444.2
0.01875,446.2
0.01905,449.2
0.01935,452.8
0.01967,455.7
0.01997,457.1
0.02026,460.3
0.02056,463.9
0.02084,465.3
0.02115,468.9
0.02145,469.9
0.02176,473.2
0.02209,475
0.02238,478.6
0.02269,480.3
0.02302,482.8
0.02333,485.8
0.02365,488.9
0.02395,491.7
0.02429,493.8
0.02458,495.9
0.02491,498
0.02524,500.2
0.02557,503
0.0259,505.8
0.02621,508.4
0.02653,510.8
0.02684,512.7
0.02718,515.6
0.02751,518.3
0.02783,519.4
0.02816,523.3
0.02846,523.9
0.02882,527.7
0.02915,529.6
0.02947,531.3
0.0298,533.3
0.03012,535.8
0.03047,538.7
0.03081,541.1
0.03116,543
0.03151,545.1
0.03186,546.5
0.03217,549.5
0.03249,551.4
0.03281,554.1
0.03317,555.8
0.03354,557.4
0.03394,559.9
0.03431,562.1
0.03468,564.7
0.03497,565.9
0.03522,568.1
0.03554,570.2
0.03589,573
0.03632,573.8
0.03677,576.7
0.03724,578.7
0.03765,581.5
0.03801,583.1
0.03824,584.6
0.03843,586.7
0.03872,586.6
0.03909,591.9
0.03951,591.9
0.04,593.9
0.0405,596.1
0.04101,598.3
0.04148,601.4
0.04177,603.4
0.04195,603.4
0.04215,604.8
0.04246,608.6
0.0427,608.6
0.0432,610.9
0.04359,613.4
0.04415,612.4
0.0447,615.6
0.04521,619
0.04576,619.4
0.04615,625.9
0.04636,625.4
0.04659,625.6
0.04679,625.1
0.04709,630.3
0.04727,630.5
0.04772,631.3
0.04813,637
0.0487,635.6
0.04925,636.3
0.04985,636.9
0.05043,640.5
0.05102,641.7
0.05145,646.9
0.05179,647.8
0.052,647.8
0.05203,645.4
0.05214,653.5
0.05224,650.9
0.0527,653.3
0.05313,657.5
0.05375,654.2
0.05434,656.4
0.05494,658.8
0.05556,660.8
0.05619,662
0.05682,663.5
0.05736,666
0.05758,668.4
0.05771,669.7
0.05781,671.6
0.0579,670.8
0.05831,671.3
0.05871,673
0.05913,672.8
0.05965,674.9
0.06018,676.9
0.06071,678.7
0.0613,679.2
0.06191,680.5
0.06254,681.8
0.06318,684.4
0.06379,686.2
0.06401,687.5
0.06416,690.6
0.0645,688.7
0.06481,689.5
0.06488,691.8
0.06512,691.6
0.06563,693.2
0.06616,694.4
0.06673,696.3
0.06727,697.3
0.06786,699.2
0.06844,700.2
0.06905,700.8
0.06966,702.2
0.07027,703.1
0.07081,705.3
0.07119,706.1
0.07135,707.4
0.07144,708.7
0.07153,710.7
0.0716,712
0.07175,712.1
0.07227,709.6
0.07285,712.2
0.07343,714.1
0.07409,713.9
0.0747,716.3
0.07535,717
0.07603,720.1
0.07676,717.8
0.07738,718.8
0.07801,720
0.07866,721.2
0.07924,723.1
0.07943,725.6
0.07947,723.3
0.0796,728.1
0.07971,729.4
0.0799,728.9
0.08046,726.7
0.08104,728.6
0.08165,729.2
0.08229,731.1
0.08294,731.9
0.08363,732.7
0.08429,735.4
0.08499,734.7
0.08567,735.3
0.08631,735.6
0.08697,736.2
0.08746,737.2
0.08769,738.7
0.0879,740.2
0.08824,740.9
0.08839,743.1
0.08843,745.8
0.08845,747.7
0.08856,746.6
0.08875,740.5
0.08921,743.1
0.08983,743.8
0.09049,744.1
0.09116,745.8
0.09183,747.4
0.09248,747.5
0.09315,749.7
0.09386,748.6
0.09453,752.6
0.0952,750.4
0.09584,750.7
0.09649,752.5
0.09714,752.1
0.09778,754.5
0.09841,756.3
0.09894,758.1
0.09915,760.2
0.09922,759
0.09926,760.2
0.09941,761.5
0.09984,757.7
0.10047,759
0.10111,760
0.10176,761
0.10242,761.6
0.10311,763.1
0.10377,762.7
0.10445,764.8
0.10517,765.4
0.10597,764.2
0.10667,765.7
0.10734,767.7
0.10806,767.6
0.10873,768.5
0.10941,770.5
0.11,772.4
0.1103,769.7
0.11044,770.6
0.11065,775.1
0.1109,778.4
0.11104,773.8
0.1111,774.2
0.11115,775.4
0.11121,774.2
0.1113,770.1
0.11165,773.6
0.1121,776.1
0.1126,777.2
0.11326,772.9
0.1139,773.9
0.11456,773.6
0.11523,774.9
0.11591,775.4
0.11664,776.1
0.11735,777.3
0.11809,776.6
0.11883,777.7
0.11954,779.8
0.12027,780.9
0.12099,781.4
0.1217,781.4
0.12242,782.1
0.12315,784
0.12385,784.3
0.1245,785.8
0.12489,787.5
0.12506,787.8
0.12522,790.4
0.1254,793.3
0.12566,794.9
0.12636,785.4
0.12706,786.2
0.12776,787
0.12845,787.4
0.12914,787.7
0.1299,788.4
0.13073,785.7
0.13129,785.7
0.13143,787.3
0.13158,788.2
0.13189,790.4
0.13218,792.3
0.13243,795.7
0.13296,793.9
0.13365,794.6
0.13444,791.2
0.13513,793.1
0.13584,793.9
0.13655,793
0.13726,794.6
0.13798,795.2
0.13869,796.1
0.1394,797.4
0.14017,798
0.14087,798.8
0.14156,799
0.14204,800.4
0.14228,802
0.14242,804.1
0.1426,806.1
0.14313,795.2
0.14379,796.4
0.14449,797.6
0.14519,798.3
0.14586,797.2
0.14655,800.4
0.14728,799.6
0.14802,801.5
0.14876,802.2
0.14954,803.9
0.15038,803.7
0.15075,803.7
0.1508,804.2
0.15115,805.8
0.15155,806.5
0.15177,809.2
0.15192,808.2
0.15198,804.3
0.1521,805.4
0.15227,807.5
0.15286,802.5
0.15349,803.6
0.15414,804.5
0.15485,804.3
0.15555,805.2
0.15628,806.6
0.157,806.7
0.1577,808.9
0.15841,808.8
0.15911,808.2
0.1598,809
0.16051,809.5
0.16121,809.7
0.16188,810.3
0.16246,812.2
0.16294,811.6
0.16357,806.9
0.16426,809
0.16496,810.9
0.16566,810.6
0.16635,811.2
0.16701,810.7
0.16771,811.3
0.16838,811.6
0.16908,812.6
0.16975,811.7
0.17045,811.6
0.17113,813.8
0.17181,814.9
0.17253,815.1
0.17303,814.5
0.17317,816.5
0.1733,817.2
0.17346,818.4
0.17364,820.9
0.17394,817.5
0.17466,814.4
0.1754,814.2
0.17615,813.9
0.17684,815.3
0.17755,815.4
0.17825,815.6
0.17895,817.1
0.17965,817.8
0.18037,816.7
0.18108,818.4
0.1818,818.5
0.18251,818.8
0.18323,819.1
0.18397,819.1
0.18471,818.6
0.18526,815.8
0.18543,815
0.18551,815.9
0.18555,815.7
0.18559,822.7
0.18569,822.8
0.18602,822.8
0.18644,823.7
0.18689,825.7
0.18748,825.7
0.18815,824.9
0.18884,826.3
0.18953,825.9
0.19026,826.4
0.19098,824.9
0.19173,824.1
0.19248,822.5
0.19323,823.4
0.194,823.8
0.19472,821.5
0.1954,819.1
0.1961,819.2
0.19678,820.1
0.19753,820.1
0.19825,819.2
0.199,820
0.19975,818.7
0.20049,820.4
0.20121,820.2
0.20193,821.8
0.20266,820.9
0.20339,822
0.20415,822.4
0.20492,823.5
0.20569,824.4
0.20642,824.8
0.20697,824.3
0.20733,826
0.20755,826.8
0.20774,827.7
0.20791,828.2
0.20802,829.1
0.20809,830.3
0.20814,830.4
0.20822,835.9
0.20831,836.1
0.20851,836.7
0.20905,830
0.20971,829.9
0.21038,829.9
0.21104,829.9
0.21173,829.6
0.21247,828.2
0.21317,826.5
0.2139,828.2
0.21465,827.8
0.21544,827.5
0.2162,827.1
0.21694,828
0.21769,828.2
0.21843,830.1
0.21917,829
0.21989,829.4
0.22061,829.7
0.22132,829.8
0.22204,831.4
0.22274,831.4
0.22347,830.5
0.22422,830
0.22496,831.2
0.2257,831.2
0.22644,830.9
0.22718,831.7
0.22791,832.5
0.22864,832.7
0.22938,832.9
0.23012,832.3
0.23086,832.5
0.23162,832
0.23227,831
0.23273,831.3
0.23308,830.9
0.23332,831
0.23348,831.9
0.23362,834.8
0.23375,835.1
0.23395,837.3
0.23428,837.4
0.23471,837.2
0.23519,837.6
0.23581,836.6
0.2365,836.8
0.23724,837.3
0.23796,837
0.23873,837
0.23945,836
0.24017,837.1
0.24091,835.8
0.24161,836.7
0.24237,835.4
0.2431,835
0.24387,836.2
0.24462,835.5
0.24538,835.6
0.24612,836
0.24683,834.9
0.24759,833.6
0.24835,833.4
0.24904,833.8
0.24974,833.5
0.25049,833.3
0.2512,833.2
0.25196,832.9
0.25272,832.8
0.25349,832.8
0.25424,833
0.25499,833.3
0.25573,833.9
0.25647,835.2
0.25719,835.8
0.2579,835.4
0.25869,834.6
0.25943,835.4
0.25996,834.5
0.2602,836
0.26046,835.5
0.26079,835.1
0.26106,836.3
0.26126,838.1
0.26141,840.3
0.26156,839.4
0.26183,840.6
0.26233,840
0.26296,839.5
0.26364,839.9
0.26436,839.5
0.26509,838.9
0.26585,838.9
0.26658,838.2
0.26731,838.1
0.26807,837.8
0.2688,837.7
0.2695,838.2
0.27028,838.3
0.27102,837.5
0.27178,837.4
0.27254,838.7
0.27326,839.4
0.27398,838
0.2747,838.4
0.27546,839.9
0.27618,839.1
0.27692,839.4
0.27766,839.9
0.27837,839.7
0.27909,839.4
0.27984,839.4
0.28058,838.6
0.28133,839.5
0.28209,840.4
0.28285,841.2
0.28359,840.4
0.28434,841
0.28508,839.8
0.2858,841.1
0.28651,840.6
0.28725,841
0.28801,840.3
0.28874,841.9
0.28948,840.8
0.29024,840.8
0.29099,841.4
0.29172,841.3
0.29235,841.3
0.29282,841.1
0.29324,840
0.29357,841.1
0.29386,841.1
0.29414,842.7
0.29436,843.1
0.29456,843.3
0.29473,845.1
0.29494,845.3
0.29518,844.9
0.29534,843.1
0.29546,847.5
0.29586,843.9
0.29638,843.6
0.29699,843.4
0.29764,844.3
0.29825,844.7
0.29889,843
0.29953,843.8
0.30019,843.5
0.30085,844.2
0.30152,843.8
0.30219,842.8
0.3029,844.4
0.30361,842.5
0.30432,842.3
0.30503,843.1
0.30573,842.1
0.30646,843.6
0.30719,843.2
0.3079,841.6
0.30866,841.5
0.30941,842.5
0.31014,842.4
0.31089,841.9
0.31164,842.6
0.31238,842.4
0.31309,841.6
0.31385,842.1
0.31458,841.4
0.31532,842
0.31605,841.4
0.31677,841.7
0.31753,841.9
0.31827,841.7
0.319,841.7
0.31974,841.3
0.32049,842.2
0.32124,842.5
0.32197,841.2
0.32271,841.9
0.32342,841.9
0.32418,842.1
0.3249,842.4
0.32565,841.4
0.32642,842.1
0.3272,842.8
0.32799,842.8
0.32869,842.3
0.32921,842.5
0.32959,844.1
0.32986,843.7
0.33018,843.8
0.33045,844.6
0.33067,844
0.33089,845.1
0.33102,846.2
0.33112,845.8
0.3312,849.3
0.33138,848.9
0.3318,847.5
0.33237,845
0.33303,845.7
0.33371,844.9
0.33443,844.5
0.33517,844.7
0.33591,843.9
0.33667,844
0.33738,845.5
0.33814,844.4
0.33888,843
0.33961,843.5
0.34038,844.6
0.34111,843.2
0.34184,844.6
0.34257,844.3
0.34334,844
0.34408,844.9
0.34483,844.3
0.34557,844.1
0.34632,844.4
0.34706,845.1
0.34779,845
0.34855,844.5
0.34928,845.6
0.35004,845.7
0.35078,844.5
0.3515,844.9
0.35223,845.6
0.35296,845.3
0.35371,844.9
0.35447,845.9
0.35525,846.3
0.35599,845.9
0.35673,845.5
0.35749,846.1
0.35821,845.5
0.35895,845
0.3597,845.5
0.36042,845.9
0.36118,844.7
0.36192,845.7
0.36266,845.5
0.36342,845.2
0.36414,845.2
0.36489,845.4
0.36562,845.9
0.36637,845.5
0.36707,845.8
0.3678,846.7
0.36854,845.6
0.36926,846.1
0.37002,845
0.37074,845.9
0.37146,846.7
0.37221,846
0.37289,846
0.37349,846.3
0.37402,845.5
0.37447,845.4
0.3749,846.5
0.37527,846.8
0.37565,848.2
0.37603,846.9
0.37639,848.2
0.37674,849.2
0.37719,848
0.37775,847.9
0.37841,847.9
0.37909,847.2
0.37982,846.9
0.38053,846.9
0.38129,847.2
0.382,846.2
0.38273,846.3
0.38345,845.4
0.38421,846.3
0.38493,846.3
0.38568,847
0.38642,846.3
0.38717,845.9
0.3879,845.7
0.38864,844.4
0.3894,844.8
0.39013,845.7
0.39085,845.4
0.39158,845.2
0.39234,845.3
0.39308,845.9
0.39378,845
0.39453,844.5
0.39527,844.9
0.396,845
0.39674,845
0.39746,845.7
0.39818,845.6
0.39893,847
0.39966,845.3
0.40041,845.6
0.40114,845.5
0.40189,845.1
0.40264,845.2
0.40339,845.8
0.40413,845.1
0.40485,846
0.40561,845.2
0.40634,845.2
0.40711,846.1
0.40784,845.9
0.4086,845.4
0.40935,846
0.41009,846.2
0.41082,846.7
0.41158,845.7
0.41229,845.6
0.41302,846.2
0.41374,845.3
0.41449,845.3
0.41521,846.4
0.41597,845
0.4167,845.2
0.4174,844.8
0.41817,845
0.41889,845.8
0.41964,845.6
0.42035,846.1
0.42109,846.2
0.42182,845.3
0.42257,846.6
0.42332,846.6
0.42407,846.5
0.42482,847
0.42556,847
0.4263,847.5
0.42698,846.6
0.42756,847.6
0.4281,848.1
0.42861,847.3
0.42899,847.2
0.42943,847.9
0.42991,848.6
0.43041,848.4
0.43101,847.2
0.43165,846.9
0.43236,846.1
0.4331,845.7
0.43381,845.4
0.43454,845.8
0.43527,844.3
0.43602,845.3
0.43676,844.9
0.4375,844.5
0.43824,844.7
0.43899,845.2
0.43972,844.8
0.44045,845.3
0.44118,844.8
0.4419,844.7
0.44264,845.4
0.44336,845.1
0.44412,843.5
0.44486,843.9
0.44559,843.9
0.44633,844.8
0.44706,844.3
0.44779,845.5
0.44855,844.9
0.44928,844.3
0.45,845.2
0.45073,844.8
0.45147,844.6
0.45221,844.5
0.45295,845.3
0.45368,844.8
0.45442,844.6
0.45518,844.5
0.45592,844.2
0.45665,844.9
0.4574,844.5
0.45815,844.1
0.45888,843.7
0.45958,843.9
0.46032,845.1
0.46108,844
0.46182,843.5
0.46256,844.2
0.46332,843.1
0.46405,843.7
0.46478,842.6
0.46551,843.4
0.46624,842
0.46697,841.8
0.46773,841.3
0.46848,840.7
0.46922,841.9
0.46996,840.8
0.47072,840.8
0.47145,840.9
0.47221,839.8
0.47296,840
0.47369,840.2
0.47443,838.8
0.47518,839.7
0.47591,839.2
0.47666,838.9
0.47741,838.3
0.47815,839.1
0.47888,839.5
0.47962,837.9
0.48036,837.2
0.48108,837.2
0.48182,837.5
0.48257,837
0.48332,836
0.48407,836.4
0.4848,836.1
0.48554,835.8
0.4863,835.2
0.48705,835.3
0.48778,834
0.48851,834.6
0.48926,834
0.49001,833.8
0.49075,832.4
0.49149,832.4
0.49226,831.4
0.49299,831.2
0.49373,832.4
0.49445,830.3
0.49517,830.4
0.49591,830.7
0.49665,829.9
0.49741,828.2
0.49815,828.9
0.4989,828.6
0.49967,827
0.50039,826.7
0.50114,825.8
0.50187,826.2
0.50264,825
0.50337,825.4
0.50413,823.9
0.50487,824.4
0.50562,824.1
0.50638,822
0.50711,821.9
0.50788,821.5
0.50862,820.9
0.50938,818.8
0.51014,818.1
0.51086,818.5
0.51163,817.9
0.51239,817.1
0.51314,816.4
0.51389,816.2
0.51467,813.4
0.51541,813
0.51616,812.6
0.51689,812.1
0.51763,811.8
0.51839,811.1
0.51916,810.1
0.51989,808.8
0.52065,807.5
0.52139,807
0.52215,805.5
0.52288,804.3
0.52365,804.6
0.5244,802.9
0.52514,801.5
0.5259,799.5
0.52667,799.5
0.52741,797.7
0.52817,797
0.52893,796.1
0.52967,794.2
0.53042,794.3
0.53117,791.4
0.53192,790.3
0.53269,789.1
0.53344,788.6
0.53419,787.6
0.53493,786.1
0.53569,784
0.53635,783.3
0.53698,782.5
0.53754,780.4
0.53807,778.7
0.53854,778.8
0.539,777.1
0.53946,776.2
0.53989,776.2
0.54036,775.1
0.54084,773
0.5413,772.5
0.54176,772
0.5422,771.3
0.54269,769.5
0.5431,768.1
0.54358,766.8
0.54404,766.7
0.54448,765.1
0.54491,765.2
0.54536,763.1
0.54582,762.3
0.54627,761.8
0.54672,760.2
0.54718,759
0.54762,758.1
0.54806,756.8
0.5485,755.8
0.54895,754.5
0.54942,753.2
0.54987,753.2
0.55032,751.6
0.55076,750.4
0.55123,749.5
0.55166,748.1
0.55212,746.8
0.55257,746
0.55303,744.3
0.55348,742.6
0.55393,741.9
0.55439,739.9
0.55485,738.7
0.55532,737.3
0.55577,736.5
0.55622,735.1
0.55667,733.5
0.55713,732.8
0.55758,731.6
0.55805,729.4
0.55849,728.7
0.55895,727.9
0.55941,724.5
0.55986,724.1
0.56032,723
0.56075,721.2
0.56123,719.5
0.56168,718.2
0.56213,716.4
0.56256,715
0.56305,713.7
0.56352,711.7
0.564,709.2
0.56445,707.8
0.5649,706.8
0.56538,704.7
0.56585,703.9
0.56629,700.2
0.56674,698.5
0.56722,697.5
0.56768,695.8
0.56814,693.9
0.56859,692.4
0.56907,690.6
0.56951,688
0.56997,686.5
0.57043,685.1
0.57088,682.3
0.57136,680.5
0.57182,679.2
0.57229,677
0.57275,674.4
0.57324,671.8
0.5737,669.8
0.57417,667.6
0.57464,664.9
0.5751,662
0.57559,661
0.57604,658.1
0.5765,655
0.57697,653.1
0.57744,650.4
0.57791,647
0.5784,645.1
0.5789,642.2
0.57937,639.6
0.57983,636.4
0.58028,632.8
0.58076,630.2
0.58125,627.2
0.58176,623.3
0.58224,620
0.58272,616.8
0.58321,612.7
0.58368,610.8
0.58416,606.7
0.58467,602.3
0.58519,597.8
0.5857,594.5
0.5862,589.1
0.58671,583.7
0.58724,577.4
0.58814,547.2
0.5924,379.7
0.59496,324.6
0.59679,290.7
0.59849,262.5
0.60001,238
0.60108,221
0.60208,207.2
0.60328,189.6
0.60445,172
0.60565,153.8
0.6066,140.7
0.60738,133.2
0.60824,123.2
0.60904,115
0.60986,105.2
0.61059,98.5
0.61131,91.1
0.61203,83.8
0.61277,76.9
0.61358,67.3
0.61447,57.1
0.6155,43.5
0.61655,32.4
0.61739,23.5
0.61807,19.7
0.61875,16.7
0.61955,12
0.62013,9.8
0.62162,3.6
0.62238,1.4
0.62288,0.8
0.62336,-0.5
0.62382,-0.5
0.62435,-0.8
0.62472,-1.4
0.6252,-26.2
0.62526,-0.6
0.62531,-1
0.62533,-1.5
0.62533,-0.4
0.62535,-0.9
0.62536,-1.1
0.62537,-1.1
0.62538,-1.3
0.62537,-0.4
0.62539,-0.8
0.6254,-0.8
0.62539,-0.7
0.6254,-0.7