File: MAE_3272/Module_1/Group1-1018 Cold Rolled_7.csv
2/12/2016
3:59 PM
Sampling Frequency:,10Hz
Group:,Group1
Extensometer:,E85191
Sample:,1018 Cold Rolled
Sample width [inch]:,0.496000
Sample thickness [inch]:,0.124000
--------,--------

Extensometer,Load
[Inches],[Lbs]
0.00000,  -0.2
0.00001,  -0.4
-0.00000,  -0.5
0.00001,  -0.1
0.00000,   0.4
0.00001,   0.2
0.00001,  -0.3
0.00001,   0.4
0.00000,  -0.4
-0.00001,   0.3
0.00002,   0.2
0.00001,  -0.4
0.00001,  -0.8
0.00000,   0.1
0.00000,   1.1
-0.00001,   0.2
0.00000,   0.1
0.00002,  -0.0
0.00000,  -0.8
-0.00001,   1.1
0.00001,   0.3
0.00001,   0.5
0.00000,  -0.3
-0.00001,   0.7
0.00001,  -0.7
0.00000,  -0.0
0.00000,  -0.5
0.00000,  -0.1
0.00000,   0.1
0.00001,   0.7
0.00002,   0.0
0.00002,  -0.5
0.00001,   0.2
0.00000,  -0.3
0.00000,   0.9
0.00001,   0.5
0.00002,   0.2
-0.00001,   2.8
0.00001,   2.1
-0.00000,   3.3
0.00001,   4.1
0.00000,   3.0
0.00002,   3.1
0.00002,   3.4
0.00002,   3.6
0.00002,   4.0
0.00002,   3.9
0.00001,   3.1
0.00002,   4.7
0.00002,   3.8
0.00002,   3.6
0.00003,   2.9
0.00002,   3.5
0.00002,   2.9
0.00001,   2.7
0.00002,   3.8
0.00002,   4.6
0.00002,   3.8
0.00001,   3.0
0.00003,   4.3
0.00002,   3.6
0.00003,   3.2
0.00003,   4.1
0.00000,   3.9
0.00000,   3.6
0.00002,   4.6
0.00003,   4.2
0.00000,   4.9
0.00003,   6.2
0.00002,   6.3
0.00003,   6.8
0.00005,   8.6
0.00006,   8.4
0.00006,   8.6
0.00005,  10.1
0.00006,  11.0
0.00006,  11.7
0.00007,  12.1
0.00006,  13.5
0.00007,  14.1
0.00008,  14.3
0.00008,  14.4
0.00008,  15.4
0.00009,  17.8
0.00010,  16.8
0.00009,  18.1
0.00011,  18.9
0.00011,  19.0
0.00011,  19.2
0.00011,  20.9
0.00010,  20.6
0.00008,  20.8
0.00010,  20.9
0.00010,  21.4
0.00011,  22.0
0.00010,  23.1
0.00010,  23.6
0.00010,  23.9
0.00012,  24.2
0.00010,  26.0
0.00011,  25.5
0.00012,  25.1
0.00011,  26.2
0.00012,  25.9
0.00010,  26.3
0.00013,  27.7
0.00013,  27.0
0.00012,  28.2
0.00012,  27.8
0.00011,  28.2
0.00013,  28.4
0.00012,  29.2
0.00013,  28.4
0.00012,  29.2
0.00012,  29.0
0.00012,  28.7
0.00012,  28.8
0.00011,  29.2
0.00011,  29.1
0.00012,  29.1
0.00012,  30.1
0.00012,  31.6
0.00012,  31.5
0.00012,  32.2
0.00012,  32.2
0.00012,  35.5
0.00012,  35.2
0.00012,  37.3
0.00013,  38.1
0.00012,  39.0
0.00013,  41.1
0.00012,  41.3
0.00013,  44.5
0.00013,  44.3
0.00014,  45.1
0.00015,  46.5
0.00014,  49.1
0.00014,  48.6
0.00016,  50.3
0.00015,  52.0
0.00013,  53.9
0.00015,  55.9
0.00016,  56.6
0.00017,  59.5
0.00016,  62.2
0.00016,  63.8
0.00018,  63.6
0.00017,  66.6
0.00016,  68.4
0.00017,  70.2
0.00017,  72.1
0.00019,  74.3
0.00018,  76.6
0.00018,  78.7
0.00018,  80.6
0.00019,  82.7
0.00019,  86.0
0.00020,  88.5
0.00019,  90.7
0.00019,  93.8
0.00020,  94.7
0.00021,  98.8
0.00020, 100.2
0.00020, 102.5
0.00021, 105.3
0.00022, 109.5
0.00023, 111.6
0.00022, 114.4
0.00024, 118.0
0.00023, 120.8
0.00023, 124.0
0.00023, 127.5
0.00023, 130.6
0.00024, 132.6
0.00025, 136.2
0.00024, 139.2
0.00022, 142.0
0.00025, 146.6
0.00024, 149.6
0.00025, 153.0
0.00026, 156.1
0.00026, 159.8
0.00026, 162.8
0.00028, 165.4
0.00029, 168.9
0.00029, 171.6
0.00029, 175.2
0.00029, 178.3
0.00028, 183.8
0.00029, 186.3
0.00029, 190.8
0.00030, 193.3
0.00032, 197.8
0.00032, 201.0
0.00032, 204.9
0.00030, 208.5
0.00032, 212.2
0.00033, 216.0
0.00033, 220.8
0.00035, 224.3
0.00033, 227.7
0.00035, 231.8
0.00036, 235.4
0.00036, 238.8
0.00036, 244.6
0.00037, 248.3
0.00037, 252.0
0.00037, 256.4
0.00038, 261.4
0.00039, 265.7
0.00040, 270.0
0.00039, 273.9
0.00041, 278.5
0.00041, 283.3
0.00042, 287.5
0.00043, 292.4
0.00043, 296.1
0.00043, 300.7
0.00044, 306.5
0.00044, 310.6
0.00045, 315.5
0.00045, 320.6
0.00047, 324.8
0.00046, 328.3
0.00047, 334.4
0.00047, 338.7
0.00048, 343.0
0.00049, 348.6
0.00050, 353.7
0.00050, 357.4
0.00052, 363.0
0.00052, 367.3
0.00052, 373.0
0.00053, 378.2
0.00052, 383.0
0.00053, 387.9
0.00054, 392.8
0.00055, 399.2
0.00055, 404.6
0.00056, 410.0
0.00055, 415.9
0.00058, 422.1
0.00057, 426.5
0.00058, 432.5
0.00059, 436.8
0.00061, 443.6
0.00060, 448.5
0.00061, 454.0
0.00061, 460.0
0.00061, 466.2
0.00063, 473.6
0.00064, 478.3
0.00066, 484.9
0.00066, 490.5
0.00066, 497.3
0.00065, 504.4
0.00067, 510.4
0.00067, 517.8
0.00069, 523.7
0.00069, 530.2
0.00071, 536.7
0.00072, 543.5
0.00072, 549.2
0.00073, 556.9
0.00075, 564.0
0.00074, 571.9
0.00075, 579.5
0.00078, 587.2
0.00079, 595.6
0.00079, 602.7
0.00080, 610.8
0.00081, 617.7
0.00082, 625.9
0.00084, 633.9
0.00085, 642.5
0.00085, 651.2
0.00086, 657.4
0.00085, 661.7
0.00088, 660.0
0.00091, 670.9
0.00091, 683.0
0.00092, 692.8
0.00093, 703.1
0.00095, 714.0
0.00097, 723.1
0.00098, 733.2
0.00099, 743.6
0.00099, 752.8
0.00102, 762.9
0.00102, 773.0
0.00103, 784.7
0.00105, 794.6
0.00107, 804.3
0.00108, 814.3
0.00110, 826.5
0.00109, 835.9
0.00112, 846.5
0.00114, 857.7
0.00115, 868.8
0.00115, 878.7
0.00118, 889.5
0.00118, 899.4
0.00120, 911.7
0.00122, 921.7
0.00121, 932.9
0.00124, 944.5
0.00126, 955.0
0.00127, 967.8
0.00127, 978.3
0.00128, 989.4
0.00132,1000.7
0.00133,1013.1
0.00135,1024.8
0.00134,1036.0
0.00135,1047.6
0.00140,1059.8
0.00140,1072.5
0.00141,1083.7
0.00143,1095.9
0.00145,1107.2
0.00147,1119.4
0.00148,1130.3
0.00151,1142.2
0.00151,1156.0
0.00153,1168.3
0.00155,1180.5
0.00155,1192.3
0.00156,1205.2
0.00158,1217.2
0.00162,1229.5
0.00162,1243.0
0.00163,1254.3
0.00165,1268.3
0.00167,1279.9
0.00167,1292.9
0.00171,1305.1
0.00172,1317.6
0.00172,1329.7
0.00174,1344.4
0.00177,1355.5
0.00177,1368.8
0.00177,1381.7
0.00180,1394.4
0.00183,1408.3
0.00183,1420.7
0.00184,1434.1
0.00187,1447.6
0.00188,1460.3
0.00191,1473.2
0.00192,1486.2
0.00193,1499.8
0.00196,1514.2
0.00196,1527.2
0.00198,1540.0
0.00201,1553.2
0.00202,1566.3
0.00203,1580.7
0.00206,1593.8
0.00206,1607.0
0.00209,1622.0
0.00210,1634.6
0.00211,1649.4
0.00214,1661.3
0.00215,1676.2
0.00217,1691.9
0.00219,1705.9
0.00222,1722.6
0.00221,1736.8
0.00224,1752.7
0.00229,1765.9
0.00229,1781.8
0.00229,1797.4
0.00231,1811.1
0.00233,1827.4
0.00236,1841.8
0.00238,1857.9
0.00240,1872.7
0.00241,1886.2
0.00244,1901.3
0.00246,1917.2
0.00247,1932.4
0.00249,1947.1
0.00252,1963.0
0.00255,1978.2
0.00256,1993.5
0.00259,2009.8
0.00260,2024.2
0.00264,2039.8
0.00266,2055.4
0.00268,2070.4
0.00270,2085.7
0.00273,2101.7
0.00273,2116.7
0.00276,2131.8
0.00278,2147.5
0.00281,2162.7
0.00282,2178.5
0.00285,2194.1
0.00288,2208.5
0.00289,2224.9
0.00292,2240.6
0.00294,2256.0
0.00296,2272.8
0.00298,2287.9
0.00301,2303.8
0.00303,2318.3
0.00306,2335.4
0.00308,2351.1
0.00310,2366.4
0.00312,2382.3
0.00316,2398.4
0.00318,2414.8
0.00321,2431.5
0.00323,2446.2
0.00326,2463.2
0.00327,2479.3
0.00331,2495.4
0.00333,2510.8
0.00335,2527.4
0.00339,2543.5
0.00340,2559.2
0.00344,2574.9
0.00345,2591.2
0.00349,2607.1
0.00353,2623.8
0.00354,2639.3
0.00358,2656.3
0.00360,2672.7
0.00362,2688.9
0.00366,2703.4
0.00368,2720.7
0.00371,2736.4
0.00373,2754.4
0.00375,2768.9
0.00379,2785.0
0.00383,2800.8
0.00385,2817.0
0.00387,2835.5
0.00389,2849.8
0.00393,2865.8
0.00395,2881.4
0.00398,2899.1
0.00402,2915.2
0.00405,2931.1
0.00409,2947.8
0.00411,2963.4
0.00413,2979.2
0.00416,2994.9
0.00419,3012.6
0.00423,3028.0
0.00426,3045.0
0.00428,3061.9
0.00432,3078.1
0.00434,3093.9
0.00437,3110.6
0.00440,3127.4
0.00442,3143.0
0.00446,3161.6
0.00451,3178.1
0.00455,3193.8
0.00455,3209.1
0.00459,3226.5
0.00464,3242.4
0.00467,3259.2
0.00470,3276.8
0.00475,3292.7
0.00476,3310.3
0.00480,3324.8
0.00483,3340.4
0.00486,3356.0
0.00491,3372.0
0.00494,3389.0
0.00498,3405.2
0.00502,3421.4
0.00505,3437.9
0.00508,3454.2
0.00511,3469.9
0.00516,3485.1
0.00520,3502.7
0.00523,3519.5
0.00526,3535.6
0.00531,3551.7
0.00536,3567.8
0.00538,3582.9
0.00542,3598.2
0.00545,3615.8
0.00548,3630.3
0.00554,3646.7
0.00557,3663.0
0.00561,3678.0
0.00564,3694.4
0.00570,3709.7
0.00573,3725.7
0.00577,3742.4
0.00582,3758.7
0.00587,3774.4
0.00589,3791.5
0.00594,3807.2
0.00600,3823.2
0.00603,3839.2
0.00609,3857.1
0.00611,3871.4
0.00618,3886.2
0.00622,3904.5
0.00625,3919.4
0.00630,3934.6
0.00634,3949.4
0.00640,3964.7
0.00645,3980.0
0.00651,3993.8
0.00655,4008.9
0.00659,4021.2
0.00663,4032.8
0.00668,4046.7
0.00671,4061.5
0.00676,4073.7
0.00679,4085.1
0.00684,4095.4
0.00689,4105.3
0.00690,4116.0
0.00696,4126.2
0.00699,4135.8
0.00702,4142.9
0.00704,4150.5
0.00709,4159.3
0.00711,4167.5
0.00715,4173.8
0.00718,4181.1
0.00720,4188.7
0.00726,4196.4
0.00728,4202.2
0.00731,4210.1
0.00732,4217.8
0.00736,4225.5
0.00738,4232.6
0.00741,4240.4
0.00745,4246.6
0.00748,4253.8
0.00750,4262.6
0.00754,4269.6
0.00756,4277.8
0.00762,4287.2
0.00764,4297.0
0.00768,4304.4
0.00771,4313.9
0.00775,4321.3
0.00780,4330.1
0.00783,4338.6
0.00786,4346.2
0.00792,4353.9
0.00795,4362.7
0.00799,4371.1
0.00802,4378.9
0.00806,4388.3
0.00810,4395.6
0.00814,4404.7
0.00819,4412.5
0.00823,4420.4
0.00826,4428.8
0.00833,4436.8
0.00838,4444.2
0.00839,4452.3
0.00845,4460.3
0.00848,4467.5
0.00854,4474.9
0.00856,4482.4
0.00860,4491.4
0.00867,4498.2
0.00871,4506.3
0.00876,4513.6
0.00881,4520.4
0.00885,4527.1
0.00888,4534.5
0.00895,4542.0
0.00899,4549.6
0.00904,4556.9
0.00908,4564.3
0.00914,4571.5
0.00919,4579.0
0.00923,4586.2
0.00929,4593.7
0.00935,4600.7
0.00938,4607.5
0.00945,4614.5
0.00951,4621.1
0.00956,4627.9
0.00962,4634.1
0.00966,4640.8
0.00973,4647.1
0.00979,4654.6
0.00984,4659.6
0.00992,4666.2
0.00997,4673.8
0.01001,4679.9
0.01007,4685.6
0.01015,4692.5
0.01021,4698.3
0.01026,4704.5
0.01033,4709.3
0.01040,4716.1
0.01046,4720.6
0.01054,4726.2
0.01059,4731.9
0.01067,4737.6
0.01074,4742.7
0.01079,4747.6
0.01086,4753.4
0.01094,4759.5
0.01100,4763.6
0.01109,4769.7
0.01115,4774.1
0.01124,4778.5
0.01132,4783.6
0.01141,4789.1
0.01147,4793.3
0.01156,4798.5
0.01167,4803.2
0.01173,4809.3
0.01182,4812.7
0.01190,4816.1
0.01201,4821.8
0.01209,4824.8
0.01217,4828.9
0.01228,4833.1
0.01237,4836.8
0.01246,4840.2
0.01256,4844.5
0.01266,4847.6
0.01277,4851.3
0.01286,4854.6
0.01295,4856.2
0.01306,4859.7
0.01315,4862.0
0.01324,4863.6
0.01334,4864.7
0.01345,4866.2
0.01354,4868.4
0.01360,4870.0
0.01372,4872.0
0.01380,4873.1
0.01392,4877.0
0.01401,4878.6
0.01410,4881.6
0.01421,4883.6
0.01431,4884.6
0.01440,4887.9
0.01451,4890.4
0.01462,4893.5
0.01474,4895.7
0.01483,4897.5
0.01495,4898.2
0.01506,4898.7
0.01517,4899.9
0.01528,4901.2
0.01539,4903.4
0.01549,4903.6
0.01563,4906.5
0.01573,4908.1
0.01585,4909.3
0.01597,4908.9
0.01606,4909.7
0.01619,4910.7
0.01631,4912.9
0.01641,4914.4
0.01657,4916.4
0.01668,4917.1
0.01682,4918.1
0.01692,4919.1
0.01707,4918.9
0.01717,4919.9
0.01729,4919.1
0.01742,4919.6
0.01754,4921.5
0.01765,4923.0
0.01779,4922.6
0.01791,4923.6
0.01804,4924.9
0.01817,4924.7
0.01830,4924.9
0.01844,4926.4
0.01855,4926.2
0.01868,4927.1
0.01882,4926.8
0.01896,4927.6
0.01909,4927.7
0.01921,4928.5
0.01935,4930.2
0.01947,4930.2
0.01960,4929.8
0.01974,4929.7
0.01988,4929.3
0.02001,4930.3
0.02015,4930.0
0.02029,4932.0
0.02041,4931.6
0.02055,4930.7
0.02070,4930.9
0.02082,4933.5
0.02096,4932.1
0.02108,4932.7
0.02124,4933.0
0.02138,4934.9
0.02151,4934.7
0.02165,4933.5
0.02179,4933.5
0.02194,4933.2
0.02208,4933.9
0.02221,4935.1
0.02235,4933.8
0.02250,4934.0
0.02265,4934.9
0.02278,4933.8
0.02293,4934.0
0.02308,4933.8
0.02323,4932.8
0.02335,4930.9
0.02349,4930.8
0.02364,4930.7
0.02377,4930.5
0.02390,4930.2
0.02403,4930.7
0.02418,4929.2
0.02432,4930.2
0.02445,4929.5
0.02459,4929.9
0.02472,4929.6
0.02485,4929.4
0.02498,4929.3
0.02512,4927.9
0.02525,4928.6
0.02539,4927.7
0.02551,4928.0
0.02565,4928.2
0.02579,4926.8
0.02592,4927.6
0.02606,4926.6
0.02616,4925.3
0.02630,4926.2
0.02642,4924.9
0.02657,4925.0
0.02667,4925.1
0.02681,4926.2
0.02697,4926.1
0.02709,4926.5
0.02722,4926.2
0.02734,4926.6
0.02748,4925.0
0.02764,4925.3
0.02776,4924.8
0.02792,4924.6
0.02802,4924.9
0.02814,4923.6
0.02828,4924.4
0.02843,4924.6
0.02856,4924.0
0.02869,4925.3
0.02883,4925.3
0.02897,4925.7
0.02913,4925.2
0.02928,4925.5
0.02942,4927.2
0.02960,4933.6
0.02980,4939.3
0.03005,4944.1
0.03028,4944.8
0.03053,4942.1
0.03079,4941.9
0.03103,4939.0
0.03128,4938.6
0.03151,4937.8
0.03175,4936.6
0.03198,4935.3
0.03221,4936.3
0.03244,4935.4
0.03266,4934.7
0.03291,4933.9
0.03315,4933.2
0.03338,4932.1
0.03362,4931.2
0.03384,4931.9
0.03408,4930.6
0.03431,4929.3
0.03454,4928.7
0.03477,4929.4
0.03502,4928.8
0.03523,4928.5
0.03548,4927.8
0.03570,4927.5
0.03594,4926.3
0.03617,4925.4
0.03641,4925.9
0.03663,4925.9
0.03687,4924.2
0.03709,4925.5
0.03733,4925.5
0.03758,4925.7
0.03781,4923.3
0.03806,4922.3
0.03830,4922.2
0.03854,4921.6
0.03877,4921.1
0.03903,4920.6
0.03926,4920.5
0.03949,4920.5
0.03974,4918.8
0.04000,4919.1
0.04024,4917.1
0.04045,4916.2
0.04069,4917.2
0.04095,4916.3
0.04118,4915.9
0.04142,4915.8
0.04168,4916.1
0.04191,4915.7
0.04216,4915.1
0.04241,4914.4
0.04264,4913.5
0.04290,4912.9
0.04314,4911.7
0.04337,4910.8
0.04362,4909.4
0.04385,4910.7
0.04409,4909.7
0.04435,4909.3
0.04460,4908.2
0.04484,4908.2
0.04508,4906.4
0.04533,4906.7
0.04557,4906.7
0.04581,4906.8
0.04605,4905.9
0.04630,4905.2
0.04654,4903.7
0.04678,4902.7
0.04703,4902.4
0.04728,4902.7
0.04752,4900.8
0.04777,4901.3
0.04800,4900.5
0.04826,4901.1
0.04850,4900.4
0.04876,4900.6
0.04900,4898.9
0.04927,4899.1
0.04952,4898.5
0.04976,4897.3
0.05002,4896.6
0.05025,4895.8
0.05050,4896.9
0.05076,4894.0
0.05099,4893.1
0.05123,4892.4
0.05150,4891.2
0.05174,4890.4
0.05198,4889.7
0.05220,4889.5
0.05245,4887.8
0.05269,4888.2
0.05294,4887.9
0.05318,4887.9
0.05345,4888.1
0.05370,4887.7
0.05394,4888.5
0.05423,4886.7
0.05447,4886.3
0.05470,4884.5
0.05495,4885.3
0.05522,4884.7
0.05545,4884.0
0.05571,4882.4
0.05595,4881.7
0.05621,4881.6
0.05647,4881.8
0.05671,4881.1
0.05697,4880.0
0.05723,4879.4
0.05748,4876.5
0.05773,4877.2
0.05798,4876.1
0.05824,4876.3
0.05848,4875.8
0.05874,4874.9
0.05899,4874.9
0.05923,4874.3
0.05949,4872.9
0.05974,4872.8
0.06000,4870.3
0.06025,4871.0
0.06049,4870.0
0.06077,4870.7
0.06100,4868.9
0.06127,4868.7
0.06152,4869.0
0.06178,4867.1
0.06203,4866.2
0.06228,4865.4
0.06252,4865.4
0.06279,4864.3
0.06305,4864.3
0.06330,4864.1
0.06355,4862.4
0.06379,4862.2
0.06405,4860.3
0.06430,4859.9
0.06455,4859.7
0.06481,4858.9
0.06505,4858.1
0.06531,4857.0
0.06557,4856.5
0.06584,4855.9
0.06609,4856.1
0.06636,4856.3
0.06661,4854.8
0.06688,4852.6
0.06711,4852.3
0.06735,4849.8
0.06760,4849.6
0.06786,4848.7
0.06810,4849.4
0.06834,4847.1
0.06861,4845.8
0.06885,4846.9
0.06908,4846.3
0.06933,4845.3
0.06959,4843.9
0.06984,4843.7
0.07009,4844.1
0.07034,4844.1
0.07061,4844.4
0.07088,4842.9
0.07114,4840.7
0.07140,4840.1
0.07165,4838.7
0.07192,4838.1
0.07218,4836.8
0.07243,4835.2
0.07270,4835.6
0.07297,4835.9
0.07321,4833.8
0.07347,4832.7
0.07374,4832.6
0.07401,4830.5
0.07427,4829.6
0.07452,4829.2
0.07477,4827.6
0.07502,4827.1
0.07527,4825.7
0.07552,4824.1
0.07578,4824.6
0.07604,4823.0
0.07627,4822.2
0.07652,4819.7
0.07676,4819.8
0.07703,4819.8
0.07730,4819.4
0.07755,4819.3
0.07780,4818.6
0.07807,4816.5
0.07833,4816.7
0.07859,4816.1
0.07886,4814.1
0.07912,4813.9
0.07938,4811.6
0.07963,4809.3
0.07988,4809.4
0.08014,4809.4
0.08040,4809.1
0.08066,4806.8
0.08092,4806.4
0.08116,4804.6
0.08143,4803.5
0.08168,4802.7
0.08193,4802.8
0.08220,4801.7
0.08245,4799.7
0.08271,4798.0
0.08296,4798.3
0.08324,4798.4
0.08349,4796.5
0.08375,4796.1
0.08403,4794.8
0.08427,4793.2
0.08452,4793.0
0.08477,4792.2
0.08503,4791.1
0.08528,4790.2
0.08556,4789.7
0.08581,4788.7
0.08606,4786.5
0.08634,4784.8
0.08659,4784.1
0.08684,4782.6
0.08711,4782.1
0.08737,4781.5
0.08762,4779.4
0.08789,4778.9
0.08815,4778.1
0.08840,4775.5
0.08865,4773.9
0.08893,4773.7
0.08916,4773.7
0.08944,4772.0
0.08970,4771.1
0.08996,4769.8
0.09024,4769.0
0.09049,4767.2
0.09076,4765.2
0.09101,4765.3
0.09129,4766.2
0.09156,4765.1
0.09183,4762.6
0.09208,4759.8
0.09234,4759.6
0.09262,4759.2
0.09286,4757.6
0.09314,4756.3
0.09342,4755.3
0.09367,4753.9
0.09395,4752.5
0.09421,4750.6
0.09448,4749.6
0.09472,4747.3
0.09499,4746.4
0.09526,4745.8
0.09553,4744.3
0.09579,4742.7
0.09605,4740.2
0.09631,4738.4
0.09657,4737.0
0.09683,4736.7
0.09707,4736.0
0.09735,4736.4
0.09762,4734.1
0.09787,4731.8
0.09815,4730.7
0.09839,4728.6
0.09867,4728.9
0.09893,4726.4
0.09919,4726.1
0.09945,4724.5
0.09972,4723.4
0.09999,4721.6
0.10024,4720.2
0.10051,4717.8
0.10078,4716.6
0.10105,4714.9
0.10129,4714.4
0.10156,4714.5
0.10183,4711.7
0.10209,4708.8
0.10236,4709.2
0.10263,4707.8
0.10288,4704.8
0.10313,4702.9
0.10339,4703.1
0.10365,4702.0
0.10392,4700.4
0.10420,4699.1
0.10445,4698.0
0.10472,4695.7
0.10497,4694.5
0.10524,4693.8
0.10550,4692.7
0.10577,4690.6
0.10602,4688.5
0.10630,4687.2
0.10658,4685.1
0.10683,4685.3
0.10709,4683.2
0.10737,4681.2
0.10761,4680.6
0.10789,4679.5
0.10817,4677.2
0.10845,4674.9
0.10870,4672.9
0.10896,4671.2
0.10923,4669.3
0.10950,4667.2
0.10975,4667.1
0.11002,4665.3
0.11028,4664.6
0.11053,4662.1
0.11079,4660.6
0.11106,4659.5
0.11132,4658.7
0.11158,4656.0
0.11184,4655.1
0.11210,4653.4
0.11236,4652.2
0.11264,4651.2
0.11291,4649.1
0.11316,4647.2
0.11343,4644.5
0.11370,4642.7
0.11397,4642.4
0.11423,4641.4
0.11451,4638.3
0.11476,4637.3
0.11503,4635.8
0.11528,4633.4
0.11556,4630.7
0.11583,4629.6
0.11607,4628.5
0.11634,4627.3
0.11662,4624.5
0.11687,4622.8
0.11715,4621.4
0.11741,4620.4
0.11769,4619.3
0.11796,4617.8
0.11822,4615.2
0.11847,4612.8
0.11877,4611.3
0.11903,4609.7
0.11931,4607.3
0.11956,4605.7
0.11981,4603.6
0.12007,4603.4
0.12034,4599.6
0.12061,4599.3
0.12088,4597.9
0.12114,4596.0
0.12141,4593.9
0.12167,4591.5
0.12194,4589.3
0.12221,4587.8
0.12247,4586.3
0.12276,4585.3
0.12300,4583.3
0.12329,4581.2
0.12355,4579.3
0.12381,4576.6
0.12409,4575.6
0.12436,4573.1
0.12463,4571.3
0.12488,4568.6
0.12516,4567.3
0.12543,4565.2
0.12569,4562.3
0.12596,4561.8
0.12623,4559.5
0.12650,4557.3
0.12677,4556.0
0.12703,4554.2
0.12729,4550.5
0.12757,4548.4
0.12782,4547.1
0.12809,4544.6
0.12835,4542.7
0.12859,4542.9
0.12888,4539.2
0.12914,4538.9
0.12943,4536.0
0.12971,4533.8
0.12997,4531.8
0.13024,4529.6
0.13050,4527.1
0.13077,4525.7
0.13105,4523.4
0.13132,4520.2
0.13159,4518.1
0.13185,4517.1
0.13212,4515.0
0.13239,4511.5
0.13266,4510.0
0.13293,4507.3
0.13322,4505.4
0.13347,4503.7
0.13372,4501.7
0.13401,4499.5
0.13425,4496.6
0.13452,4493.5
0.13480,4493.0
0.13506,4491.5
0.13534,4488.8
0.13560,4485.5
0.13587,4483.5
0.13613,4481.9
0.13642,4478.3
0.13667,4476.2
0.13695,4474.0
0.13721,4472.2
0.13749,4469.7
0.13774,4468.1
0.13803,4465.2
0.13829,4463.3
0.13856,4460.6
0.13883,4458.5
0.13908,4454.8
0.13935,4453.9
0.13961,4451.4
0.13990,4449.4
0.14013,4445.3
0.14042,4445.0
0.14070,4443.0
0.14094,4439.0
0.14121,4437.1
0.14150,4435.2
0.14176,4432.4
0.14203,4428.2
0.14231,4427.1
0.14255,4423.7
0.14284,4421.5
0.14310,4418.8
0.14337,4416.9
0.14363,4414.5
0.14390,4412.5
0.14418,4410.7
0.14446,4406.7
0.14472,4403.8
0.14500,4402.0
0.14527,4399.9
0.14554,4396.6
0.14583,4393.6
0.14611,4391.0
0.14636,4387.7
0.14664,4384.3
0.14690,4382.1
0.14718,4379.2
0.14744,4376.7
0.14772,4373.4
0.14798,4371.3
0.14823,4368.8
0.14851,4365.4
0.14879,4364.3
0.14907,4361.6
0.14935,4357.8
0.14962,4354.0
0.14990,4351.4
0.15017,4348.2
0.15045,4346.4
0.15073,4341.3
0.15099,4339.7
0.15127,4336.8
0.15155,4333.2
0.15182,4330.2
0.15211,4327.7
0.15237,4325.2
0.15266,4321.2
0.15294,4318.2
0.15319,4314.5
0.15348,4310.8
0.15376,4308.7
0.15402,4305.3
0.15430,4303.1
0.15459,4299.2
0.15487,4296.4
0.15514,4293.1
0.15541,4289.4
0.15570,4286.6
0.15597,4283.1
0.15624,4279.8
0.15652,4277.0
0.15679,4273.4
0.15707,4269.3
0.15734,4266.7
0.15761,4263.5
0.15788,4259.9
0.15816,4256.8
0.15844,4254.5
0.15874,4250.9
0.15901,4246.7
0.15929,4242.6
0.15956,4239.0
0.15986,4234.9
0.16013,4232.5
0.16041,4228.2
0.16069,4224.7
0.16097,4221.3
0.16125,4217.7
0.16149,4213.3
0.16178,4210.1
0.16210,4206.8
0.16238,4203.2
0.16266,4200.0
0.16297,4195.0
0.16323,4190.7
0.16351,4188.2
0.16380,4183.7
0.16408,4179.0
0.16435,4176.1
0.16463,4171.3
0.16491,4166.6
0.16518,4163.2
0.16545,4159.8
0.16574,4156.2
0.16602,4151.2
0.16631,4148.6
0.16658,4144.0
0.16686,4140.3
0.16717,4135.6
0.16745,4131.3
0.16772,4127.8
0.16803,4122.6
0.16830,4118.1
0.16858,4114.3
0.16888,4109.8
0.16918,4104.8
0.16945,4099.5
0.16975,4096.3
0.17001,4090.4
0.17030,4086.1
0.17060,4082.0
0.17087,4077.9
0.17117,4073.8
0.17144,4069.3
0.17173,4064.6
0.17201,4060.2
0.17230,4054.8
0.17260,4051.3
0.17289,4046.6
0.17319,4040.8
0.17347,4036.4
0.17376,4030.2
0.17405,4027.3
0.17434,4021.6
0.17462,4015.7
0.17492,4010.5
0.17521,4006.4
0.17549,4001.9
0.17580,3996.4
0.17609,3990.8
0.17639,3986.8
0.17669,3981.2
0.17699,3976.0
0.17729,3968.8
0.17758,3963.7
0.17788,3958.8
0.17818,3952.9
0.17849,3946.9
0.17878,3942.0
0.17905,3936.4
0.17937,3930.0
0.17970,3923.9
0.17998,3918.3
0.18028,3912.2
0.18058,3906.0
0.18088,3900.0
0.18119,3893.3
0.18148,3889.0
0.18178,3881.3
0.18208,3875.3
0.18237,3869.3
0.18269,3863.7
0.18297,3857.7
0.18328,3851.1
0.18359,3844.8
0.18390,3838.8
0.18422,3831.5
0.18452,3824.5
0.18483,3817.8
0.18515,3810.6
0.18547,3803.9
0.18577,3798.1
0.18607,3789.1
0.18639,3782.3
0.18672,3775.4
0.18702,3768.0
0.18732,3761.2
0.18764,3753.2
0.18798,3746.2
0.18830,3738.3
0.18859,3731.3
0.18892,3722.8
0.18924,3715.7
0.18955,3706.4
0.18986,3697.8
0.19017,3691.1
0.19048,3683.3
0.19082,3674.3
0.19113,3667.4
0.19145,3658.0
0.19176,3649.7
0.19210,3640.9
0.19242,3632.4
0.19275,3622.8
0.19310,3613.8
0.19341,3604.6
0.19376,3595.2
0.19412,3586.2
0.19444,3576.1
0.19480,3565.7
0.19512,3554.9
0.19546,3544.9
0.19580,3533.3
0.19613,3522.8
0.19648,3512.4
0.19683,3500.4
0.19717,3489.0
0.19753,3473.7
0.38326,1548.7
0.26315, -22.7
0.26956, -20.6
0.26539, -20.0
0.26683, -19.3
0.26702, -19.4
0.26724, -18.2
0.26752, -18.8
0.26781, -17.1
0.26809, -18.5
0.26836, -16.8
0.26865, -17.2
0.26893, -17.0
0.26920, -16.7
0.26950, -15.6
0.26979, -15.1
0.27002, -14.5
0.27004, -15.2
0.27003, -14.7
0.27003, -15.5
0.27003, -15.3
0.27003, -15.6
0.27004, -13.8
0.27004, -14.6
0.27004, -15.0
0.27003, -14.6
0.27002, -14.0
0.27004, -14.2
0.27006, -14.0
0.27003, -14.4
0.27002, -13.6
0.27006, -14.1
0.27004, -13.0
0.27004, -13.2
0.27004, -13.6
0.27002, -13.1
0.27005, -12.8
0.27003, -14.0
0.27004, -12.8
0.27006, -12.5
0.27007, -11.9
0.27006, -12.6
0.27006, -12.8
0.27005, -12.1
0.27006, -12.1
0.27004, -12.1
0.27003, -11.7
0.27004, -11.4
0.27004, -12.6
0.27004, -11.7
0.27004, -12.0
0.27003, -12.0
0.27004, -11.4
0.27003, -12.3
0.27002, -11.6
0.27005, -12.2
0.27002, -11.1