File: MAE_3272/Module_1/Group1-1018 Annealed.csv
2/12/2016
4:08 PM
Sampling Frequency:,10Hz
Group:,Group1
Extensometer:,E85191
Sample:,1018 Annealed
Sample width [inch]:,0.499000
Sample thickness [inch]:,0.119000
--------,--------

Extensometer,Load
[Inches],[Lbs]
-0.00001,   0.1
-0.00000,   0.4
-0.00000,   0.3
0.00002,   0.6
-0.00001,  -0.4
0.00002,   0.1
0.00001,   1.3
-0.00001,   0.7
0.00001,   0.3
-0.00002,   0.7
0.00001,  -0.7
-0.00001,   0.5
-0.00000,   0.6
-0.00003,  -0.2
-0.00000,  -0.2
-0.00001,  -0.1
-0.00001,  -0.2
0.00001,  -0.3
0.00001,   1.0
-0.00001,   1.0
0.00000,   0.9
-0.00000,   0.4
0.00001,  -0.1
-0.00001,  -0.2
-0.00001,  -0.3
-0.00001,   0.8
0.00000,   0.2
-0.00000,  -0.3
-0.00001,   1.1
-0.00000,  -0.7
-0.00000,   0.4
0.00001,   0.6
0.00001,   0.9
0.00001,   2.2
-0.00001,   5.1
0.00000,   6.2
-0.00000,   7.2
-0.00001,   8.8
-0.00001,  10.1
0.00003,  11.5
0.00003,  14.2
0.00005,  15.1
0.00008,  17.2
0.00010,  18.6
0.00009,  20.5
0.00010,  21.5
0.00012,  22.6
0.00014,  24.4
0.00014,  26.0
0.00017,  28.3
0.00019,  30.0
0.00019,  31.6
0.00021,  35.0
0.00023,  36.3
0.00025,  39.1
0.00026,  42.6
0.00029,  45.6
0.00030,  49.2
0.00031,  52.3
0.00031,  52.4
0.00033,  53.9
0.00031,  51.5
0.00031,  51.4
0.00027,  52.0
0.00023,  52.9
0.00026,  53.0
0.00025,  54.1
0.00026,  55.8
0.00025,  58.6
0.00027,  59.9
0.00029,  62.2
0.00029,  65.0
0.00029,  67.7
0.00029,  70.2
0.00029,  72.5
0.00030,  75.2
0.00032,  78.6
0.00033,  81.7
0.00033,  84.6
0.00035,  88.7
0.00033,  91.9
0.00035,  96.0
0.00036,  99.8
0.00037, 104.1
0.00038, 107.7
0.00040, 112.2
0.00041, 117.2
0.00041, 123.0
0.00042, 125.8
0.00043, 131.8
0.00042, 134.1
0.00044, 140.8
0.00047, 144.1
0.00046, 149.7
0.00047, 154.0
0.00050, 157.5
0.00049, 162.9
0.00050, 166.9
0.00050, 171.9
0.00052, 177.8
0.00051, 182.0
0.00053, 186.0
0.00055, 190.9
0.00055, 195.8
0.00056, 200.3
0.00057, 204.7
0.00058, 209.0
0.00058, 213.0
0.00058, 219.1
0.00059, 222.7
0.00059, 227.2
0.00061, 231.7
0.00061, 236.8
0.00061, 243.2
0.00063, 247.5
0.00065, 252.7
0.00065, 257.4
0.00066, 263.1
0.00067, 269.5
0.00068, 277.5
0.00067, 283.1
0.00070, 290.6
0.00068, 297.7
0.00071, 304.2
0.00072, 310.8
0.00074, 318.0
0.00073, 324.3
0.00074, 330.7
0.00074, 336.7
0.00076, 342.1
0.00077, 349.2
0.00077, 356.5
0.00079, 362.2
0.00079, 368.7
0.00080, 374.2
0.00081, 380.2
0.00083, 388.6
0.00080, 395.4
0.00084, 402.9
0.00084, 409.5
0.00086, 417.7
0.00087, 424.2
0.00087, 431.1
0.00088, 440.5
0.00086, 448.8
0.00089, 456.0
0.00090, 465.3
0.00089, 472.7
0.00091, 482.4
0.00092, 490.2
0.00092, 499.6
0.00094, 508.0
0.00096, 516.8
0.00097, 525.0
0.00097, 534.8
0.00097, 542.5
0.00097, 551.8
0.00098, 559.1
0.00100, 567.7
0.00100, 577.6
0.00101, 585.9
0.00101, 595.8
0.00104, 606.6
0.00105, 615.6
0.00106, 627.6
0.00106, 638.1
0.00108, 649.0
0.00110, 659.8
0.00110, 668.7
0.00111, 681.2
0.00112, 693.5
0.00114, 707.0
0.00116, 717.6
0.00117, 726.0
0.00120, 741.5
0.00118, 755.3
0.00120, 769.8
0.00122, 784.6
0.00123, 795.4
0.00125, 809.4
0.00128, 824.0
0.00127, 837.7
0.00130, 853.1
0.00131, 868.0
0.00133, 883.7
0.00135, 898.2
0.00136, 914.3
0.00139, 930.5
0.00140, 946.2
0.00143, 963.2
0.00143, 980.1
0.00144, 995.4
0.00147,1012.9
0.00149,1030.7
0.00150,1048.8
0.00153,1067.7
0.00154,1084.9
0.00156,1103.1
0.00159,1122.0
0.00161,1140.4
0.00162,1158.3
0.00165,1176.4
0.00166,1194.6
0.00169,1213.7
0.00172,1234.8
0.00172,1253.6
0.00177,1272.0
0.00176,1292.2
0.00180,1310.9
0.00180,1331.8
0.00183,1351.3
0.00186,1372.2
0.00188,1393.3
0.00190,1413.5
0.00193,1434.5
0.00197,1454.8
0.00197,1474.9
0.00198,1495.7
0.00201,1517.0
0.00206,1537.4
0.00205,1558.6
0.00208,1580.4
0.00211,1601.6
0.00212,1622.3
0.00217,1642.6
0.00217,1664.6
0.00219,1687.2
0.00222,1707.6
0.00225,1729.7
0.00228,1750.4
0.00229,1772.3
0.00230,1792.5
0.00232,1816.0
0.00234,1836.4
0.00238,1859.1
0.00241,1879.5
0.00240,1901.2
0.00244,1923.4
0.00246,1945.3
0.00247,1967.8
0.00250,1990.1
0.00253,2011.1
0.00252,2031.8
0.00256,2054.2
0.00255,2076.2
0.00256,2096.6
0.00258,2116.4
0.00260,2137.7
0.00261,2159.9
0.00262,2180.0
0.00262,2200.1
0.00262,2220.5
0.00263,2238.5
0.00264,2255.1
0.00265,2274.0
0.00265,2293.4
0.00267,2311.1
0.00265,2324.8
0.00265,2338.7
0.00265,2350.6
0.00264,2355.3
0.00255,2347.3
0.00251,2344.8
0.00247,2346.6
0.00244,2347.5
0.00251,2348.4
0.00269,2347.3
0.00289,2344.6
0.00309,2341.9
0.00334,2335.3
0.00371,2328.3
0.00411,2326.8
0.00455,2325.5
0.00498,2317.1
0.00541,2315.6
0.00588,2313.9
0.00634,2312.4
0.00699,2291.9
0.00739,2281.8
0.00795,2278.3
0.00846,2277.1
0.00897,2280.2
0.00945,2285.9
0.00994,2282.7
0.01046,2283.4
0.01099,2281.0
0.01152,2280.6
0.01205,2281.6
0.01259,2283.3
0.01317,2282.7
0.01373,2281.8
0.01442,2276.9
0.01511,2267.6
0.01567,2272.5
0.01620,2283.2
0.01672,2292.9
0.01725,2299.6
0.01777,2307.2
0.01831,2309.3
0.01887,2313.8
0.01943,2317.8
0.01997,2321.7
0.02052,2324.4
0.02108,2325.2
0.02164,2326.5
0.02221,2328.1
0.02280,2329.6
0.02342,2328.4
0.02402,2329.7
0.02463,2328.7
0.02525,2324.4
0.02598,2317.0
0.02671,2305.0
0.02739,2301.9
0.02801,2307.5
0.02866,2306.2
0.02922,2317.6
0.02978,2326.4
0.03042,2322.8
0.03108,2323.4
0.03168,2324.2
0.03225,2330.9
0.03284,2337.3
0.03343,2340.8
0.03407,2337.0
0.03481,2324.9
0.03553,2314.7
0.03627,2304.1
0.03692,2302.2
0.03761,2295.6
0.03831,2290.7
0.03897,2290.8
0.03963,2292.3
0.04020,2301.7
0.04081,2308.9
0.04139,2318.3
0.04195,2326.5
0.04251,2333.3
0.04309,2339.6
0.04367,2346.0
0.04427,2348.8
0.04489,2349.5
0.04551,2350.0
0.04615,2348.3
0.04675,2348.6
0.04739,2347.0
0.04802,2344.9
0.04864,2342.9
0.04928,2343.0
0.04993,2340.2
0.05062,2333.0
0.05139,2312.2
0.05261,2239.3
0.05333,2238.2
0.05376,2273.2
0.05411,2311.6
0.05450,2346.5
0.05491,2372.4
0.05531,2390.6
0.05569,2405.3
0.05607,2415.9
0.05644,2424.4
0.05680,2433.0
0.05713,2439.3
0.05747,2446.6
0.05776,2446.5
0.05808,2451.5
0.05838,2459.3
0.05869,2465.3
0.05901,2472.0
0.05933,2476.4
0.05970,2481.7
0.06002,2487.3
0.06040,2490.6
0.06074,2495.8
0.06109,2500.7
0.06146,2503.9
0.06182,2508.7
0.06218,2511.8
0.06253,2517.9
0.06289,2522.1
0.06325,2527.2
0.06362,2533.0
0.06398,2537.1
0.06435,2540.1
0.06474,2545.2
0.06510,2547.8
0.06546,2552.8
0.06582,2557.7
0.06620,2562.3
0.06656,2564.9
0.06692,2569.3
0.06727,2573.7
0.06764,2578.6
0.06801,2581.7
0.06838,2586.6
0.06874,2590.8
0.06910,2593.5
0.06948,2597.7
0.06983,2600.3
0.07021,2605.9
0.07058,2611.3
0.07097,2613.9
0.07133,2618.1
0.07171,2620.9
0.07206,2626.2
0.07245,2629.7
0.07283,2634.5
0.07322,2637.2
0.07360,2641.0
0.07399,2644.9
0.07437,2649.3
0.07475,2653.3
0.07512,2657.1
0.07548,2661.9
0.07589,2664.3
0.07626,2669.7
0.07667,2673.3
0.07703,2676.8
0.07743,2681.2
0.07785,2684.8
0.07822,2688.6
0.07863,2692.2
0.07901,2695.0
0.07941,2699.0
0.07979,2702.5
0.08018,2707.2
0.08057,2710.3
0.08096,2713.1
0.08134,2717.7
0.08175,2721.1
0.08212,2723.4
0.08251,2728.1
0.08289,2731.0
0.08326,2733.9
0.08364,2736.0
0.08399,2739.0
0.08434,2744.3
0.08472,2748.2
0.08508,2751.9
0.08543,2754.2
0.08581,2758.5
0.08617,2761.7
0.08657,2765.9
0.08694,2768.9
0.08733,2771.6
0.08771,2775.9
0.08809,2778.5
0.08848,2782.5
0.08888,2785.6
0.08926,2788.6
0.08966,2792.7
0.09004,2795.4
0.09042,2798.3
0.09082,2800.3
0.09121,2803.2
0.09157,2806.0
0.09196,2810.4
0.09233,2812.8
0.09271,2814.7
0.09309,2817.3
0.09342,2819.9
0.09379,2824.0
0.09414,2828.0
0.09449,2829.5
0.09485,2831.2
0.09519,2833.1
0.09553,2837.4
0.09590,2840.2
0.09624,2841.0
0.09657,2844.6
0.09689,2846.3
0.09723,2850.2
0.09756,2854.3
0.09790,2857.8
0.09826,2859.4
0.09860,2861.9
0.09894,2863.4
0.09926,2867.9
0.09962,2869.4
0.09996,2872.2
0.10030,2875.0
0.10066,2877.6
0.10099,2880.3
0.10136,2883.3
0.10173,2885.6
0.10206,2887.6
0.10240,2890.3
0.10274,2893.2
0.10309,2895.5
0.10342,2896.2
0.10376,2898.9
0.10409,2900.0
0.10441,2900.7
0.10474,2905.7
0.10505,2907.0
0.10537,2910.3
0.10568,2911.5
0.10602,2914.4
0.10633,2916.4
0.10666,2918.3
0.10699,2922.8
0.10732,2923.1
0.10763,2926.8
0.10796,2928.5
0.10829,2931.0
0.10861,2932.6
0.10896,2936.4
0.10930,2938.0
0.10964,2941.7
0.10999,2943.5
0.11031,2946.6
0.11068,2949.3
0.11103,2950.9
0.11138,2953.2
0.11172,2954.9
0.11205,2956.9
0.11241,2960.3
0.11276,2961.7
0.11312,2964.4
0.11347,2967.2
0.11382,2970.6
0.11418,2972.2
0.11454,2974.8
0.11491,2976.6
0.11527,2977.8
0.11563,2981.9
0.11599,2984.9
0.11636,2986.7
0.11671,2988.8
0.11708,2990.8
0.11746,2992.7
0.11782,2995.1
0.11819,2997.1
0.11856,2999.8
0.11892,3003.1
0.11928,3003.8
0.11965,3006.3
0.12002,3009.0
0.12040,3010.9
0.12076,3014.3
0.12113,3015.6
0.12151,3018.5
0.12189,3020.1
0.12225,3022.1
0.12262,3024.8
0.12296,3026.6
0.12333,3028.1
0.12370,3031.0
0.12407,3035.1
0.12446,3041.9
0.12492,3047.4
0.12544,3052.1
0.12593,3053.7
0.12648,3057.2
0.12699,3060.6
0.12756,3064.5
0.12811,3066.8
0.12869,3072.1
0.12927,3074.2
0.12986,3077.9
0.13050,3082.2
0.13111,3085.7
0.13173,3087.9
0.13234,3092.6
0.13300,3096.4
0.13365,3099.0
0.13427,3101.5
0.13490,3105.0
0.13554,3108.5
0.13617,3112.4
0.13681,3115.1
0.13746,3119.0
0.13809,3122.9
0.13874,3125.5
0.13939,3128.0
0.14003,3130.7
0.14068,3134.2
0.14130,3137.9
0.14197,3140.3
0.14260,3144.0
0.14326,3145.8
0.14389,3150.1
0.14454,3153.3
0.14516,3156.6
0.14583,3159.7
0.14649,3163.5
0.14712,3164.2
0.14776,3166.9
0.14841,3170.6
0.14906,3173.0
0.14970,3176.1
0.15035,3179.1
0.15101,3181.6
0.15166,3184.9
0.15232,3189.3
0.15299,3191.5
0.15365,3193.4
0.15431,3197.2
0.15495,3199.1
0.15562,3201.9
0.15627,3204.9
0.15694,3207.7
0.15759,3210.2
0.15826,3213.1
0.15891,3215.0
0.15958,3218.3
0.16024,3219.7
0.16091,3222.3
0.16157,3225.2
0.16222,3227.7
0.16287,3229.2
0.16350,3232.1
0.16416,3235.1
0.16481,3237.0
0.16544,3239.8
0.16607,3241.9
0.16672,3243.5
0.16737,3246.5
0.16802,3250.2
0.16869,3253.5
0.16936,3254.7
0.17002,3257.8
0.17068,3258.3
0.17137,3261.4
0.17203,3263.8
0.17270,3267.0
0.17341,3269.8
0.17408,3271.1
0.17476,3273.5
0.17544,3274.7
0.17610,3278.7
0.17681,3281.1
0.17749,3283.0
0.17817,3284.7
0.17888,3286.9
0.17957,3288.7
0.18026,3291.6
0.18095,3293.2
0.18165,3295.1
0.18234,3297.1
0.18303,3298.6
0.18373,3302.3
0.18442,3302.7
0.18510,3305.4
0.18580,3306.8
0.18646,3307.3
0.18714,3311.5
0.18781,3314.0
0.18849,3313.9
0.18917,3315.5
0.18984,3317.1
0.19049,3318.7
0.19113,3320.8
0.19181,3321.3
0.19246,3323.9
0.19312,3324.9
0.19374,3325.8
0.19437,3327.1
0.19498,3329.0
0.19560,3330.3
0.19622,3331.4
0.19683,3332.0
0.19745,3333.9
0.19802,3336.5
0.19867,3338.0
0.19928,3339.4
0.19990,3341.4
0.20053,3343.6
0.20117,3346.5
0.20182,3347.6
0.20249,3349.8
0.20312,3351.1
0.20379,3352.8
0.20445,3355.4
0.20515,3356.3
0.20582,3357.7
0.20647,3360.1
0.20718,3360.8
0.20783,3362.8
0.20853,3365.2
0.20920,3365.4
0.20988,3366.5
0.21056,3366.7
0.21122,3369.6
0.21190,3372.1
0.21259,3372.6
0.21326,3373.7
0.21391,3374.7
0.21458,3376.6
0.21524,3377.2
0.21588,3380.4
0.21654,3380.1
0.21719,3382.6
0.21787,3384.1
0.21856,3386.4
0.21922,3388.4
0.21994,3390.1
0.22062,3390.9
0.22132,3393.0
0.22203,3393.5
0.22273,3396.6
0.22345,3397.1
0.22418,3398.7
0.22488,3399.8
0.22560,3401.6
0.22633,3400.8
0.22704,3404.3
0.22779,3405.2
0.22852,3408.1
0.22926,3407.9
0.23001,3410.8
0.23075,3411.8
0.23152,3412.7
0.23225,3414.2
0.23301,3415.5
0.23377,3416.9
0.23451,3418.4
0.23526,3419.7
0.23601,3420.2
0.23674,3421.9
0.23750,3423.3
0.23826,3425.8
0.23903,3425.7
0.23980,3426.4
0.24054,3428.6
0.24133,3429.6
0.24210,3431.5
0.24288,3433.1
0.24368,3434.3
0.24443,3436.7
0.24522,3436.8
0.24601,3437.5
0.24677,3438.3
0.24753,3439.7
0.24831,3442.4
0.24910,3442.9
0.24991,3444.2
0.25066,3445.0
0.25146,3445.8
0.25223,3447.4
0.25299,3448.8
0.25378,3450.8
0.25457,3450.0
0.25537,3451.9
0.25614,3451.9
0.25692,3454.1
0.25773,3454.8
0.25851,3455.6
0.25930,3458.1
0.26010,3457.7
0.26089,3458.4
0.26170,3461.0
0.26249,3461.6
0.26328,3461.8
0.26411,3464.0
0.26491,3464.5
0.26572,3464.8
0.26651,3466.1
0.26730,3466.2
0.26811,3468.8
0.26890,3469.9
0.26971,3471.0
0.27052,3472.1
0.27131,3471.5
0.27212,3472.8
0.27293,3473.9
0.27373,3474.6
0.27453,3475.1
0.27533,3476.5
0.27615,3476.6
0.27695,3478.6
0.27776,3479.1
0.27858,3479.8
0.27939,3481.0
0.28019,3481.1
0.28100,3481.4
0.28180,3484.0
0.28261,3484.1
0.28342,3484.8
0.28424,3486.4
0.28506,3486.9
0.28588,3487.1
0.28670,3488.8
0.28753,3489.7
0.28834,3489.8
0.28918,3491.3
0.29001,3491.9
0.29081,3492.0
0.29164,3493.3
0.29247,3493.5
0.29330,3494.5
0.29413,3495.5
0.29493,3495.7
0.29576,3495.9
0.29658,3496.3
0.29741,3497.6
0.29825,3499.2
0.29907,3498.4
0.29989,3499.2
0.30074,3500.8
0.30157,3501.2
0.30240,3502.4
0.30322,3502.2
0.30407,3502.6
0.30491,3502.6
0.30574,3504.0
0.30656,3505.1
0.30739,3504.1
0.30821,3506.1
0.30906,3506.9
0.30991,3507.9
0.31076,3508.4
0.31158,3506.7
0.31243,3507.7
0.31327,3508.9
0.31411,3509.4
0.31496,3510.3
0.31582,3512.5
0.31667,3512.2
0.31754,3512.2
0.31839,3512.5
0.31924,3512.6
0.32010,3513.1
0.32095,3515.1
0.32181,3515.0
0.32267,3515.5
0.32351,3515.4
0.32435,3517.2
0.32520,3515.4
0.32607,3518.4
0.32693,3518.7
0.32778,3518.0
0.32867,3518.3
0.32953,3519.5
0.33037,3519.9
0.33125,3520.5
0.33210,3520.7
0.33298,3521.2
0.33385,3521.8
0.33471,3520.7
0.33556,3521.9
0.33644,3522.1
0.33729,3523.3
0.33816,3523.7
0.33904,3524.6
0.33992,3523.7
0.34078,3524.0
0.34164,3525.1
0.34251,3524.7
0.34338,3527.0
0.34429,3526.4
0.34517,3525.5
0.34607,3526.3
0.34694,3525.5
0.34780,3526.6
0.34869,3527.0
0.34959,3527.9
0.35050,3528.7
0.35139,3529.2
0.35227,3527.7
0.35315,3529.5
0.35402,3529.2
0.35490,3528.8
0.35579,3530.4
0.35667,3529.6
0.35756,3529.7
0.35846,3530.3
0.35935,3530.9
0.36027,3530.2
0.36113,3531.3
0.36202,3530.2
0.36294,3531.2
0.36381,3531.3
0.36470,3531.5
0.36562,3532.2
0.36650,3531.6
0.36738,3532.4
0.36827,3533.9
0.36919,3532.4
0.37009,3532.5
0.37098,3532.5
0.37189,3534.0
0.37280,3533.2
0.37368,3533.7
0.37460,3533.6
0.37549,3534.3
0.37640,3534.5
0.37730,3535.5
0.37823,3534.5
0.37911,3534.9
0.38000,3533.5
0.38092,3534.5
0.38178,3535.3
0.38267,3536.1
0.38358,3533.9
0.38448,3535.2
0.38538,3534.8
0.38629,3535.8
0.38722,3536.8
0.38812,3536.0
0.38907,3536.3
0.38999,3536.1
0.39088,3534.7
0.39179,3535.9
0.39271,3536.5
0.39362,3536.4
0.39454,3536.5
0.39547,3535.9
0.39637,3534.9
0.39728,3535.9
0.39822,3537.0
0.39913,3536.5
0.40005,3535.9
0.40099,3536.3
0.40190,3536.3
0.40284,3537.3
0.40380,3536.9
0.40470,3536.7
0.40565,3536.6
0.40657,3536.3
0.40751,3535.3
0.40843,3536.4
0.40935,3536.2
0.41028,3535.8
0.41119,3536.0
0.41214,3536.1
0.41308,3535.6
0.41402,3534.4
0.41494,3536.7
0.41589,3535.7
0.41680,3535.0
0.41775,3536.4
0.41868,3537.1
0.41965,3536.2
0.42058,3535.3
0.42151,3535.3
0.42241,3535.8
0.42334,3535.7
0.42428,3535.1
0.42522,3535.2
0.42618,3536.5
0.42714,3535.4
0.42808,3535.3
0.42902,3535.3
0.42997,3534.4
0.43091,3535.7
0.43187,3535.9
0.43283,3535.2
0.43381,3535.6
0.43478,3533.8
0.43573,3533.5
0.43668,3534.3
0.43765,3534.2
0.43862,3534.4
0.43958,3534.2
0.44055,3534.4
0.44151,3533.6
0.44250,3532.0
0.44347,3532.2
0.44445,3531.3
0.44541,3533.0
0.44637,3531.6
0.44733,3531.0
0.44828,3530.9
0.44926,3530.5
0.45025,3530.7
0.45121,3530.8
0.45220,3531.1
0.45318,3529.6
0.45415,3529.2
0.45511,3530.1
0.45610,3529.9
0.45707,3529.6
0.45806,3528.4
0.45904,3529.5
0.46003,3528.9
0.46100,3527.1
0.46198,3527.1
0.46298,3527.4
0.46397,3527.4
0.46497,3527.0
0.46598,3525.1
0.46700,3525.7
0.46796,3525.2
0.46897,3524.4
0.46996,3524.3
0.47095,3524.7
0.47196,3524.0
0.47297,3522.3
0.47397,3522.3
0.47495,3520.3
0.47594,3520.6
0.47691,3520.4
0.47792,3521.2
0.47895,3520.7
0.47996,3518.6
0.48097,3517.8
0.48197,3517.7
0.48296,3518.2
0.48396,3516.1
0.48494,3516.4
0.48596,3514.5
0.48695,3514.7
0.48797,3514.9
0.48897,3513.1
0.49000,3513.0
0.49100,3512.8
0.49203,3510.9
0.49306,3509.4
0.49407,3509.1
0.49509,3508.7
0.49608,3507.7
0.49708,3505.3
0.49808,3505.6
0.49909,3504.0
0.50013,3504.2
0.50115,3503.2
0.50215,3502.0
0.50317,3500.9
0.50419,3500.3
0.50522,3497.7
0.50628,3496.6
0.50728,3495.0
0.50831,3494.1
0.50936,3492.4
0.51038,3491.9
0.51141,3488.4
0.51244,3487.2
0.51347,3487.2
0.51450,3483.8
0.51554,3483.2
0.51659,3481.3
0.51761,3478.5
0.51863,3477.4
0.51968,3476.1
0.52072,3472.9
0.52177,3470.3
0.52282,3467.4
0.52385,3466.6
0.52489,3463.0
0.52594,3461.2
0.52697,3458.9
0.52802,3455.9
0.52907,3452.5
0.53008,3448.9
0.53110,3445.7
0.53210,3442.4
0.53308,3438.9
0.53403,3435.8
0.53502,3433.0
0.53598,3429.0
0.53695,3425.7
0.53793,3423.3
0.53893,3419.1
0.53989,3416.1
0.54088,3412.2
0.54184,3407.6
0.54282,3403.5
0.54377,3401.6
0.54475,3396.7
0.54570,3392.7
0.54663,3388.6
0.54759,3383.7
0.54853,3380.8
0.54953,3377.7
0.55051,3373.1
0.55148,3366.5
0.55243,3362.8
0.55337,3358.6
0.55432,3353.7
0.55526,3349.2
0.55620,3344.6
0.55716,3339.4
0.55814,3333.6
0.55910,3328.5
0.56005,3322.9
0.56100,3316.6
0.56198,3312.5
0.56294,3307.1
0.56389,3301.3
0.56488,3294.7
0.56585,3288.6
0.56681,3281.9
0.56777,3275.1
0.56873,3269.3
0.56968,3263.1
0.57064,3256.8
0.57161,3250.2
0.57257,3241.9
0.57351,3236.1
0.57448,3228.5
0.57544,3220.8
0.57639,3214.1
0.57736,3205.3
0.57832,3198.3
0.57928,3188.4
0.58019,3180.1
0.58114,3173.9
0.58207,3165.1
0.58300,3156.4
0.58391,3148.2
0.58485,3139.1
0.58579,3129.8
0.58671,3122.1
0.58765,3110.8
0.58855,3102.1
0.58946,3092.4
0.59036,3083.3
0.59126,3071.2
0.59219,3061.3
0.59310,3051.0
0.59403,3041.3
0.59492,3028.0
0.59580,3016.8
0.59667,3005.0
0.59761,2994.1
0.59848,2979.9
0.59942,2967.9
0.60031,2954.6
0.60125,2940.6
0.60217,2925.8
0.60311,2910.2
0.60403,2895.9
0.60495,2878.2
0.60586,2862.1
0.60682,2843.2
0.60775,2823.0
0.60870,2800.1
0.60316, 266.5
0.58540, -14.6
0.60470, -13.7
0.59859, -13.3
0.59885, -13.6
0.59927, -13.3
0.59970, -12.8
0.60021, -12.2
0.60078, -11.4
0.60134, -11.6
0.60195, -20.3
0.60220, -11.8
0.60218, -10.4
0.60219,  -9.9
0.60219, -10.2
0.60219, -10.0
0.60219, -10.8
0.60218,  -8.7
0.60219,  -9.2
0.60218,  -8.3
0.60217,  -9.1
0.60219,  -9.3
0.60219,  -9.4
0.60220,  -8.4
0.60218,  -7.9
0.60219,  -8.5
0.60220,  -8.5
0.60219,  -8.4
0.60218,  -8.0
0.60220,  -8.1
0.60219,  -8.0
0.60218,  -8.0
0.60218,  -7.4
0.60217,  -7.5
0.60220,  -7.9
0.60219,  -8.0
0.60220,  -6.6
0.60218,  -6.9
0.60220,  -7.6
0.60220,  -6.4
0.60218,  -7.5
0.60219,  -6.8
0.60220,  -8.2
0.60217,  -7.8
0.60218,  -6.5
0.60220,  -7.3
0.60219,  -6.8
0.60220,  -6.6
0.60219,  -7.0
0.60221,  -6.7
0.60220,  -7.3
0.60218,  -6.8
0.60219,  -6.6
0.60221,  -6.9
0.60218,  -7.1
0.60222,  -8.2
0.60219,  -6.9
0.60219,  -7.3
0.60221,  -6.5
0.60221,  -5.8
0.60220,  -5.8
0.60219,  -7.0
0.60221,  -5.9
0.60218,  -7.4
0.60219,  -6.2
0.60218,  -6.9
0.60219,  -6.9
0.60220,  -5.8
0.60219,  -6.4
0.60218,  -6.0
0.60219,  -6.6
0.60219,  -6.4
0.60220,  -6.7
0.60219,  -6.7
0.60219,  -6.3
0.60219,  -6.2
0.60218,  -5.7
0.60218,  -6.5
0.60218,  -6.7
0.60220,  -6.9
0.60219,  -6.4
0.60219,  -6.6
0.60220,  -6.6
0.60220,  -6.3
0.60218,  -6.4
0.60219,  -6.2
0.60218,  -6.2
0.60219,  -6.2
0.60218,  -6.7
0.60219,  -5.6
0.60219,  -4.3
0.60219,  -6.2
0.60220,  -5.9
0.60220,  -5.8
0.60219,  -6.1
0.60220,  -6.1
0.60221,  -5.5
0.60220,  -6.0
0.60221,  -6.9
0.60218,  -6.4
0.60219,  -6.3
0.60217,  -6.2
0.60219,  -5.7
0.60219,  -5.9
0.60219,  -5.9
0.60219,  -6.6
0.60218,  -6.6
0.60217,  -6.3
0.60216,  -6.2
0.60216,  -5.8
0.60216,  -5.9
0.60218,  -6.5
0.60217,  -5.5
0.60219,  -4.7
0.60219,  -6.5
0.60218,  -5.9
0.60217,  -5.9
0.60218,  -5.7
0.60217,  -5.8
0.60219,  -6.0
0.60218,  -5.0
0.60218,  -5.1
0.60219,  -5.6
0.60217,  -5.8
0.60219,  -7.5
0.60218,  -6.0
0.60220,  -6.5
0.60219,  -5.7
0.60218,  -5.7
0.60220,  -5.4
0.60219,  -4.7
0.60219,  -5.2
0.60220,  -5.9
0.60218,  -5.1
0.60219,  -6.1
0.60219,  -5.1
0.60219,  -5.1
0.60219,  -5.2
0.60219,  -6.2
0.60220,  -5.6
0.60219,  -5.9
0.60218,  -4.5
0.60219,  -5.5
0.60218,  -5.3
0.60221,  -4.9
0.60218,  -5.0
0.60219,  -5.2
0.60221,  -4.7
0.60221,  -5.9
0.60219,  -5.2
0.60219,  -6.0
0.60221,  -5.5
0.60219,  -4.8
0.60220,  -5.7
0.60219,  -5.5
0.60217,  -5.5
0.60219,  -6.3
0.60217,  -6.4
0.60217,  -6.2
0.60217,  -5.7
0.60220,  -6.4
0.60217,  -5.8
0.60218,  -5.9
0.60218,  -5.8
0.60220,  -5.0
0.60220,  -6.3
0.60218,  -5.4
0.60219,  -6.6
0.60219,  -5.1
0.60219,  -6.1
0.60218,  -5.3
0.60219,  -5.6
0.60220,  -5.0
0.60217,  -6.6
0.60218,  -5.9
0.60219,  -5.1
0.60219,  -5.7
0.60220,  -5.4
0.60218,  -5.6
0.60219,  -4.6
0.60219,  -4.9
0.60218,  -4.5
0.60218,  -5.4
0.60217,  -4.7
0.60219,  -6.2
0.60219,  -5.1
0.60218,  -4.9
0.60221,  -4.9
0.60219,  -5.3
0.60220,  -5.7
0.60218,  -5.2
0.60219,  -5.6
0.60219,  -4.9
0.60218,  -4.7
0.60218,  -6.4
0.60219,  -6.1
0.60219,  -6.3
0.60218,  -5.5
0.60219,  -6.4
0.60219,  -5.5
0.60220,  -5.6
0.60218,  -4.3
0.60219,  -5.1
0.60219,  -4.8
0.60219,  -4.4
0.60219,  -5.2
0.60218,  -5.5
0.60220,  -5.5
0.60218,  -5.4
0.60220,  -4.8
0.60219,  -5.0
0.60219,  -5.2