File: MAE_3272/Module_1/Group1-1018 Cold Rolled_4.csv
2/12/2016
3:31 PM
Sampling Frequency:,10Hz
Group:,Group1
Extensometer:,E85191
Sample:,1018 Cold Rolled
Sample width [inch]:,0.497000
Sample thickness [inch]:,0.124000
--------,--------

Extensometer,Load
[Inches],[Lbs]
0.00001,   0.4
0.00001,   0.7
0.00002,   0.1
0.00002,   0.3
0.00002,   0.7
0.00001,  -0.2
0.00001,   0.1
0.00002,   0.9
0.00001,   0.1
0.00001,   1.6
0.00002,  -0.3
0.00001,   1.6
0.00001,   0.9
-0.00001,   0.6
0.00002,   0.4
0.00001,   0.7
-0.00000,   0.3
0.00000,  -0.9
0.00002,   0.1
0.00001,  -0.1
0.00001,   1.5
0.00000,   0.2
0.00004,   0.7
0.00000,  -0.3
0.00003,  -1.2
0.00003,  -0.4
0.00002,  -0.7
0.00003,   0.9
0.00003,   0.7
0.00001,   0.4
0.00003,   0.9
0.00002,   0.7
0.00002,   0.0
0.00003,   0.3
0.00002,   0.7
0.00002,   0.2
0.00002,   1.2
0.00002,  -0.0
0.00003,   0.9
0.00003,   0.4
0.00003,  -0.0
0.00002,  -0.1
0.00003,  -0.5
0.00003,   0.1
0.00001,  -0.2
0.00003,  -4.7
0.00001,   0.0
0.00002,  -0.3
0.00002,  -0.3
0.00003,   0.1
0.00001,   0.0
0.00002,   0.6
0.00002,   0.4
0.00003,   0.1
0.00002,   2.4
0.00005,   1.9
0.00003,   2.4
0.00004,   2.0
0.00003,   2.1
0.00004,   3.7
0.00005,   3.5
0.00003,   2.3
0.00004,   3.0
0.00003,   4.6
0.00004,   4.5
0.00003,   4.0
0.00003,   4.4
0.00004,   3.7
0.00004,   3.4
0.00004,   4.2
0.00004,   5.4
0.00003,   5.2
0.00004,   4.6
0.00004,   4.9
0.00004,   5.3
0.00003,   5.5
0.00004,   5.1
0.00002,   4.9
0.00004,   5.0
0.00004,   5.1
0.00005,   5.7
0.00005,   4.9
0.00004,   5.9
0.00003,   6.0
0.00005,   5.9
0.00005,   6.1
0.00005,   5.3
0.00004,   5.1
0.00004,   5.3
0.00004,   5.8
0.00006,   5.1
0.00004,   6.6
0.00005,   4.5
0.00004,   5.7
0.00006,   5.7
0.00004,   6.5
0.00004,   5.5
0.00003,   3.4
0.00004,   4.1
0.00003,   4.1
0.00004,   4.7
0.00004,   5.0
0.00004,   4.4
0.00002,   4.1
0.00003,   4.3
0.00002,   4.5
0.00004,   5.0
0.00006,   5.7
0.00004,   4.6
0.00004,   4.7
0.00005,   5.3
0.00004,   5.0
0.00005,   4.4
0.00004,   4.4
0.00004,   4.5
0.00004,   4.2
0.00003,   4.9
0.00003,   4.1
0.00004,   5.3
0.00004,   4.9
0.00005,   4.8
0.00006,   4.1
0.00005,   4.6
0.00005,   3.9
0.00005,   5.2
0.00004,   5.1
0.00004,   4.5
0.00004,   4.2
0.00005,   4.2
0.00006,   4.2
0.00005,   3.8
0.00005,   3.3
0.00005,   5.2
0.00005,   4.6
0.00005,   6.0
0.00005,   5.5
0.00005,   5.2
0.00006,   5.1
0.00006,   5.7
0.00007,   6.0
0.00005,   5.8
0.00005,   4.9
0.00005,   6.1
0.00004,   5.7
0.00004,   5.8
0.00005,   5.8
0.00006,   5.7
0.00006,   5.7
0.00004,   4.8
0.00005,   5.4
0.00003,   6.5
0.00004,   6.2
0.00005,   6.6
0.00006,   5.9
0.00006,   6.1
0.00006,   5.3
0.00006,   5.4
0.00004,   5.7
0.00005,   5.5
0.00007,   5.8
0.00004,   6.2
0.00004,   5.5
0.00005,   5.0
0.00005,   6.1
0.00005,   6.3
0.00006,   5.4
0.00005,   4.7
0.00007,   5.3
0.00006,   4.9
0.00005,   5.7
0.00006,   6.1
0.00006,   5.6
0.00005,   4.5
0.00006,   5.7
0.00006,   5.7
0.00005, -11.6
0.00008,   5.6
0.00006,   5.2
0.00005,   4.7
0.00006,   4.8
0.00005,   6.0
0.00005,   4.9
0.00005,   5.6
0.00006,   5.8
0.00005,   5.0
0.00006,   4.9
0.00005,   5.0
0.00005,   5.5
0.00006,   5.8
0.00007,   6.0
0.00005,   5.9
0.00004,   5.2
0.00006,   5.1
0.00006,   5.0
0.00006,   4.6
0.00006,   5.5
0.00006,   5.7
0.00006,   5.2
0.00007,   5.4
0.00006,   5.5
0.00005,   5.3
0.00007,   5.3
0.00008,   5.6
0.00005,   4.7
0.00007,   4.5
0.00007,   4.9
0.00006,   4.7
0.00004,   4.1
0.00005,   6.3
0.00006,   4.7
0.00006,   6.4
0.00007,   5.0
0.00006,   5.8
0.00006,   4.4
-0.00035,   5.9
-0.00204,   4.2
-0.00197,   4.1
-0.00200,   4.7
-0.00264,   5.0
-0.00397,   3.8
-0.01964,   4.6
0.01618,   3.3
0.00725,   4.3
-0.00677,   5.3
-0.12615,   4.4
-0.11003,   4.4
0.01613,   4.7
0.11196,   4.9
0.13596,   4.6
0.10613,   4.0
0.08428,   4.8
-0.08089,   4.1
-0.06943,   4.2
-0.05084,   5.2
-0.25234,   4.6
-0.29349,   5.3
-0.15749,   4.2
-0.16349,   3.9
-0.16973,   4.7
-0.16282,   4.7
-0.16677,   5.1
-0.17034,   4.6
-0.16611,   4.8
-0.16611,   4.0
-0.16609,   4.4
-0.16611,   5.2
-0.16611,   5.3
-0.16611,   4.0
-0.16611,   4.2
-0.16610,   6.5
-0.16609,   7.5
-0.16609,   8.9
-0.16609,   5.1
-0.16611,   3.7
-0.16611,   4.7
-0.16610,   6.3
-0.16608,   5.9
-0.16609,   7.1
-0.16609,   6.8
-0.16610,   6.0
-0.16608,   5.7
-0.16609,   5.5
-0.16610,   4.8
-0.16611,   3.4
-0.16611,   4.1
-0.16608,   5.0
-0.16607,   5.2
-0.16609,   6.1
-0.16610,   5.6
-0.16608,   6.5
-0.16609,   5.7
-0.16609,   6.8
-0.16610,   7.0
-0.16609,   6.5
-0.16609,   6.7
-0.16609,   7.1
-0.16610,   8.2
-0.16610,   7.5
-0.16609,   6.6
-0.16608,   7.6
-0.16607,   7.4
-0.16609,   6.3
-0.16609,   6.4
-0.16608,   6.5
-0.16608,   5.4
-0.16608,   5.8
-0.16608,   5.7
-0.16608,   3.6
-0.16609,   2.0
-0.16608,   1.5
-0.16608,  -0.4
-0.16610,  -0.5
-0.16607,  -2.1
-0.16609,   0.2
-0.16607,  -0.6
-0.16609,  -0.7
-0.16608,  -0.6
-0.16609,   0.7
-0.16609,  -0.5
-0.16610,  -0.9
-0.16610,  -0.8
-0.16609,   0.7
-0.16606,   0.3
-0.16610,  -0.2
-0.16608,  -0.9
-0.16608,   0.1
-0.16608,  -0.4
-0.16607,   0.0
-0.16608,  -0.4
-0.16608,  -0.5
-0.16608,   0.8
-0.16608,   0.6
-0.16608,   1.3
-0.16607,   0.1
-0.16610,   0.4
-0.16608,   0.5
-0.16608,  -0.4
-0.16610,   0.3
-0.16608,  -0.5
-0.16609,   0.1
-0.16609,   0.6
-0.16609,  -0.2
-0.16608,  -0.3
-0.16608,  -0.1
-0.16607,   0.3
-0.16610,   0.3
-0.16608,   0.1
-0.16608,  -0.3
-0.16609,  -0.5
-0.16609,  -0.0
-0.16607,  -0.0
-0.16607,  -0.6
-0.16607,  -0.5
-0.16608,   0.2
-0.16609,  -0.2
-0.16609,  -0.1
-0.16608,  -0.4
-0.16609,   0.1
-0.16607,  -0.2
-0.16608,  -0.3
-0.16609,  -0.3
-0.16608,  -0.6
-0.16609,  -0.3
-0.16608,  -0.1
-0.16609,  -0.5
-0.16608,  -0.2
-0.16609,  -0.8
-0.16607,  -0.4
-0.16609,  -0.0
-0.16608,   0.1
-0.16607,   0.4
-0.16607,   0.5
-0.16608,  -0.6
-0.16607,   0.6
-0.16606,   0.2
-0.16608,  -0.2
-0.16608,   1.2
-0.16610,  -0.0
-0.16608,   1.0
-0.16608,  -1.0
-0.16607,   0.2
-0.16607,   0.8
-0.16607,   0.5
-0.16607,   0.0
-0.16607,  -0.2
-0.16608,   0.8
-0.16607,   1.0
-0.16607,  -0.2
-0.16607,  -0.3
-0.16608,   0.1
-0.16607,   0.6
-0.16607,   0.0
-0.16608,   0.4
-0.16607,   0.3
-0.16608,  -0.2
-0.16607,   0.1
-0.16607,   0.1
-0.16607,  -0.1
-0.16610,   1.2
-0.16607,   3.4
-0.16608,   3.7
-0.16608,   3.1
-0.16607,   5.3
-0.16608,   6.2
-0.16609,   6.8
-0.16608,   6.5
-0.16608,   5.6
-0.16610,   6.0
-0.16608,   5.4
-0.16609,   5.4
-0.16609,   5.6
-0.16608,   5.1
-0.16608,   5.2
-0.16607,   6.6
-0.16608,   7.0
-0.16606,   6.3
-0.16606,   4.9
-0.16606,   5.0
-0.16608,   4.9
-0.16608,   5.4
-0.16608,   4.7
-0.16607,   5.2
-0.16606,   5.4
-0.16607,   4.6
-0.16606,   5.0
-0.16608,   5.0
-0.16607,   4.4
-0.16608,   4.6
-0.16608,   3.9
-0.16606,   4.5
-0.16609,   3.4
-0.16609,   4.8
-0.16608,   4.2
-0.16607,   3.7
-0.16609,   4.8
-0.16609,   4.2
-0.16609,   3.3
-0.16608,   3.0
-0.16608,   4.3
-0.16610,   2.6
-0.16608,   3.0
-0.16607,   2.1
-0.16606,   4.1
-0.16607,   2.9
-0.16608,   2.9
-0.16608,   3.6
-0.16608,   3.0
-0.16608,   2.2
-0.16609,   2.8
-0.16607,   3.3
-0.16608,   3.9
-0.16608,   2.6
-0.16607,   3.0
-0.16607,   3.4
-0.16607,   2.0
-0.16608,   2.3
-0.16608,   2.7
-0.16608,   2.3
-0.16608,   2.3
-0.16609,   1.6
-0.16609,   1.2
-0.16608,   1.4
-0.16605,   2.3
-0.16609,   2.1
-0.16607,   1.4
-0.16609,   1.8
-0.16606,   0.8
-0.16606,   2.2
-0.16607,   2.9
-0.16608,   2.1
-0.16609,   2.2
-0.16607,   2.1
-0.16609,   2.6
-0.16608,   1.9
-0.16608,   3.2
-0.16609,   2.7
-0.16610,   1.7
-0.16608,   2.2
-0.16608,   2.0
-0.16608,   2.4
-0.16610,   1.8
-0.16609,   2.0
-0.16608,   1.3
-0.16608,   0.7
-0.16608,   0.1
-0.16607,   0.7
-0.16606,  -0.0
-0.16607,  -0.1
-0.16608,  -0.2
-0.16606,  -0.2
-0.16608,   0.2
-0.16608,  -0.2
-0.16609,   0.8
-0.16607,  -0.2
-0.16604,   0.2
-0.16604,  -0.7
-0.16604,   0.3
-0.16604,  -0.1
-0.16604,  -0.6
-0.16602,  -0.3
-0.16603,  -0.3
-0.16601,  -0.3
-0.16604,  -0.2
-0.16604,  -0.6
-0.16605,   0.4
-0.16604,   0.3
-0.16604,   0.0
-0.16604,   0.3
-0.16605,  -0.5
-0.16604,   0.9
-0.16594,  -0.5
-0.16596,  -0.5
-0.16595,  -0.2
-0.16594,  -0.0
-0.16595,  -0.0
-0.16594,   0.5
-0.16594,  -0.1
-0.16596,   0.2
-0.16595,  -0.2
-0.16597,  -0.2
-0.16595,   0.0
-0.16596,  -1.1
-0.16596,   0.3
-0.16595,   0.0
-0.16596,   0.5
-0.16596,  -0.8
-0.16594,   0.0
-0.16594,   0.3
-0.16594,   0.1
-0.16594,   0.0
-0.16597,   0.4
-0.16593,  -0.0
-0.16595,  -0.7
-0.16594,   1.0
-0.16594,   0.4
-0.16595,   0.5
-0.16595,   0.4
-0.16595,   0.6
-0.16595,   0.2
-0.16594,  -0.6
-0.16595,   1.6
-0.16594,  -0.4
-0.16596,   0.6
-0.16594,   0.3
-0.16595,  -0.5
-0.16594,   0.2
-0.16593,   1.4
-0.16593,   0.9
-0.16595,   0.2
-0.16595,   0.4
-0.16595,   0.0
-0.16595,   0.4
-0.16595,   0.4
-0.16596,  -0.0
-0.16598,   0.2
-0.16596,   0.4
-0.16595,   0.6
-0.16594,   0.4
-0.16594,   0.6
-0.16596,   0.4
-0.16596,   0.3
-0.16595,   0.1
-0.16596,  -0.1
-0.16594,   1.1
-0.16595,   0.0
-0.16594,   0.9
-0.16597,   0.1
-0.16596,   0.3
-0.16595,   0.2
-0.16596,   0.3
-0.16594,   0.5
-0.16595,   0.1
-0.16595,   0.2
-0.16594,   0.0
-0.16596,  -0.1
-0.16594,   0.8
-0.16595,  -0.1
-0.16596,   0.6
-0.16596,  -0.1
-0.16597,  -0.3
-0.16597,  -0.2
-0.16595,   0.1
-0.16594,  -0.6
-0.16596,  -0.5
-0.16596,  -0.2
-0.16596,  -0.7
-0.16596,  -0.4
-0.16597,  -0.2
-0.16596,  -0.2
-0.16596,   0.0
-0.16597,  -0.2
-0.16596,  -0.1
-0.16595,  -0.2
-0.16595,   0.5
-0.16597,   0.4
-0.16595,  -0.6
-0.16594,   0.3
-0.16594,  -0.1
-0.16597,   0.4
-0.16597,  -0.2
-0.16595,  -0.2
-0.16595,   0.6
-0.16595,   0.6
-0.16595,   0.6
-0.16596,   0.3
-0.16595,  -1.0
-0.16598,   0.4
-0.16572,   1.0
-0.16567,   0.9
-0.16562,   1.1
-0.16555,   1.0
-0.16560,   0.5
-0.16560,   0.3
-0.16559,   1.4
-0.16559,   1.2
-0.16562,   0.7
-0.16559,   0.4
-0.16561,   0.3
-0.16561,   1.0
-0.16560,   1.3
-0.16561,   2.5
-0.16560,   0.7
-0.16559,   1.1
-0.16561,   0.4
-0.16561,   0.4
-0.16561,   0.2
-0.16560,  -0.1
-0.16559,   0.7
-0.16561,   1.2
-0.16560,   1.9
-0.16560,   0.2
-0.16561,   1.2
-0.16560,   0.9
-0.16559,   2.2
-0.16561,   1.9
-0.16560,   2.5
-0.16562,   1.9
-0.16561,   0.2
-0.16562,   2.0
-0.16561,   1.3
-0.16562,   1.0
-0.16564,   2.0
-0.16562,   1.3
-0.16562,   1.1
-0.16562,   1.1
-0.16561,   0.5
-0.16561,   1.0
-0.16562,   1.4
-0.16561,   1.3
-0.16560,   1.3
-0.16560,   0.9
-0.16559,   2.0
-0.16561,   2.1
-0.16559,   0.5
-0.16561,   2.2
-0.16560,   1.2
-0.16560,   0.7
-0.16560,   1.9
-0.16560,   1.6
-0.16559,   0.3
-0.16561,  -0.6
-0.16561,  -2.7
-0.16561,  -1.8
-0.16560,   6.9
-0.16562,   2.0
-0.16561,   4.1
-0.16559,   3.7
-0.16559,  -1.2
-0.16560,  -3.5
-0.16562,   3.4
-0.16559,  -2.0
-0.16560,  -3.2
-0.16560,  -6.2
-0.16559,  -6.7
-0.16558,  -7.3
-0.16560,  -6.2
-0.16561,  -7.1
-0.16561,  -0.0
-0.16561,   2.4
-0.16562,   4.6
-0.16563,   3.5
-0.16560,   0.4
-0.16561,  -6.9
-0.16560,  -1.5
-0.16559,   6.7
-0.16558,  -4.9
-0.16560,  -1.1
-0.16559,   9.1
-0.16561,  -2.2
-0.16561,  -0.6
-0.16561,   8.7
-0.16561,   8.3
-0.16561,   8.3
-0.16563,   8.4
-0.16561,   8.3
-0.16562,   5.3
-0.16561,  -5.5
-0.16561,  -0.5
-0.16561,   0.5
-0.16561,   1.8
-0.16562,   2.9
-0.16562,   2.6
-0.16562,   3.8
-0.16561,   0.1
-0.16563,  -3.6
-0.16562,  -6.5
-0.16562,  -4.5
-0.16562,  -1.3
-0.16563,   5.2
-0.16562,   7.8
-0.16562,   8.7
-0.16561,   9.6
-0.16562,   8.7
-0.16561,   8.4
-0.16561,   8.4
-0.16562,   9.0
-0.16563,   7.9
-0.16563,   8.7
-0.16563,   8.7
-0.16563,   8.5
-0.16563,   8.4
-0.16563,   9.5
-0.16562,  10.0
-0.16562,   9.1
-0.16563,   9.6
-0.16561,   9.1
-0.16563,   8.4
-0.16563,   8.9
-0.16563,   8.8
-0.16564,   8.8
-0.16563,   7.7
-0.16561,   9.8
-0.16559,  10.6
-0.16562,  10.8
-0.16561,  10.8
-0.16561,  10.8
-0.16562,   8.9
-0.16561,   7.2
-0.16562,   8.7
-0.16562,   8.7
-0.16562,   9.2
-0.16561,   8.0
-0.16560,   7.7
-0.16563,   6.4
-0.16562,   0.1
-0.16561,   2.9
-0.16561,   0.0
-0.16563,   0.9
-0.16562,   3.6
-0.16562,   3.3
-0.16561,   7.3
-0.16563,  -1.5
-0.16562,  -0.7
-0.16563,  -3.9
-0.16560,  -0.0
-0.16562,   0.6
-0.16562,  -1.9
-0.16561,   0.5
-0.16562,   0.1
-0.16562,   0.6
-0.16562,   0.6
-0.16562,   0.3
-0.16562,  -0.2
-0.16560,   0.4
-0.16562,  -0.4
-0.16563,   0.9
-0.16563,   0.1
-0.16562,  -0.4
-0.16562,  -0.5
-0.16561,   0.5
-0.16560,   0.9
-0.16561,   0.1
-0.16563,   0.8
-0.16563,   0.2
-0.16562,  -0.8
-0.16561,   1.0
-0.16562,   0.4
-0.16562,   1.7
-0.16561,  -0.2
-0.16563,  -0.4
-0.16561,  -0.8
-0.16563,  -0.3
-0.16560,  -0.6
-0.16561,  -1.5
-0.16560,  -0.6
-0.16562,   0.0
-0.16560,   0.0
-0.16561,  -0.6
-0.16560,  -0.3
-0.16559,  -0.3
-0.16560,  -0.5
-0.16560,  -0.6
-0.16560,  -1.1
-0.16559,   0.4
-0.16559,   0.5
-0.16562,  -2.2
-0.16560,  -0.5
-0.16562,   0.6
-0.16559,  -1.4
-0.16561,  -0.2
-0.16562,  -0.3
-0.16559,  -0.1
-0.16561,   1.0
-0.16560,   1.5
-0.16560,   1.9
-0.16560,   0.1
-0.16560,   1.0
-0.16560,   1.3
-0.16560,   0.8
-0.16561,   1.5
-0.16561,   0.8
-0.16561,   0.6
-0.16561,   1.5
-0.16563,   1.1
-0.16561,   2.0
-0.16560,   2.3
-0.16560,   2.0
-0.16559,   2.5
-0.16559,   1.7
-0.16560,   2.4
-0.16561,   3.0
-0.16560,   1.8
-0.16560,   2.1
-0.16560,   2.2
-0.16560,   1.8
-0.16560,   1.4
-0.16560,   1.7
-0.16560,   1.5
-0.16562,   2.5
-0.16561,   2.2
-0.16560,   2.7
-0.16560,   2.9
-0.16561,   3.0
-0.16560,   3.2
-0.16560,   2.4
-0.16560,   2.1
-0.16561,   1.7
-0.16561,   1.7
-0.16561,   2.7
-0.16561,   0.8
-0.16561,   1.9
-0.16559,   1.8
-0.16559,   2.2
-0.16561,   2.2
-0.16561,   2.5
-0.16560,   2.3
-0.16562,   2.2
-0.16560,   1.9
-0.16560,   1.4
-0.16561,   2.8
-0.16560,   1.5
-0.16561,   1.8
-0.16560,   0.7
-0.16561,  -0.1
-0.16561,   0.4
-0.16560,   0.1
-0.16560,   0.1
-0.16560,   1.0
-0.16560,   0.7
-0.16560,  -1.1
-0.16562,   0.7
-0.16560,   0.1
-0.16561,   0.5
-0.16560,   0.4
-0.16560,   0.2
-0.16562,   0.1
-0.16561,   0.3
-0.16560,   1.2
-0.16560,   0.6
-0.16560,   0.9
-0.16560,   1.8
-0.16560,   0.8
-0.16561,   0.9
-0.16561,   1.0
-0.16560,   0.6
-0.16562,   1.9
-0.16560,   2.0
-0.16559,   2.4
-0.16559,   3.4
-0.16560,   1.8
-0.16560,   2.2
-0.16558,   3.8
-0.16559,   3.4
-0.16561,   2.2
-0.16558,   1.9
-0.16559,   0.7
-0.16561,   0.2
-0.16561,  -0.4
-0.16560,   0.1
-0.16561,   2.7
-0.16562,   4.1
-0.16560,   4.9
-0.16561,   5.9
-0.16561,   5.0
-0.16561,   6.6
-0.16561,   4.8
-0.16561,   5.6
-0.16560,   4.9
-0.16560,   4.7
-0.16561,   4.3
-0.16562,   4.2
-0.16561,   6.1
-0.16560,   4.6
-0.16560,   5.0
-0.16561,   5.6
-0.16562,   5.1
-0.16561,   6.3
-0.16561,   6.3
-0.16561,   7.3
-0.16562,   6.1
-0.16561,   6.1
-0.16560,   5.7
-0.16561,   5.6
-0.16562,   5.7
-0.16560,   5.6
-0.16561,   5.9
-0.16560,   5.3
-0.16561,   5.0
-0.16560,   4.7
-0.16561,   5.3
-0.16560,   3.9
-0.16560,   4.1
-0.16561,   2.7
-0.16561,   5.0
-0.16561,   3.6
-0.16562,   3.0
-0.16561,   2.8
-0.16560,   4.1
-0.16561,   2.6
-0.16561,   3.0
-0.16561,   2.9
-0.16561,   3.2
-0.16561,   2.2
-0.16561,   2.2
-0.16562,   1.1
-0.16564,   0.2
-0.16563,   2.1
-0.16561,   3.0
-0.16563,   2.4
-0.16563,   1.0
-0.16562,   1.9
-0.16561,   0.6
-0.16561,   0.8
-0.16563,   0.6
-0.16562,   1.4
-0.16563,   0.9
-0.16562,   1.3
-0.16563,  -0.8
-0.16562,   0.2
-0.16563,  -0.5
-0.16562,   0.1
-0.16562,   0.3
-0.16562,   0.2
-0.16564,   0.9
-0.16564,   1.5
-0.16561,   0.6
-0.16563,   1.7
-0.16563,   2.3
-0.16562,   1.7
-0.16562,   2.4
-0.16562,   2.9
-0.16562,   2.0
-0.16563,   2.4
-0.16562,   3.2
-0.16563,   2.9
-0.16564,   2.2
-0.16562,   2.3
-0.16563,   2.7
-0.16562,   2.4
-0.16561,   3.3
-0.16563,   2.1
-0.16562,   2.8
-0.16561,   3.2
-0.16564,   2.4
-0.16564,   2.3
-0.16563,   3.3
-0.16563,   1.9
-0.16563,   3.0
-0.16562,   2.0
-0.16563,   1.8
-0.16562,   1.8
-0.16562,   2.7
-0.16562,   1.6
-0.16562,   1.5
-0.16561,   1.1
-0.16562,  -0.7
-0.16561,  -0.9
-0.16562,   2.2
-0.16563,  -1.3
-0.16561,  -3.8
-0.16562,  -2.7
-0.16562,  -1.4
-0.16562,  -2.9
-0.16560,  -1.5
-0.16561,   0.3
-0.16561,   0.6
-0.16562,   3.5
-0.16562,   3.1
-0.16562,   4.4
-0.16563,   3.0
-0.16562,   3.0
-0.16561,   4.0
-0.16562,   3.7
-0.16563,   3.2
-0.16563,   2.9
-0.16563,   4.2
-0.16562,   5.4
-0.16563,   3.8
-0.16562,   1.9
-0.16561,   2.7
-0.16563,   3.2
-0.16563,  -1.7
-0.16561,   0.5
-0.16562,  -1.2
-0.16563,  -0.7
-0.16560,  -1.5
-0.16562,  -1.3
-0.16562,  -0.5
-0.16561,  -0.4
-0.16561,  -2.0
-0.16561,  -0.2
-0.16562,   2.5
-0.16562,   1.7
-0.16562,  -0.5
-0.16563,   3.2
-0.16561,  -0.4
-0.16563,   1.6
-0.16563,   2.1
-0.16561,   1.8
-0.16561,   4.7
-0.16561,   3.3
-0.16560,   2.8
-0.16561,   3.6
-0.16562,   3.9
-0.16563,   3.1
-0.16513,   3.1
-0.15525,   3.6
-0.18211,   3.3
-0.18032,   3.7
-0.30797,   3.7
-0.35075,   4.8
-0.26291,   4.0
-0.22955,   3.1
-0.19024,   4.4
-0.18148,   3.8
-0.18106,   3.5
-0.18272,   4.8
-0.18271,   3.4
-0.18188,   4.2
-0.18346,   3.6
-0.19445,   2.9
-0.19542,   3.6
-0.19292,   3.6
-0.19015,   3.7
-0.19054,   3.8
-0.19074,   2.9
-0.19037,   3.9
-0.18982,   3.9
-0.18442,   3.9
-0.17842,   3.9
-0.18052,   4.5
-0.18557,   3.3
-0.11611,   4.2
-0.00886,   4.3
0.01919,   4.5
0.00780,   4.0
0.00151,   4.2
-0.00429,   3.5
-0.00378,   3.7
-0.00901,   4.0
-0.00884,   4.2
-0.01141,   3.8
-0.01494,   3.8
-0.01537,   4.2
-0.01123,   3.7
-0.01094,   3.8
-0.01387,   4.7
-0.01974,   4.0
-0.02079,   4.0
-0.04203,   3.6
-0.06022,   4.2
-0.06692,   5.5
-0.09019,   3.7
-0.07678,   4.3
-0.06773,   4.4
-0.07170,   3.9
-0.06640,   3.7
-0.04569,   5.2
-0.06164,   4.1
-0.05624,   3.7
-0.05603,   4.4
-0.04580,   4.1
0.01887,   4.3
0.06230,   4.5
0.05136,   3.9
0.08216,   3.9
0.09565,   5.1
0.10919,   3.9
0.07893,   3.3
0.06233,   3.0
0.05536,   3.8
0.04896,   4.6
0.02645,   4.1
0.06126,   4.7
0.11133,   4.5
0.10977,   5.4
0.10286,   4.3
0.09489,   4.2
0.09334,   4.7
-0.01507,   4.0
-0.01111,   3.1
-0.00289,   4.0
0.02777,   4.4
0.03366,   3.9
0.05902,   4.5
0.06287,   4.5
0.05735,   3.3
0.04725,   4.5
0.04288,   3.9
0.04094,   3.9
0.04103,   4.0
0.03861,   3.8
0.03945,   3.7
0.03951,   3.2
0.03650,   4.6
0.03640,   3.6
0.03520,   4.2
0.03213,   4.7
0.02952,   3.9
0.02901,   3.9
0.02889,   4.4
0.02863,   4.4
0.02858,   4.7
0.02486,   4.7
0.01701,   3.5
0.00117,   2.8
0.00032,   3.0
0.01001,   3.8
0.02969,   3.4
0.03310,   4.6
0.03202,   4.1
0.03065,   3.4
0.02338,   3.4
0.01424,   4.0
0.01114,   4.0
-0.03748,   4.6
-0.03352,   3.7
-0.01833,   2.5
-0.02161,   3.8
-0.01294,   4.6
-0.01511,   2.9
-0.00606,   3.0
-0.01332,   4.1
-0.02177,   3.6
-0.02236,   3.6
-0.02329,   3.3
-0.04811,   4.6
-0.06051,   4.6
-0.05650,   4.8
-0.02895,   3.9
0.01732,   3.9
0.00020,   3.9
-0.00843,   3.3
-0.03028,   4.1
-0.07294,   4.1
-0.11675,   4.5
-0.12467,   3.7
-0.14412,   4.4
-0.14366,   4.2
-0.13994,   5.0
-0.13860,   4.4
-0.12921,   3.8
-0.14765,   4.1
-0.21944,   3.6
-0.25877,   4.6
-0.25832,   4.5
-0.25478,   5.0
-0.79289,   3.1
-0.77581,   4.3
-0.78876,   4.3
-0.85000,   4.7
-0.84755,   3.7
-0.81946,   4.4
-0.62861,   4.4
-0.50110,   3.6
-0.41852,   4.3
-0.39710,   4.0
-0.38373,   5.0
-0.24843,   4.4
-0.16506,   4.3
-0.08232,   3.8
0.02434,   3.9
0.07766,   3.6
0.08235,   3.1
-0.01795,   3.4
-0.05429,   3.4
-0.05600,   3.8
-0.05519,   4.6
-0.05718,   4.3
-0.06173,   5.0
-0.06301,   3.3
-0.06341,   4.5
-0.06279,   4.2
-0.25763,   3.8
-0.27728,   4.6
-0.24774,   3.9
-0.24484,   3.2
-0.23949,   3.2
-0.20073,   4.0
-0.18723,   3.0
-0.18569,   4.0
-0.18851,   4.1
-0.19703,   3.8
-0.19930,   4.3
-0.19844,   4.3
-0.19826,   3.6
-0.19788,   4.3
-0.19783,   3.2
-0.19749,   2.7
-0.20176,   3.5
-0.19830,   3.5
-0.20045,   3.2
-0.20104,   4.9
-0.19821,   4.2
-0.19945,   4.4
-0.19958,   4.1
-0.20049,   4.5
-0.20077,   4.7
-0.19846,   3.8
-0.19666,   4.5
-0.19769,   3.3
-0.19868,   4.7
-0.20328,   4.0
-0.20131,   4.1
-0.20121,   4.4
-0.20186,   4.8
-0.20240,   4.8
-0.20125,   3.8
-0.20186,   2.9
-0.20195,   1.1
-0.20236,   0.6
-0.20246,   1.3
-0.20205,   1.3
-0.20136,  -0.4
-0.20104,   1.3
-0.20195,   1.3
-0.20205,   1.3
-0.20173,   0.9
-0.20198,   0.9
-0.20342,   0.5
-0.20399,  -0.7
-0.20408,  -0.1
-0.20323,  -0.3
-0.20332,   0.2
-0.20427,  -2.7
-0.20267,  -0.2
-0.20025,   2.3
-0.20007,   3.7
-0.20037,   4.7
-0.20084,   5.1
-0.20131,   5.5
-0.20142,   4.8
-0.20166,   6.2
-0.20165,   5.0
-0.20164,   4.7
-0.20163,   5.5
-0.20163,   5.9
-0.20156,   6.0
-0.20158,   4.8
-0.20128,   5.2
-0.20103,   5.3
-0.20132,   4.7
-0.20139,   6.0
-0.20271,   5.7
-0.20340,   6.0
-0.20341,   5.1
-0.20340,   5.2
-0.20340,   5.8
-0.20343,   5.8
-0.20343,   5.0
-0.20342,   5.6
-0.20349,   5.3
-0.20345,   4.5
-0.20345,   5.5
-0.20346,   4.5
-0.20345,   5.5
-0.20344,   4.6
-0.20345,   5.0
-0.20344,   5.7
-0.20343,   5.5
-0.20342,   5.9
-0.20341,   5.0
-0.20344,   5.7
-0.20343,   5.5
-0.20343,   4.7
-0.20342,   5.8
-0.20343,   4.4
-0.20344,   5.7
-0.20342,   5.7
-0.20343,   4.4
-0.20343,   5.9
-0.20344,   5.7
-0.20344,   5.2
-0.20343,   4.7
-0.20343,   6.0
-0.20343,   5.5
-0.20344,   6.5
-0.20344,   5.3
-0.20343,   5.9