File: MAE_3272/Module_1/Group1-1018 Cold Rolled_1.csv
2/12/2016
3:28 PM
Sampling Frequency:,10Hz
Group:,Group1
Extensometer:,E85191
Sample:,1018 Cold Rolled
Sample width [inch]:,0.497000
Sample thickness [inch]:,0.124000
--------,--------

Extensometer,Load
[Inches],[Lbs]
0.00001,  -0.9
-0.00001,  -0.3
0.00000,  -0.7
-0.00000,  -0.7
-0.00001,   1.3
-0.00000,  -0.9
0.00001,  -0.6
-0.00000,   0.1
-0.00001,   0.9
-0.00000,   0.1
-0.00000,  -0.2
0.00000,  -0.2
0.00000,  -0.5
0.00000,  -0.3
0.00001,  -0.9
0.00000,  -0.5
-0.00002,  -0.5
-0.00000,   0.3
0.00000,  -1.4
-0.00000,   1.0
0.00000,  -0.1
0.00003,   1.0
0.00002,   0.3
0.00001,  -0.5
-0.00001,  -0.2
0.00000,   0.1
0.00001,  -0.4
0.00000,  -0.8
0.00001,  -0.6
-0.00001,  -0.2
0.00002,   0.1
-0.00000,  -0.2
0.00003,  -0.9
0.00002,   0.1
0.00002,   0.4
0.00001,  -0.5
0.00000,  -0.7
0.00002,  -0.2
-0.00000,  -0.8
0.00001,   0.1
0.00002,   0.7
0.00003,   0.0
0.00001,   0.8
0.00001,   1.0
0.00003,  -1.2
0.00002,  -0.3
0.00002,   0.7
0.00002,  -0.6
0.00002,   0.6
0.00002,  -0.4
0.00002,  -0.3
0.00002,   1.0
0.00001,   1.7
0.00001,   1.6
0.00003,   1.4
0.00002,   1.3
0.00002,   2.2
0.00003,   2.5
0.00003,   1.5
0.00001,   2.4
0.00001,   2.8
0.00002,   2.9
0.00002,   2.9
0.00001,   2.2
0.00001,   2.3
0.00001,   2.6
0.00001,   1.6
0.00002,   3.6
0.00000,   2.7
0.00001,   3.3
0.00002,   2.3
0.00001,   2.8
0.00002,   2.5
0.00001,   2.9
0.00003,   2.8
0.00002,   2.5
0.00001,   3.4
0.00003,   3.6
0.00003,   2.9
0.00002,   3.0
0.00003,   3.7
0.00002,   4.0
0.00001,   4.3
0.00002,   4.0
0.00001,   4.5
0.00001,   3.9
0.00002,   4.8
0.00000,   3.1
0.00001,   3.8
0.00002,   4.7
0.00001,   4.9
0.00001,   4.3
0.00001,   4.5
0.00002,   3.5
0.00002,   4.5
0.00001,   3.6
0.00000,   4.0
0.00000,   3.3
0.00001,   3.9
0.00001,   4.4
0.00001,   3.8
0.00002,   3.7
0.00002,   3.7
0.00001,   4.5
0.00003,   3.3
0.00002,   3.4
0.00002,   3.9
0.00002,   3.3
0.00002,   3.0
0.00001,   2.4
0.00002,   2.6
0.00001,   2.7
-0.00002,   4.1
0.00002,   3.6
0.00001,   2.0
0.00001,   2.8
0.00001,   2.6
0.00001,   2.6
0.00002,   2.2
0.00003,   3.2
0.00001,   3.2
0.00001,   2.8
0.00001,   3.6
0.00001,   3.4
-0.00000,   1.6
0.00000,   3.2
-0.00002,   3.0
-0.00000,   1.6
-0.00000,   1.7
0.00000,   2.8
0.00000,   3.7
-0.00000,   2.2
-0.00000,   3.2
-0.00001,   2.7
0.00000,   2.8
-0.00001,   3.2
-0.00003,   3.3
-0.00001,   2.6
-0.00000,   2.6
-0.00001,   3.6
-0.00001,   2.6
0.00001,   3.6
-0.00000,   4.9
-0.00001,   3.1
-0.00000,   3.8
-0.00002,   4.4
-0.00000,   4.2
0.00000,   2.9
-0.00001,   3.5
0.00000,   4.1
-0.00001,   3.6
-0.00001,   3.6
0.00001,   3.7
-0.00001,   5.0
0.00000,   3.9
-0.00000,   5.3
0.00001,   5.3
0.00001,   4.5
0.00001,   5.7
0.00000,   4.6
-0.00000,   3.9
0.00001,   3.8
0.00001,   4.8
0.00001,   4.7
0.00000,   3.6
-0.00000,   4.6
-0.00001,   4.6
0.00001,   5.4
-0.00000,   4.2
-0.00000,   4.6
0.00001,   2.6
0.00000,   3.1
-0.00000,   3.9
0.00001,   4.6
0.00000,   4.2
-0.00000,   4.3
-0.00000,   4.3
-0.00001,   4.0
0.00001,   3.8
-0.00001,   4.0
0.00000,   3.6
0.00000,   3.3
-0.00001,   3.6
-0.00002,   4.3
0.00001,   3.7
-0.00001,   4.4
-0.00001,   4.5
-0.00001,   5.0
-0.00002,   3.2
-0.00001,   3.6
0.00000,   4.3
0.00001,   4.4
-0.00001,   3.3
-0.00000,   3.7
-0.00002,   5.0
-0.00001,   3.5
-0.00000,   2.9
-0.00002,   2.9
-0.00001,   3.3
-0.00002,   3.2
-0.00001,   2.4
-0.00000,   2.2
-0.00001,   3.9
-0.00001,   3.6
0.00001,   2.8
-0.00001,   3.4
-0.00001,   2.6
0.00001,   3.0
-0.00000,   2.3
0.00001,   2.1
-0.00000,   2.9
-0.00000,   3.0
-0.00001,   2.9
-0.00000,   1.8
-0.00002,   3.1
0.00001,   2.3
-0.00001,   2.6
-0.00000,   3.5
-0.00001,   3.0
-0.00001,   3.3
0.00001,   3.3
-0.00000,   3.4
0.00000,   2.5
0.00001,   4.3
0.00001,   2.8
0.00002,   2.8
0.00002,   3.0
-0.00001,   3.2
0.00000,   2.8
0.00002,   3.4
0.00002,   2.7
0.00002,   2.7
0.00001,   2.6
0.00001,   2.8
0.00001,   3.6
0.00001,   2.3
0.00002,   3.9
0.00001,   3.6
0.00002,   3.9
-0.00000,   3.4
0.00001,   3.6
0.00002,   4.7
-0.00001,   4.0
-0.00001,   3.8
0.00002,   4.8
0.00001,   4.9
0.00000,   3.9
0.00001,   4.1
0.00000,   3.4
-0.00001,   4.9
0.00001,   4.3
0.00000,   4.1
0.00002,   4.5
0.00000,   3.3
-0.00001,   3.4
-0.00000,   3.4
-0.00001,   4.2
-0.00000,   3.3
-0.00001,   2.0
0.00002,   3.2
0.00001,   2.6
0.00001,   3.3
0.00001,   3.4
0.00003,   2.6
0.00000,   3.1
-0.00002,   2.8
0.00001,   3.5
0.00001,   2.3
-0.00000,   2.3
0.00001,   2.9
0.00001,   2.9
0.00000,   2.6
0.00000,   3.0
0.00000,   3.3
0.00001,   2.8
0.00000,   2.8
0.00000,   3.6
0.00001,   2.9
-0.00001,   1.9
0.00000,   2.3
-0.00000,   3.0
0.00002,   3.5
-0.00001,   2.4
0.00001,   2.0
0.00001,   3.7
-0.00000,   2.7
0.00000,   2.3
0.00000,   3.2
0.00000,   3.8
-0.00001,   3.7
0.00001,   3.4
0.00000,   3.3
-0.00000,   2.6
-0.00001,   3.3
-0.00001,   3.3
-0.00000,   2.7
0.00000,   4.2
-0.00000,   3.1
0.00000,   3.4
0.00002,   2.1
-0.00000,   2.3
-0.00001,   2.8
-0.00000,   2.9
0.00001,   2.2
-0.00000,   2.7
-0.00000,   2.8
0.00001,   1.9
0.00000,   2.9
0.00001,   2.7
0.00000,   3.8
0.00000,   3.7
-0.00001,   3.3
-0.00002,   3.3
0.00001,   4.1
0.00000,   4.2
-0.00002,   3.1
0.00001,   2.8
0.00001,   3.3
-0.00000,   2.1
-0.00001,   2.8
0.00001,   3.8
0.00001,   4.1
-0.00002,   3.1
0.00001,   2.8
-0.00001,   2.3
0.00002,   3.3
-0.00000,   3.1
0.00001,   3.0
-0.00001,   3.6
-0.00000,   3.9
0.00001,   3.0
-0.00001,   2.4
0.00001,   3.0
-0.00001,   1.7
0.00001,   2.6
0.00000,   2.9
-0.00001,   2.6
-0.00000,   2.8
-0.00001,   2.0
0.00001,   3.0
-0.00000,   2.2
-0.00000,   1.5
-0.00000,   1.4
0.00000,   1.6
-0.00001,   2.1
0.00000,   1.4
-0.00001,   2.0
0.00000,   2.7
0.00000,   1.9
0.00001,   2.6
0.00001,   2.1
0.00001,   2.2
0.00001,   2.2
0.00000,   1.9
0.00001,   1.9
0.00000,   2.9
-0.00001,   2.9
0.00002,   1.4
-0.00000,   2.0
-0.00000,   2.0
0.00000,   1.8
-0.00000,   2.7
0.00000,   2.5
-0.00000,   2.5
0.00001,   3.3
-0.00001,   2.4
0.00001,   1.7
-0.00000,   1.8
0.00000,   2.8
-0.00001,   1.9
-0.00001,   3.0
-0.00006,   2.5
-0.00010,   1.9
-0.00013,   1.7
-0.00013,   2.1
-0.00013,   2.0
-0.00015,   1.0
-0.00014,   2.5
-0.00013,   1.4
-0.00013,   1.6
-0.00014,   1.8
-0.00015,   3.0
-0.00013,   2.2
-0.00013,   1.9
-0.00013,   2.7
-0.00014,   2.3
-0.00013,   2.5
-0.00012,   1.4
-0.00014,   1.7
-0.00014,   2.2
-0.00014,   1.9
-0.00013,   1.3
-0.00014,   2.0
-0.00014,   2.8
-0.00014,   1.5
-0.00015,   2.3
-0.00014,   2.8
-0.00014,   1.8
-0.00014,   2.1
-0.00013,   1.8
-0.00013,   1.9
-0.00012,   2.5
-0.00013,   2.1
-0.00012,   2.0
-0.00014,   1.7
-0.00015,   2.3
-0.00015,   2.1
-0.00013,   1.3
-0.00013,   2.2
-0.00014,   1.8
-0.00015,   1.7
-0.00013,   2.8
-0.00013,   1.4
-0.00014,   2.7
-0.00014,   2.9
-0.00014,   2.9
-0.00013,   2.3
-0.00013,   2.4
-0.00014,   2.9
-0.00013,   2.6
-0.00014,   3.5
-0.00013,   3.2
-0.00012,   2.8
-0.00012,   2.5
-0.00015,   2.8
-0.00012,   2.7
-0.00013,   2.1
-0.00015,   2.4
-0.00012,   1.2
-0.00014,   3.2
-0.00014,   2.1
-0.00015,   1.6
-0.00013,   3.2
-0.00015,   2.4
-0.00012,   2.4
-0.00015,   2.6
-0.00014,   2.5
-0.00013,   2.2
-0.00014,   2.9
-0.00013,   1.9
-0.00013,   2.8
-0.00013,   3.3
-0.00012,   2.6
-0.00013,   3.1
-0.00015,   2.8
-0.00014,   3.1
-0.00014,   2.8
-0.00014,   2.6
-0.00015,   2.1
-0.00014,   3.0
-0.00013,   3.0
-0.00014,   2.5
-0.00012,   3.0
-0.00013,   2.7
-0.00014,   2.8
-0.00015,   4.2
-0.00013,   2.9
-0.00013,   2.5
-0.00013,   2.7
-0.00056,   3.2
-0.00278,   2.6
-0.06216,   2.6
-0.06250,   2.7
-0.06307,   1.6
-0.06269,   2.8
-0.06076,   2.8
-0.05294,   2.6
-0.05250,   1.7
-0.04445,   2.2
-0.07384,   1.4
-0.08675,   1.5
-0.05686,   1.1
-0.07974,   1.9
-0.02195,   2.7
0.07754,   2.2
0.12898,   2.1
0.09176,   2.4
0.08497,   1.7
0.05368,   1.6
0.06357,   1.6
0.06502,   1.9
0.06644,   1.7
0.07818,   2.0
0.07702,   1.8
0.07902,   2.2
0.08303,   1.9
0.10919,   1.9
0.11808,   1.5
0.10090,   1.9
-0.01826,   1.6
-0.03693,   1.3
-0.06763,   1.2
-0.08594,   1.6
-0.09714,   2.7
-0.09644,   1.2
-0.10969,   2.4
-0.11121,   1.6
-0.12551,   2.0
-0.14486,   2.0
-0.15307,   2.2
-0.14672,   1.2
-0.14408,   2.6
-0.17936,   2.3
-0.17397,   3.1
-0.16733,   1.4
-0.16780,   1.9
0.03510,   2.4
0.15375,   2.3
0.14851,   1.4
0.14532,   1.5
0.12216,   1.3
0.10564,   3.1
0.09523,   1.8
0.07147,   3.2
0.03425,  -0.6
0.02610,   0.6
0.02647,  -0.9
0.02633,  -0.2
0.02656,  -1.3
0.02572,   0.3
0.02599,  -0.5
0.02722,  -0.3
0.02696,  -0.7
0.02641,   0.1
0.02668,  -0.3
0.02681,  -0.3
0.02696,   0.3
0.02843,  -1.0
0.02896,  -0.2
0.02875,  -0.5
0.02881,   0.4
0.02876,  -0.0
0.02881,  -1.1
0.02883,  -1.0
0.02891,  -0.5
0.02918,  -0.8
0.02925,  -1.5
0.02952,  -0.5
0.02966,  -0.0
0.02971,  -1.0
0.02954,   0.5
0.02929,  -0.7
0.03002,  -1.4
0.02972,   0.1
0.02953,  -0.3
0.02958,  -0.6
0.02969,  -0.7
0.02954,  -0.3
0.02967,  -2.6
0.02976,  -1.4
0.02976,  -1.9
0.02973,  -1.6
0.02973,  -1.7
0.02973,  -1.5
0.02979,   0.0
0.02968,  -0.8
0.02978,  -0.2
0.02968,  -0.1
0.02972,  -0.9
0.02965,  -0.9
0.02968,  -0.6
0.02970,  -1.3
0.02968,  -0.5
0.02968,  -1.2
0.02971,  -0.7
0.02964,   0.1
0.02964,  -0.2
0.02965,   0.4
0.02965,  -0.7
0.02968,  -0.5
0.02965,  -0.7
0.02967,  -0.8
0.02965,  -1.3
0.02967,  -0.2
0.02967,  -0.9
0.02965,  -0.5
0.02963,  -0.9
0.02969,  -0.8
0.02966,   0.1
0.02966,  -0.7
0.02965,  -0.6
0.02966,  -0.5
0.02966,  -1.5
0.02966,  -0.2
0.02964,   1.1
0.02965,  -0.1
0.02964,   0.3
0.02966,  -0.5
0.02967,  -0.4
0.02963,  -0.1
0.02965,   0.6
0.02967,  -0.4
0.02962,  -0.3
0.02965,   0.6
0.02967,  -0.7
0.02963,  -0.1
0.02965,  -1.0
0.02965,   0.3
0.02967,  -1.6
0.02964,  -0.7
0.02961,  -0.3
0.02969,  -0.6
0.02963,   0.3
0.02972,  -1.0
0.02953,   0.4
0.02970,  -1.1
0.02970,  -0.1
0.02965,  -0.5
0.02969,  -0.8
0.02970,  -0.8
0.02967,   0.5
0.02964,  -1.2
0.02965,  -0.8
0.02969,  -0.4
0.02967,  -1.1
0.02963,  -0.2
0.02966,  -0.1
0.02969,  -1.4
0.02968,  -1.0
0.02969,  -0.3
0.02961,   0.5
0.02977,  -1.1
0.02956,   0.2
0.02959,   1.2
0.02974,   0.5
0.02913,   0.4
0.02913,   1.4
0.02916,   1.3
0.02915,   1.5
0.02908,   1.3
0.02851,  -0.4
0.02842,  -0.5
0.02875,   1.1
0.02854,   0.1
0.02869,   2.5
0.02753,   2.9
0.02596,   3.1
0.02702,   2.4
0.02709,   1.8
0.02758,   2.9
0.02741,   1.8
0.02714,  -0.1
0.02677,   0.6
0.02674,  -0.3
0.02677,   0.6
0.02789,   1.1
0.02871,   0.3
0.02904,   0.7
0.02948,   0.5
0.02868,  -0.6
0.02802,   0.2
0.02808,   0.6
0.02824,   1.1
0.02869,  -0.6
0.02880,  -0.6
0.02873,  -1.7
0.02870,  -1.0
0.02839,  -1.2
0.02596,   0.0
0.02551,  -0.7
0.02534,  -0.8
0.02790,  -0.5
0.02807,  -1.0
0.02809,  -0.5
0.02810,  -0.0
0.02809,  -0.9
0.02808,  -0.6
0.02809,  -0.7
0.02808,  -0.3
0.02808,  -0.4
0.02809,   0.6
0.02809,   0.6
0.02807,  -0.4
0.02808,   1.1
0.02806,   0.8
0.02806,  -0.7
0.02809,  -0.5
0.02809,  -1.5
0.02809,   0.9
0.02807,   0.8
0.02809,   0.7
0.02810,   0.8
0.02808,   1.6
0.02809,   0.6
0.02807,  -0.8
0.02809,  -0.1
0.02809,   0.5
0.02808,  -0.6
0.02807,  -0.6
0.02807,  -0.1
0.02808,  -1.4
0.02809,  -0.8
0.02808,  -0.8
0.02809,  -0.8
0.02808,  -1.2
0.02807,  -0.9
0.02806,  -1.6
0.02808,  -0.4
0.02806,  -1.5
0.02806,  -1.0
0.02808,  -0.6
0.02809,  -0.9
0.02808,  -1.1
0.02809,  -0.2
0.02807,  -0.0
0.02807,  -0.6
0.02808,  -0.3
0.02808,  -0.8
0.02808,  -0.6
0.02808,   0.3
0.02809,   0.9
0.02809,  -1.0
0.02808,  -1.2
0.02809,  -1.2
0.02809,  -1.1
0.02810,  -0.7
0.02808,  -0.7
0.02810,   0.3
0.02808,  -1.1
0.02807,  -0.4
0.02809,  -0.2
0.02809,  -0.5
0.02810,  -0.2
0.02809,  -0.1
0.02808,  -0.9
0.02809,  -0.0
0.02808,   0.1
0.02808,   0.2
0.02808,  -0.6
0.02810,  -0.3
0.02809,  -0.5
0.02809,  -0.3
0.02809,  -0.7
0.02808,   0.0
0.02809,  -0.1
0.02808,  -0.3
0.02808,   0.9
0.02809,   0.8
0.02809,   0.0
0.02810,   0.5
0.02808,  -0.1
0.02807,  -1.5
0.02807,   0.4
0.02807,  -0.7
0.02809,   0.2
0.02807,  -0.2
0.02807,  -0.2
0.02808,  -0.8
0.02809,  -1.2
0.02808,   0.1
0.02805,  -0.7
0.02809,  -1.6
0.02808,  -1.7
0.02808,  -0.7
0.02809,  -1.6
0.02809,  -1.2
0.02809,  -1.3
0.02809,  -0.0
0.02810,  -0.9
0.02810,  -1.3
0.02809,  -0.8
0.02810,  -0.1
0.02808,  -0.3
0.02808,   0.0
0.02809,   0.1
0.02810,  -0.6
0.02810,  -0.3
0.02809,   0.7
0.02809,  -0.3
0.02811,  -0.6
0.02809,   0.1
0.02809,  -0.1
0.02809,   0.4
0.02810,  -0.8
0.02808,  -0.2
0.02810,  -0.3
0.02810,   0.6
0.02810,   0.6
0.02809,   0.6
0.02808,   1.8
0.02810,   1.8
0.02809,   3.0
0.02809,   3.0
0.02809,   3.2
0.02809,   3.2
0.02809,   3.1
0.02808,   2.1
0.02810,   2.6
0.02809,   2.2
0.02809,   2.4
0.02808,   1.8
0.02807,   0.2
0.02810,   1.1
0.02810,   1.1
0.02810,   1.5
0.02809,   0.6
0.02806,   1.3
0.02808,   0.5
0.02808,   1.3
0.02809,   1.7
0.02809,   1.2
0.02808,  -0.1
0.02809,  -0.5
0.02809,   0.1
0.02808,   5.8
0.02809,   0.4
0.02809,   1.6
0.02809,   1.8
0.02808,   1.2
0.02810,   1.5
0.02808,   1.2
0.02810,   1.5
0.02809,   1.2
0.02809,   1.5
0.02809,   1.8
0.02806,   0.9
0.02808,   1.5
0.02808,  -4.5
0.02809,  -6.1
0.02808,  -5.9
0.02809,  -4.0
0.02810,  -2.2
0.02809,  -4.0
0.02810,  -5.8
0.02808,  -7.3
0.02809,  -9.9
0.02810,  -7.5
0.02811,  -7.1
0.02809,  -4.5
0.02809,  -6.8
0.02808,  -4.7
0.02809,   1.9
0.02809,  -0.8
0.02809,  -0.7
0.02808,  -0.2
0.02808,  -0.3
0.02810,  -0.1
0.02809,   0.3
0.02808,   0.6
0.02809,   1.0
0.02808,   0.8
0.02809,  -0.5
0.02809,   1.2
0.02810,   0.7
0.02809,  -0.1
0.02808,  -0.7
0.02809,  -0.3
0.02807,  -1.2
0.02810,   0.7
0.02809,  -0.1
0.02808,  -0.2
0.02764,   0.1
0.02343,  -0.7
0.02031,   0.0
0.01868,  -1.1
0.01768,  -0.3
0.01682,   0.9
0.01652,  -0.0
0.01732,  -0.5
0.01705,  -0.8
0.01695,   0.7
0.01788,  -0.9
0.01883,  -0.5
0.01980,  -0.4
0.02340,   0.0
0.02772,   0.2
0.02985,  -0.6
0.03021,  -0.0
0.03042,  -1.5
0.03043,  -0.1
0.03034,  -1.1
0.02957,  -1.3
0.02971,   0.4
0.02917,  -0.8
0.02810,   0.3
0.02652,  -0.3
0.02538,   0.4
0.02551,  -1.6
0.02596,  -0.6
0.02561,   0.1
0.02501,  -0.1
0.02345,  -1.1
0.02119,  -0.6
0.01848,   0.4
0.01791,  -0.6
0.01768,  -0.7
0.01686,  -0.8
0.01759,  -0.2
0.01823,  -0.8
0.01950,  -1.1
0.02001,  -0.6
0.02451,  -1.7
0.02640,  -0.0
0.02575,  -2.1
0.02639,  -2.0
0.02779,  -1.7
0.02916,  -1.0
0.02597,  -0.5
0.02344,  -0.9
0.02173,  -0.8
0.02386,  -0.8
0.02483,  -0.8
0.02241,  -2.0
0.01614,  -1.1
0.01420,  -0.4
0.01396,  -1.6
0.01447,  -1.1
0.01486,  -0.4
0.01546,  -0.6
0.01553,  -0.7
0.01603,  -0.3
0.01917,  -0.7
0.02043,  -0.8
0.02029,  -0.5
0.02137,  -0.3
0.02167,  -0.1
0.02135,  -0.5
0.02115,  -0.1
0.02164,  -0.5
0.02181,   0.1
0.02162,  -0.9
0.02180,   0.7
0.02125,  -0.7
0.02142,  -0.3
0.02085,  -0.6
0.02076,  -0.3
0.01983,  -0.2
0.02041,  -2.9
0.01969,  -0.2
0.01978,  -0.0
0.01894,   0.0
0.01853,  -0.2
0.01905,  -0.6
0.01866,   0.2
0.01856,  -1.0
0.01923,   0.1
0.01940,   0.1
0.01929,   0.3
0.01980,   0.3
0.02209,  -0.1
0.02390,  -0.5
0.02711,   0.7
0.02727,   1.3
0.02648,  -0.2
0.02688,  -0.4
0.02610,   0.3
0.02302,  -0.0
0.01829,  -0.5
0.01757,   0.3
0.01933,  -0.2
0.01811,   0.6
0.01801,  -0.8
0.01875,  -0.8
0.01928,  -1.1
0.02019,  -0.4
0.02042,   0.1
0.02346,  -1.2
0.02506,  -0.8
0.02556,  -2.8
0.02503,  -0.7
0.02456,  -0.5
0.02530,  -1.4
0.02633,  -0.4
0.02542,   0.2
0.02508,   0.0
0.02680,  -0.1
0.02718,  -1.3
0.02707,  -1.7
0.02601,  -0.7
0.02526,   0.4
0.02505,  -0.7
0.02523,  -0.6
0.02524,  -0.8
0.02524,   0.4
0.02524,  -0.5
0.02524,   0.2
0.02523,  -0.6
0.02531,  -1.6
0.02518,  -0.4
0.02507,  -0.5
0.02568,  -0.1
0.02654,  -0.2
0.02697,   0.3
0.02420,  -0.5
0.02377,   0.3
0.02423,  -1.0
0.02427,   0.3
0.02429,   0.1
0.02427,   0.3
0.02427,  -0.6
0.02426,  -0.7
0.02427,  -0.8
0.02428,  -0.5
0.02427,  -0.9
0.02426,  -0.5
0.02427,  -1.4
0.02427,  -0.6
0.02427,  -0.1
0.02425,  -0.2
0.02426,  -0.3
0.02428,  -0.6
0.02426,  -0.6
0.02426,  -0.8
0.02425,   0.8
0.02426,   0.0
0.02425,   0.4
0.02426,   0.1
0.02427,  -0.9
0.02426,   0.1
0.02425,  -0.9
0.02426,  -0.0
0.02426,  -1.0
0.02425,  -0.5
0.02428,  -0.7
0.02428,   0.1
0.02425,   0.6
0.02427,  -0.3
0.02428,  -0.6
0.02426,   0.7
0.02426,   0.4
0.02426,  -1.5
0.02428,   0.1
0.02427,  -0.5
0.02426,  -0.5
0.02427,  -1.6
0.02427,  -0.2
0.02426,  -0.0
0.02427,  -0.5
0.02427,  -0.7
0.02429,  -0.4
0.02428,  -0.5
0.02427,  -1.7
0.02427,  -1.2
0.02426,  -0.5
0.02425,  -0.6
0.02428,  -0.3
0.02427,   0.7
0.02428,   1.1
0.02426,   0.2
0.02428,  -0.2
0.02427,   0.2
0.02426,  -0.6
0.02427,  -0.7
0.02427,  -0.2
0.02428,  -0.8
0.02428,  -0.4
0.02427,  -0.2
0.02428,  -0.3
0.02427,  -0.4
0.02427,   0.7
0.02429,   0.4
0.02427,  -0.7
0.02429,   0.1
0.02428,   0.5
0.02426,  -0.3
0.02427,   0.3
0.02427,  -0.4
0.02427,  -0.3
0.02427,  -1.1
0.02428,  -0.7
0.02427,  -0.9
0.02427,  -0.6
0.02428,   1.4
0.02428,   2.7
0.02428,   4.8
0.02427,   3.9
0.02429,   5.0
0.02428,   6.5
0.02428,   5.9
0.02428,   4.6
0.02429,   4.0
0.02431,   5.7
0.02432,   6.3
0.02430,   5.8
0.02430,   6.4
0.02429,   6.0
0.02431,   6.2
0.02429,   6.2
0.02430,   6.4
0.02431,   6.3
0.02431,   6.9
0.02430,   5.2
0.02431,   5.1
0.02430,   5.1