File: MAE_3272/Module_1/Group1-1018 Cold Rolled.csv
2/12/2016
3:25 PM
Sampling Frequency:,10Hz
Group:,Group1
Extensometer:,E85191
Sample:,1018 Cold Rolled
Sample width [inch]:,0.497000
Sample thickness [inch]:,0.124000
--------,--------

Extensometer,Load
[Inches],[Lbs]
0.00001,   0.0
-0.00000,   0.4
0.00001,  -0.4
0.00000,   0.7
-0.00001,  -0.8
-0.00001,  -0.0
-0.00000,  -0.1
0.00001,   0.1
0.00000,  -1.3
-0.00000,  -0.2
0.00000,  -1.1
0.00001,   0.0
0.00000,   0.6
-0.00000,  -0.4
-0.00001,  -0.3
0.00001,   0.3
0.00000,  -0.4
0.00000,   0.2
-0.00000,  -0.8
0.00001,  -0.9
-0.00000,   0.2
0.00001,  -0.1
0.00000,  -0.9
0.00001,  -0.4
0.00002,  -0.4
0.00002,   0.6
0.00003,  -0.6
-0.00001,  -0.9
-0.00001,  -1.2
0.00001,  -0.7
0.00001,  -1.1
0.00000,  -1.2
-0.00001,  -0.6
0.00000,  -0.0
-0.00001,   0.8
0.00001,   0.2
0.00000,   0.0
-0.00002,  -0.1
-0.00001,  -0.4
-0.00000,   0.8
0.00001,  -1.0
0.00001,   0.3
0.00000,  -0.1
0.00000,   0.2
-0.00001,   0.5
0.00001,   0.0
0.00001,  -0.0
0.00001,  -0.9
-0.00001,  -0.2
0.00000,  -0.3
0.00000,   0.5
0.00001,   0.7
-0.00000,   0.0
-0.00000,   0.2
0.00000,   0.5
0.00001,   0.5
-0.00000,  -0.1
0.00000,  -0.5
0.00001,  -0.4
-0.00000,  -0.9
-0.00000,  -0.4
-0.00000,  -0.1
-0.00001,   0.9
-0.00001,  -0.4
0.00000,  -0.0
0.00000,   0.1
0.00001,   0.0
-0.00000,  -0.0
-0.00000,  -0.2
0.00001,   0.3
0.00001,  -0.3
0.00000,  -0.6
0.00000,  -0.3
0.00001,   0.2
0.00001,   0.4
-0.00001,   0.4
0.00001,  -0.0
0.00000,   0.1
0.00000,  -1.0
0.00000,  -0.2
0.00002,   0.3
-0.00000,  -1.3
-0.00001,   0.3
0.00001,  -0.3
0.00001,   0.3
0.00000,  -0.5
0.00001,  -0.1
0.00001,  -0.1
0.00001,  -0.2
0.00001,  -0.4
-0.00000,  -0.7
0.00000,  -0.3
-0.00000,  -0.7
0.00001,   0.1
0.00000,  -0.3
-0.00000,   0.1
0.00001,   0.2
0.00000,   0.1
0.00001,  -0.5
0.00001,  -0.9
0.00001,   0.0
0.00000,  -0.3
-0.00000,  -0.4
0.00002,  -0.1
0.00001,   0.4
-0.00001,   0.6
0.00001,   0.4
0.00000,   0.1
-0.00001,   0.3
0.00001,   1.4
0.00001,   0.9
0.00000,   0.8
-0.00000,   0.3
0.00000,   0.3
-0.00000,   0.2
-0.00000,   0.1
-0.00001,   0.0
-0.00000,   0.4
-0.00000,   0.5
0.00001,  -0.7
0.00000,  -0.7
-0.00000,  -0.3
0.00001,  -0.3
0.00002,   0.3
0.00000,  -0.5
0.00000,   0.1
-0.00000,   0.0
-0.00000,   0.5
0.00001,   0.4
0.00001,  -0.1
0.00000,  -0.6
0.00001,  -0.0
0.00002,  -0.2
0.00001,  -0.0
0.00001,   0.1
0.00001,   0.2
0.00001,   0.2
-0.00001,  -0.2
0.00001,  -0.2
0.00002,   0.8
0.00001,  -0.7
0.00001,  -0.4
0.00000,  -0.2
0.00001,   1.3
0.00002,   3.5
0.00002,   3.4
0.00004,   2.1
0.00004,   2.6
0.00002,   2.4
0.00003,   1.4
0.00004,   2.7
0.00003,   3.0
0.00003,   2.6
0.00004,   3.1
0.00004,   3.2
0.00004,   2.3
0.00002,   2.5
0.00003,   2.6
0.00004,   2.9
0.00004,   2.6
0.00004,   2.3
0.00004,   2.1
0.00003,   3.0
0.00004,   2.0
0.00002,   2.7
0.00004,   2.5
0.00005,   2.5
0.00003,   2.2
0.00004,   2.4
0.00004,   3.1
0.00003,   3.1
0.00002,   1.9
0.00003,   2.8
0.00003,   4.1
0.00002,   2.8
0.00002,   3.4
0.00003,   3.1
0.00003,   2.7
0.00003,   2.6
0.00002,   3.2
0.00003,   3.1
0.00005,   3.2
0.00003,   3.7
0.00002,   2.3
0.00003,   3.2
0.00001,   3.5
0.00001,   2.7
0.00002,   2.1
0.00003,   2.2
0.00002,   3.2
0.00001,   3.7
0.00003,   3.4
0.00003,   3.1
0.00002,   3.4
0.00001,   3.2
0.00002,   3.2
0.00003,   3.0
0.00003,   3.4
0.00003,   3.7
0.00002,   3.3
0.00002,   3.2
0.00002,   3.0
0.00003,   2.7
0.00003,   3.8
0.00004,   3.3
0.00004,   4.0
0.00004,   4.5
0.00003,   4.3
0.00004,   3.7
0.00003,   3.6
0.00002,   3.7
0.00004,   3.8
0.00003,   3.8
0.00001,   3.5
0.00003,   4.1
0.00003,   3.3
0.00002,   3.2
0.00002,   1.7
0.00002,   3.6
0.00003,   2.4
0.00003,   2.9
0.00004,   3.1
0.00004,   3.2
0.00003,   3.4
0.00003,   3.3
0.00003,   3.4
0.00002,   3.5
0.00003,   3.7
0.00004,   4.5
0.00005,   4.3
0.00004,   3.5
0.00003,   3.2
0.00002,   4.0
0.00004,   3.7
0.00003,   4.2
0.00004,   2.6
0.00003,   3.7
0.00004,   4.2
0.00003,   3.7
0.00004,   3.5
0.00003,   3.8
0.00002,   3.5
0.00003,   3.6
0.00003,   4.7
0.00002,   4.1
0.00004,   4.9
0.00002,   3.9
0.00004,   4.6
0.00004,   4.0
0.00003,   4.4
0.00003,   4.7
0.00003,   4.5
0.00005,   5.3
0.00004,   4.4
0.00004,   3.8
0.00004,   4.5
0.00005,   4.9
0.00005,   5.5
0.00004,   4.6
0.00003,   4.4
0.00004,   3.6
0.00004,   4.1
0.00005,   3.1
0.00002,   3.0
0.00004,   4.6
0.00003,   3.8
0.00004,   4.9
0.00005,   4.5
0.00004,   3.9
0.00003,   4.7
0.00003,   4.1
0.00005,   4.7
0.00003,   3.7
0.00003,   4.0
0.00004,   3.6
0.00003,   3.9
0.00003,   3.5
0.00002,   4.2
0.00003,   3.7
0.00003,   3.4
0.00004,   3.1
0.00004,   3.6
0.00004,   3.0
0.00005,   3.9
0.00004,   3.0
0.00003,   3.3
0.00005,   3.8
0.00006,   3.5
0.00004,   4.2
0.00003,   3.5
0.00003,   3.6
0.00003,   4.7
0.00004,   3.3
0.00003,   4.8
0.00003,   3.8
0.00003,   4.2
0.00003,   3.8
0.00005,   3.8
0.00004,   4.6
0.00004,   4.3
0.00005,   5.1
0.00004,   3.3
0.00003,   4.4
0.00005,   3.6
0.00005,   4.1
0.00004,   4.0
0.00003,   3.5
0.00003,   4.7
0.00002,   4.3
0.00005,   4.1
0.00003,   2.9
0.00004,   3.9
0.00004,   2.9
0.00002,   3.8
0.00003,   3.5
0.00002,   3.8
0.00003,   3.8
0.00002,   3.1
0.00004,   3.1
0.00002,   2.9
0.00003,   2.8
0.00004,   4.2
0.00004,   4.4
0.00001,   3.3
0.00003,   4.4
0.00003,   3.1
0.00003,   4.0
0.00005,   5.1
0.00003,   4.5
0.00004,   4.2
0.00005,   4.3
0.00002,   5.1
0.00005,   3.9
0.00004,   5.6
0.00004,   4.6
0.00003,   4.1
0.00003,   3.7
0.00004,   3.8
0.00003,   3.5
0.00003,   4.2
0.00003,   4.2
0.00004,   4.9
0.00006,   5.2
0.00003,   4.3
0.00004,   3.9
0.00002,   4.2
0.00003,   3.4
0.00002,   3.8
0.00004,   4.6
0.00004,   4.7
0.00003,   5.2
0.00004,   5.2
0.00004,   4.8
0.00003,   4.0
0.00003,   4.4
0.00004,   4.4
0.00004,   4.6
0.00003,   2.9
0.00003,   4.5
0.00003,   5.8
0.00003,   3.3
0.00004,   4.8
0.00003,   3.8
0.00004,   4.5
0.00004,   4.3
0.00006,   4.8
0.00003,   4.7
0.00004,   4.0
0.00007,   4.3
0.00003,   4.5
0.00003,   4.5
0.00003,   5.1
0.00005,   4.0
0.00003,   3.7
0.00004,   4.5
0.00004,   4.1
0.00004,   4.2
0.00004,   4.1
0.00004,   3.6
0.00003,   3.7
0.00004,   4.8
0.00003,   3.8
0.00003,   3.9
0.00003,   4.7
0.00004,   5.3
0.00003,   5.4
0.00002,   4.3
0.00002,   4.5
0.00004,   4.8
0.00004,   4.5
0.00004,   3.4
0.00004,   4.8
0.00003,   3.3
0.00004,   4.4
0.00004,   3.5
0.00004,   4.0
0.00006,   3.9
0.00005,   3.5
0.00005,   3.3
0.00005,   3.3
0.00003,   2.7
0.00005,   2.5
0.00003,   3.3
0.00003,   2.5
0.00005,   2.5
0.00002,   2.7
0.00001,   3.2
0.00004,   3.9
0.00004,   3.5
0.00005,   4.1
0.00003,   4.1
0.00004,   4.3
0.00003,   3.3
0.00003,   3.7
0.00004,   3.8
0.00005,   3.3
0.00004,   4.6
0.00005,   4.3
0.00005,   3.3
0.00004,   4.6
0.00004,   4.1
0.00005,   5.2
0.00005,   4.6
0.00003,   4.8
0.00004,   4.7
0.00005,   4.9
0.00003,   4.6
0.00002,   5.6
0.00004,   5.2
0.00002,   6.0
0.00005,   6.2
0.00004,   5.3
0.00005,   6.0
0.00004,   5.5
0.00005,   6.0
0.00006,   5.2
0.00004,   4.9
0.00006,   4.6
0.00004,   5.0
0.00004,   4.5
0.00005,   4.1
0.00005,   4.3
0.00004,   4.2
0.00005,   4.5
0.00004,   4.7
0.00004,   5.3
0.00004,   4.7
0.00003,   3.7
0.00004,   3.6
0.00005,   4.3
0.00002,   5.4
0.00005,   4.5
0.00004,   3.9
0.00006,   4.5
0.00004,   4.9
0.00004,   4.5
0.00005,   4.5
0.00005,   5.0
0.00004,   4.9
0.00003,   5.1
0.00006,   5.5
0.00005,   6.1
0.00005,   5.2
0.00004,   4.9
0.00005,   5.5
0.00003,   5.4
0.00004,   5.9
0.00005,   5.4
0.00005,   6.3
0.00005,   5.4
0.00006,   5.7
0.00004,   5.0
0.00005,   4.9
0.00003,   5.9
0.00002,   5.0
0.00004,   6.1
0.00004,   4.6
0.00005,   5.6
0.00005,   5.4
0.00004,   4.6
0.00005,   4.7
0.00006,   4.6
0.00003,   3.6
0.00004,   4.1
0.00004,   5.4
0.00004,   4.4
0.00003,   5.4
0.00003,   5.6
0.00004,   4.5
0.00005,   5.0
0.00004,   4.0
0.00004,   4.3
0.00003,   4.7
0.00005,   4.3
0.00005,   4.4
0.00004,   3.7
0.00005,   5.4
0.00004,   4.3
0.00004,   5.5
0.00002,   4.3
0.00004,   5.2
0.00004,   5.5
0.00003,   4.7
0.00003,   5.0
0.00004,   4.7
0.00003,   5.7
0.00002,   5.1
0.00003,   4.0
0.00003,   3.7
0.00005,   5.0
0.00004,   5.0
0.00006,   4.4
0.00004,   5.9
0.00003,   3.4
0.00003,   5.1
0.00004,   5.3
0.00004,   5.8
0.00006,   4.5
0.00003,   4.7
0.00004,   5.1
0.00005,   5.4
0.00003,   4.3
0.00004,   4.3
0.00004,   4.0
0.00004,   5.7
0.00003,   5.2
0.00003,   4.3
0.00004,   4.9
0.00005,   4.3
0.00003,   5.5
0.00007,   5.4
0.00005,   5.3
0.00004,   6.2
0.00004,   4.9
0.00004,   5.2
0.00005,   5.3
0.00003,   5.4
0.00005,   6.0
0.00004,   5.0
0.00002,   5.4
0.00005,   4.6
0.00004,   5.4
0.00004,   5.2
0.00005,   5.4
0.00005,   4.7
0.00003,   5.0
0.00004,   3.9
0.00005,   3.9
0.00004,   4.6
0.00004,   3.0
0.00004,   5.1
0.00004,   3.5
0.00005,   3.7
0.00004,   4.3
0.00005,   4.6
0.00007,   4.2
0.00005,   3.9
0.00005,   3.9
0.00006,   3.9
0.00007,   4.4
0.00004,   4.6
0.00005,   4.8
0.00005,   5.3
0.00005,   4.9
0.00005,   4.0
0.00004,   4.7
0.00005,   4.9
0.00005,   4.2
0.00004,   4.5
0.00005,   4.6
0.00005,   4.9
0.00005,   5.3
0.00005,   4.8
0.00005,   6.4
0.00003,   4.6
0.00004,   3.8
0.00005,   4.8
0.00005,   4.0
0.00005,   4.1
0.00006,   3.6
0.00004,   2.6
0.00005,   3.7
0.00005,   3.4
0.00005,   2.9
0.00003,   3.7
0.00005,   4.0
0.00006,   4.1
0.00005,   4.4
0.00006,   5.1
0.00006,   3.9
0.00004,   3.8
0.00004,   4.6
0.00005,   4.2
0.00006,   4.1
0.00005,   3.7
0.00004,   3.7
0.00004,   5.1
0.00006,   4.4
0.00004,   4.1
0.00006,   5.9
0.00005,   5.6
0.00005,   5.6
0.00004,   4.5
0.00005,   4.1
0.00005,   4.6
0.00005,   3.4
0.00004,   3.4
0.00006,   4.1
0.00005,   3.3
0.00005,   4.5
0.00006,   4.4
0.00004,   3.8
0.00005,   4.0
0.00003,   4.8
0.00005,   4.4
0.00005,   4.2
0.00005,   4.3
0.00004,   4.4
0.00006,   4.5
0.00005,   3.8
0.00005,   5.1
0.00005,   4.2
0.00004,   5.1
0.00005,   4.1
0.00006,   4.1
0.00006,   4.2
0.00005,   3.7
0.00006,   4.5
0.00004,   5.2
0.00004,   4.1
0.00005,   3.6
0.00004,   4.3
0.00004,   4.1
0.00004,   4.8
0.00004,   3.5
0.00005,   3.7
0.00004,   3.1
0.00005,   4.1
0.00004,   4.1
0.00004,   4.3
0.00004,   4.2
0.00006,   4.5
0.00004,   4.2
0.00005,   4.9
0.00005,   4.5
0.00005,   5.0
0.00003,   4.5
0.00005,   4.4
0.00005,   4.5
0.00005,   4.6
0.00006,   4.8
0.00004,   4.0
0.00004,   4.2
0.00003,   4.3
0.00004,   4.3
0.00006,   4.4
0.00003,   4.5
0.00005,   4.5
0.00005,   4.2
0.00006,   3.8
0.00005,   4.5
0.00005,   4.2
0.00006,   3.5
0.00006,   4.3
0.00005,   4.4
0.00003,   4.8
0.00004,   4.4
0.00005,   4.2
0.00005,   4.2
0.00004,   3.6
0.00006,   3.7
0.00004,   4.0
0.00005,   4.0
0.00005,   4.5
0.00004,   4.1
0.00006,   3.5
0.00005,   4.1
0.00005,   3.2
0.00004,   4.4
0.00005,   2.6
0.00004,   4.5
0.00006,   3.6
0.00004,   4.0
0.00002,   4.2
0.00004,   3.6
0.00004,   4.5
0.00006,   4.9
0.00005,   4.6
0.00005,   4.3
0.00005,   5.9
0.00004,   4.7
0.00003,   5.7
0.00005,   4.8
0.00005,   5.2
0.00004,   4.9
0.00004,   5.7
0.00004,   4.4
0.00005,   3.5
0.00005,   5.4
0.00004,   4.9
0.00004,   5.1
0.00006,   4.8
0.00005,   5.8
0.00006,   4.6
0.00007,   3.7
0.00005,   4.1
0.00006,   5.4
0.00005,   5.1
0.00005,   4.9
0.00006,   5.7
0.00005,   4.4
0.00004,   4.8
0.00006,   6.2
0.00007,   5.2
0.00006,   5.5
0.00005,   5.8
0.00005,   5.1
0.00003,   5.0
0.00005,   5.3
0.00005,   3.4
0.00004,   4.6
0.00005,   5.2
0.00004,   4.9
0.00004,   4.5
0.00005,   4.8
0.00004,   4.3
0.00006,   4.5
0.00004,   3.7
0.00004,   4.2
0.00004,   5.1
0.00003,   5.0
0.00005,   4.5
0.00006,   5.1
0.00004,   4.4
0.00005,   4.9
0.00004,   4.1
0.00005,   3.9
0.00003,   4.8
0.00005,   5.4
0.00005,   5.0
0.00005,   4.0
0.00005,   4.3
0.00005,   3.1
0.00005,   5.2
0.00005,   5.4
0.00005,   4.1
0.00007,   5.2
0.00004,   4.2
0.00005,   4.7
0.00006,   4.4
0.00005,   3.8
0.00006,   4.1
0.00004,   4.4
0.00005,   4.6
0.00005,   3.8
0.00005,   4.2
0.00006,   3.5
0.00006,   5.2
0.00006,   4.1
0.00005,   4.5
0.00004,   4.7
0.00005,   3.9
0.00005,   3.9
0.00006,   4.0
0.00005,   4.7
0.00005,   4.4
0.00005,   4.0
0.00006,   4.6
0.00006,   4.3
0.00007,   4.3
0.00006,   3.7
0.00007,   4.6
0.00006,   3.5
0.00005,   3.3
0.00006,   4.2
0.00005,   5.1
0.00007,   3.3
0.00006,   4.4
0.00005,   4.2
0.00004,   4.2
0.00003,   4.3
0.00006,   4.0
0.00006,   4.5
0.00006,   4.4
0.00006,   4.3
0.00006,   4.5
0.00004,   4.4
0.00005,   3.9
0.00004,   4.3
0.00006,   4.6
0.00006,   3.7
0.00005,   3.5
0.00005,   3.6