File: MAE_3272/Module_1/Group1-T0 Aluminum.csv
2/12/2016
2:29 PM
Sampling Frequency:,10Hz
Group:,Group1
Extensometer:,E85191
Sample:,T0 Aluminum
Sample width [inch]:,0.500000
Sample thickness [inch]:,0.125000
--------,--------

Extensometer,Load
[Inches],[Lbs]
0.00000,   0.2
0.00000,  -0.2
0.00001,  -0.2
0.00000,  -1.3
0.00000,   0.2
0.00001,  -0.1
-0.00001,   0.8
0.00000,  -0.3
0.00000,  -1.3
0.00001,  -0.6
0.00002,   0.1
0.00000,  -0.7
-0.00000,   0.4
-0.00000,  -0.5
-0.00000,  -0.1
0.00002,  -0.1
0.00000,   0.1
0.00001,   0.1
-0.00001,   0.1
-0.00001,  -0.1
-0.00001,   0.4
0.00000,   0.4
0.00001,   0.2
0.00001,   0.2
-0.00000,  -0.1
-0.00001,   0.7
-0.00000,   0.2
-0.00000,  -0.8
0.00000,   0.4
0.00000,   0.4
-0.00001,  -0.7
0.00000,   0.4
-0.00001,  -1.4
-0.00000,  -0.2
0.00001,  -0.7
0.00001,  -0.1
-0.00000,  -0.8
0.00000,   0.4
0.00000,   0.2
0.00001,   0.2
0.00001,   0.1
0.00001,  -0.5
-0.00000,  -0.8
-0.00000,  -0.4
0.00001,  -1.0
0.00000,  -1.0
0.00001,  -0.3
0.00000,  -0.5
0.00000,   0.5
0.00002,  -1.3
-0.00000,  -1.0
0.00002,   0.7
0.00001,  -0.3
0.00001,   0.1
0.00000,  -0.7
0.00002,   0.1
-0.00001,  -0.3
-0.00001,  -0.5
0.00002,  -0.2
0.00000,   0.2
0.00001,   0.8
0.00000,   1.5
0.00001,   0.2
0.00001,  -0.4
0.00001,  -0.6
0.00002,   1.0
0.00001,  -0.6
0.00001,   0.6
0.00001,   1.0
0.00000,   0.9
0.00000,  -0.1
0.00001,  -0.5
0.00001,   0.5
0.00002,   0.8
0.00001,  -0.0
0.00002,  -1.6
0.00002,  -0.6
0.00001,   0.4
-0.00001,   0.4
0.00001,  -0.5
0.00001,  -0.0
-0.00001,  -0.3
0.00002,  -0.8
-0.00000,   0.5
0.00001,  -0.1
-0.00000,  -0.3
0.00001,  -0.5
0.00001,   0.3
0.00001,  -1.0
0.00000,  -0.9
-0.00001,  -0.2
0.00001,  -0.9
0.00002,  -0.4
0.00000,   0.5
0.00001,  -0.6
0.00001,  -0.4
0.00002,  -0.4
0.00002,  -0.1
-0.00000,  -0.5
0.00001,  -0.3
0.00002,   0.3
0.00001,  -1.1
0.00001,  -0.2
0.00001,  -0.5
0.00002,  -0.3
0.00001,   0.2
0.00001,  -0.5
0.00001,  -0.1
0.00000,   0.2
0.00002,   0.2
0.00002,  -0.4
0.00002,   0.5
0.00003,   0.2
0.00002,  -0.7
0.00002,  -0.0
0.00001,  -1.1
0.00000,   0.2
0.00002,   0.9
0.00001,   0.2
0.00000,  -1.2
0.00000,  -0.2
0.00003,   0.6
0.00003,  -0.0
0.00001,   1.3
0.00001,   0.7
0.00002,  -0.6
0.00001,   0.7
0.00002,   0.3
-0.00000,   0.1
-0.00000,   0.5
0.00001,  -0.5
0.00001,   0.2
0.00001,  -0.0
-0.00000,  -0.0
0.00001,  -0.9
0.00001,  -0.4
-0.00000,   0.6
-0.00000,   0.1
-0.00001,  -0.4
-0.00001,  -0.8
0.00001,  -1.4
0.00002,  -1.8
-0.00000,   0.1
0.00002,  -0.5
0.00002,   0.1
0.00000,  -0.6
0.00002,  -0.6
0.00001,  -0.3
0.00000,  -0.8
0.00001,  -0.3
0.00001,  -0.2
0.00001,   0.0
0.00003,  -0.7
-0.00001,  -0.6
0.00003,   1.3
-0.00000,   0.0
0.00001,  -0.2
0.00001,   0.6
0.00002,   0.4
0.00002,   0.8
0.00001,   0.1
0.00001,   1.2
0.00002,   0.1
0.00002,   0.2
0.00003,   0.2
0.00002,  -0.9
0.00002,   0.4
0.00001,  -0.5
0.00002,  -0.0
0.00001,   0.5
0.00002,  -0.6
0.00002,  -0.9
0.00001,  -0.4
0.00002,   0.9
0.00002,  -0.6
0.00001,   0.2
0.00002,   0.2
0.00002,   0.7
0.00002,  -0.0
0.00001,   0.5
0.00002,  -0.1
0.00001,  -0.3
0.00001,   0.2
0.00002,  -0.0
0.00001,   0.6
0.00001,   0.5
0.00001,  -1.4
0.00001,   0.3
0.00002,   0.4
0.00001,  -0.4
0.00003,   0.4
0.00002,   0.8
0.00001,   0.8
0.00001,  -0.4
0.00002,   0.5
0.00002,  -0.2
0.00002,   0.2
0.00003,  -0.2
0.00002,   0.2
0.00002,  -0.8
0.00002,  -0.7
0.00002,   0.0
0.00002,   0.9
0.00002,  -0.1
0.00001,   0.1
0.00002,  -0.1
0.00001,   0.4
-0.00000,  -0.7
0.00001,  -0.1
0.00001,   0.2
0.00002,   0.4
0.00002,   0.1
-0.00000,  -0.2
0.00002,   0.1
0.00001,  -0.1
0.00002,  -1.5
0.00002,  -0.8
0.00002,  -0.1
0.00001,  -0.3
0.00003,   0.2
0.00003,  -0.2
0.00002,  -0.3
0.00001,  -0.2
0.00002,  -0.2
0.00003,  -0.7
0.00002,  -0.2
0.00004,  -0.7
0.00003,  -0.7
0.00001,  -0.5
0.00001,   0.1
0.00002,  -0.3
0.00001,  -0.2
-0.00000,   0.3
-0.00000,  -0.6
0.00002,  -0.1
0.00004,  -1.0
0.00003,  -0.2
0.00004,  -0.8
0.00002,  -0.9
-0.00000,   0.0
0.00001,  -1.7
0.00001,   0.3
0.00001,   0.1
0.00001,  -0.8
-0.00000,  -0.8
0.00001,  -0.3
0.00001,  -1.1
0.00000,   0.4
0.00001,  -0.7
0.00001,  -0.0
0.00001,  -1.1
0.00001,  -1.0
0.00001,  -0.6
0.00001,  -1.0
0.00002,   0.4
0.00002,   0.5
0.00002,  -0.2
0.00001,   0.5
0.00001,  -1.2
0.00003,  -0.9
0.00002,   0.3
-0.00000,  -0.1
0.00002,  -0.9
0.00001,   0.1
0.00001,  -0.6
0.00002,   0.4
0.00002,  -0.0
0.00003,  -0.6
0.00001,   0.0
0.00001,  -0.3
0.00004,   4.1
0.00005,   5.0
0.00006,   6.3
0.00006,   6.5
0.00006,   5.8
0.00007,   6.8
0.00008,   7.5
0.00012,   7.5
0.00012,   8.2
0.00013,  10.2
0.00019,  11.1
0.00019,  11.4
0.00020,  11.2
0.00020,  11.7
0.00021,  12.4
0.00021,  11.9
0.00019,  12.5
0.00020,  12.7
0.00021,  12.9
0.00020,  13.5
0.00019,  14.1
0.00020,  14.1
0.00021,  15.9
0.00020,  15.1
0.00022,  16.1
0.00022,  17.0
0.00023,  18.0
0.00022,  19.0
0.00023,  20.5
0.00026,  21.8
0.00026,  22.0
0.00026,  23.0
0.00027,  23.9
0.00027,  23.8
0.00027,  25.3
0.00028,  28.1
0.00028,  29.0
0.00030,  29.8
0.00029,  32.6
0.00030,  34.5
0.00032,  38.0
0.00033,  38.8
0.00033,  40.1
0.00034,  42.7
0.00034,  44.6
0.00035,  47.9
0.00036,  50.5
0.00040,  53.1
0.00039,  56.0
0.00041,  59.0
0.00042,  63.1
0.00043,  66.5
0.00044,  71.3
0.00047,  74.3
0.00048,  78.4
0.00049,  81.6
0.00052,  87.0
0.00052,  91.3
0.00052,  96.4
0.00055, 100.3
0.00058, 106.0
0.00058, 110.6
0.00062, 114.0
0.00064, 119.5
0.00065, 125.1
0.00068, 130.1
0.00069, 135.4
0.00071, 140.2
0.00075, 146.4
0.00077, 152.0
0.00081, 158.4
0.00084, 163.8
0.00088, 170.3
0.00093, 176.1
0.00097, 180.3
0.00101, 185.9
0.00107, 192.0
0.00113, 196.9
0.00122, 203.7
0.00128, 208.2
0.00137, 212.5
0.00147, 218.0
0.00159, 221.6
0.00173, 226.2
0.00187, 230.0
0.00202, 234.2
0.00219, 238.5
0.00234, 241.6
0.00250, 245.8
0.00266, 249.1
0.00285, 253.5
0.00301, 257.1
0.00319, 260.5
0.00337, 265.1
0.00356, 268.4
0.00376, 272.4
0.00396, 275.4
0.00415, 279.4
0.00436, 282.2
0.00456, 285.2
0.00475, 288.1
0.00495, 292.0
0.00517, 294.9
0.00536, 298.0
0.00557, 302.1
0.00578, 304.1
0.00599, 306.0
0.00620, 309.4
0.00639, 312.8
0.00661, 315.2
0.00681, 318.3
0.00702, 321.4
0.00723, 323.4
0.00744, 326.7
0.00767, 329.4
0.00788, 332.2
0.00810, 334.7
0.00832, 338.1
0.00852, 340.0
0.00874, 342.6
0.00895, 345.7
0.00917, 347.3
0.00938, 351.3
0.00958, 352.8
0.00980, 355.1
0.01004, 358.4
0.01027, 361.4
0.01049, 363.8
0.01070, 366.7
0.01093, 370.3
0.01114, 372.3
0.01139, 374.7
0.01159, 376.6
0.01182, 379.5
0.01205, 382.5
0.01229, 384.5
0.01251, 386.7
0.01275, 389.3
0.01300, 392.2
0.01323, 395.1
0.01348, 397.4
0.01371, 398.9
0.01394, 401.4
0.01418, 404.1
0.01441, 406.6
0.01463, 409.4
0.01487, 411.3
0.01508, 413.9
0.01533, 416.6
0.01554, 418.1
0.01578, 420.5
0.01601, 422.4
0.01625, 424.8
0.01647, 427.4
0.01670, 430.2
0.01696, 432.0
0.01719, 433.5
0.01744, 436.4
0.01769, 439.3
0.01793, 441.9
0.01815, 443.5
0.01841, 445.7
0.01863, 448.4
0.01888, 451.0
0.01910, 453.2
0.01935, 454.6
0.01959, 456.7
0.01983, 459.7
0.02010, 461.3
0.02033, 464.2
0.02058, 466.3
0.02085, 467.5
0.02114, 470.1
0.02141, 472.1
0.02169, 475.5
0.02195, 477.1
0.02222, 480.4
0.02251, 483.0
0.02283, 485.8
0.02313, 487.1
0.02346, 489.9
0.02376, 492.6
0.02407, 495.2
0.02433, 498.1
0.02465, 500.6
0.02498, 502.0
0.02535, 504.7
0.02570, 507.0
0.02604, 510.6
0.02640, 513.2
0.02674, 515.6
0.02711, 519.5
0.02748, 521.6
0.02785, 525.2
0.02823, 527.4
0.02862, 530.3
0.02901, 532.5
0.02939, 535.8
0.02978, 538.6
0.03014, 540.6
0.03049, 544.4
0.03087, 547.0
0.03125, 549.0
0.03167, 551.6
0.03211, 553.5
0.03252, 557.5
0.03289, 559.9
0.03321, 562.9
0.03353, 564.7
0.03392, 566.8
0.03442, 568.4
0.03494, 571.8
0.03540, 574.5
0.03578, 576.9
0.03605, 579.9
0.03636, 582.7
0.03660, 584.2
0.03711, 585.6
0.03764, 588.9
0.03819, 591.7
0.03872, 593.6
0.03913, 596.9
0.03936, 598.9
0.03962, 601.4
0.03974, 602.4
0.04001, 602.7
0.04064, 606.2
0.04122, 608.5
0.04186, 611.5
0.04247, 613.5
0.04300, 616.0
0.04335, 618.8
0.04354, 620.8
0.04365, 623.1
0.04373, 624.9
0.04418, 624.1
0.04480, 626.7
0.04541, 630.3
0.04609, 631.8
0.04670, 634.2
0.04723, 636.7
0.04776, 639.1
0.04798, 640.2
0.04809, 644.1
0.04836, 644.7
0.04881, 645.7
0.04928, 647.6
0.04975, 649.7
0.05030, 652.0
0.05094, 652.6
0.05146, 654.9
0.05199, 658.3
0.05257, 659.3
0.05281, 662.9
0.05309, 661.9
0.05361, 664.9
0.05406, 666.5
0.05455, 668.2
0.05504, 669.3
0.05554, 672.3
0.05593, 671.6
0.05651, 673.2
0.05680, 677.0
0.05713, 677.7
0.05773, 679.5
0.05810, 681.7
0.05843, 683.3
0.05905, 684.2
0.05967, 686.4
0.06031, 689.1
0.06090, 689.7
0.06146, 692.3
0.06189, 692.6
0.06248, 694.4
0.06289, 697.4
0.06306, 697.3
0.06323, 700.9
0.06372, 700.2
0.06404, 702.1
0.06423, 701.0
0.06488, 704.0
0.06557, 704.8
0.06627, 708.0
0.06698, 708.0
0.06769, 709.3
0.06837, 714.0
0.06916, 711.7
0.06980, 713.7
0.07002, 714.8
0.07016, 715.5
0.07041, 720.0
0.07084, 721.6
0.07111, 721.3
0.07174, 720.3
0.07243, 723.9
0.07313, 725.4
0.07382, 726.5
0.07450, 727.7
0.07508, 727.5
0.07532, 729.8
0.07576, 733.1
0.07652, 729.9
0.07728, 731.7
0.07769, 732.4
0.07786, 738.0
0.07810, 738.8
0.07867, 737.2
0.07935, 739.4
0.08003, 741.4
0.08070, 739.7
0.08106, 742.6
0.08169, 744.0
0.08243, 745.9
0.08316, 747.7
0.08389, 748.2
0.08438, 752.7
0.08479, 753.9
0.08541, 748.6
0.08612, 750.1
0.08661, 752.9
0.08689, 754.9
0.08730, 755.1
0.08795, 755.7
0.08862, 756.8
0.08935, 755.4
0.09001, 758.9
0.09065, 759.8
0.09130, 761.8
0.09202, 764.2
0.09267, 764.9
0.09292, 760.1
0.09297, 765.0
0.09317, 765.8
0.09374, 768.4
0.09437, 773.3
0.09522, 765.9
0.09601, 766.9
0.09664, 768.6
0.09697, 769.8
0.09717, 771.3
0.09772, 769.5
0.09846, 771.4
0.09920, 774.0
0.09996, 775.2
0.10075, 776.7
0.10153, 779.2
0.10229, 778.3
0.10297, 779.1
0.10350, 780.8
0.10385, 784.0
0.10443, 783.1
0.10511, 786.1
0.10562, 782.0
0.10634, 783.0
0.10709, 781.9
0.10788, 783.1
0.10833, 784.8
0.10858, 786.0
0.10901, 784.7
0.10973, 786.8
0.11048, 786.7
0.11125, 789.0
0.11204, 789.7
0.11261, 786.9
0.11276, 792.1
0.11313, 793.4
0.11387, 793.6
0.11462, 794.8
0.11536, 794.9
0.11621, 793.9
0.11699, 800.4
0.11764, 791.4
0.11813, 793.5
0.11889, 795.2
0.11968, 797.6
0.12051, 797.7
0.12103, 799.0
0.12133, 798.0
0.12152, 799.7
0.12170, 803.8
0.12236, 799.4
0.12315, 800.0
0.12398, 802.5
0.12483, 802.0
0.12568, 804.6
0.12657, 805.4
0.12745, 806.7
0.12833, 807.1
0.12922, 809.9
0.13015, 809.2
0.13108, 808.2
0.13166, 808.0
0.13211, 809.5
0.13259, 813.7
0.13290, 813.9
0.13324, 818.5
0.13411, 809.6
0.13492, 808.8
0.13575, 809.8
0.13660, 810.9
0.13714, 810.2
0.13750, 811.1
0.13772, 812.6
0.13794, 815.3
0.13851, 811.5
0.13930, 813.1
0.14016, 814.0
0.14103, 815.8
0.14191, 815.8
0.14277, 817.0
0.14359, 817.8
0.14435, 818.7
0.14469, 818.0
0.14489, 820.5
0.14504, 821.9
0.14551, 820.2
0.14627, 820.2
0.14708, 822.0
0.14791, 822.6
0.14881, 822.9
0.14964, 823.8
0.15034, 824.8
0.15081, 827.1
0.15112, 830.3
0.15148, 831.9
0.15224, 825.9
0.15284, 825.9
0.15297, 823.9
0.15310, 822.0
0.15369, 821.1
0.15459, 822.0
0.15551, 821.3
0.15642, 822.0
0.15729, 822.2
0.15818, 824.4
0.15903, 824.3
0.15991, 825.7
0.16079, 826.9
0.16168, 826.7
0.16254, 825.9
0.16345, 828.9
0.16430, 830.5
0.16514, 831.7
0.16598, 831.7
0.16682, 833.6
0.16768, 833.7
0.16858, 833.1
0.16951, 832.6
0.17042, 834.1
0.17131, 835.0
0.17225, 833.3
0.17322, 829.6
0.17402, 830.7
0.17461, 830.3
0.17510, 831.5
0.17550, 833.0
0.17590, 832.9
0.17665, 832.3
0.17745, 833.9
0.17834, 833.7
0.17924, 834.0
0.18017, 834.9
0.18111, 836.2
0.18203, 837.2
0.18297, 838.6
0.18391, 838.9
0.18484, 840.4
0.18577, 840.3
0.18672, 840.6
0.18767, 840.7
0.18861, 841.0
0.18954, 841.6
0.19040, 841.8
0.19117, 842.3
0.19151, 840.2
0.19167, 840.7
0.19181, 841.6
0.19194, 842.1
0.19247, 840.9
0.19337, 840.4
0.19431, 840.9
0.19521, 840.9
0.19612, 841.7
0.19706, 843.1
0.19804, 843.1
0.19898, 843.8
0.19994, 844.5
0.20089, 844.3
0.20185, 837.5
0.20258, 839.5
0.20338, 841.6
0.20397, 842.9
0.20414, 843.9
0.20421, 840.6
0.20415, 823.4
0.20428, 847.6
0.20451, 847.1
0.20538, 846.7
0.20629, 847.0
0.20728, 848.3
0.20823, 848.5
0.20915, 848.6
0.21009, 848.3
0.21104, 849.0
0.21201, 848.4
0.21302, 846.9
0.21400, 847.7
0.21498, 845.9
0.21599, 847.4
0.21693, 848.8
0.21790, 847.1
0.21882, 848.8
0.21976, 850.6
0.22072, 850.3
0.22168, 850.4
0.22269, 850.0
0.22364, 849.7
0.22462, 849.5
0.22561, 848.8
0.22659, 848.1
0.22760, 848.2
0.22858, 846.4
0.22906, 847.7
0.22941, 848.2
0.22964, 849.0
0.22976, 849.0
0.22983, 850.6
0.22988, 852.3
0.22990, 855.2
0.23000, 855.7
0.23011, 854.5
0.23042, 854.8
0.23111, 855.2
0.23193, 853.9
0.23280, 854.5
0.23372, 855.1
0.23464, 855.2
0.23557, 855.4
0.23655, 855.2
0.23750, 855.0
0.23845, 856.4
0.23943, 855.9
0.24037, 855.4
0.24136, 854.8
0.24235, 855.1
0.24336, 854.7
0.24432, 854.6
0.24528, 853.0
0.24624, 853.0
0.24718, 854.0
0.24816, 853.6
0.24913, 854.7
0.25012, 855.0
0.25108, 855.0
0.25205, 855.0
0.25305, 855.0
0.25401, 854.5
0.25497, 853.6
0.25591, 853.6
0.25688, 852.2
0.25783, 851.6
0.25867, 851.7
0.25925, 852.8
0.25968, 856.0
0.26009, 857.7
0.26066, 858.9
0.26151, 857.6
0.26244, 859.8
0.26341, 858.3
0.26434, 858.3
0.26528, 860.8
0.26619, 860.4
0.26717, 859.1
0.26814, 859.5
0.26908, 860.5
0.27003, 859.3
0.27099, 859.8
0.27197, 858.7
0.27294, 859.3
0.27391, 859.2
0.27485, 857.8
0.27580, 860.6
0.27674, 859.7
0.27770, 860.7
0.27869, 860.7
0.27968, 860.5
0.28067, 860.8
0.28163, 859.3
0.28260, 859.1
0.28357, 860.3
0.28452, 859.3
0.28546, 859.3
0.28641, 859.3
0.28738, 859.9
0.28838, 859.2
0.28935, 859.2
0.29034, 858.8
0.29130, 858.6
0.29191, 859.5
0.29232, 858.8
0.29265, 858.5
0.29279, 859.8
0.29288, 859.4
0.29292, 862.4
0.29298, 862.4
0.29303, 863.5
0.29310, 865.0
0.29336, 864.0
0.29395, 863.6
0.29476, 863.4
0.29566, 863.5
0.29656, 862.8
0.29748, 863.8
0.29844, 863.2
0.29939, 864.3
0.30038, 863.5
0.30135, 862.9
0.30233, 863.4
0.30328, 864.0
0.30422, 863.7
0.30520, 864.0
0.30618, 864.4
0.30713, 863.4
0.30809, 863.4
0.30904, 863.3
0.31003, 863.1
0.31102, 863.2
0.31198, 863.8
0.31296, 862.3
0.31393, 862.5
0.31489, 863.2
0.31583, 863.3
0.31680, 862.7
0.31778, 863.4
0.31873, 862.8
0.31971, 863.8
0.32069, 863.4
0.32167, 863.2
0.32265, 863.6
0.32362, 863.4
0.32458, 863.0
0.32553, 863.4
0.32650, 863.6
0.32746, 862.5
0.32846, 861.8
0.32942, 862.9
0.33036, 862.0
0.33125, 862.9
0.33204, 864.1
0.33265, 864.0
0.33314, 866.3
0.33351, 866.3
0.33386, 868.4
0.33453, 866.4
0.33545, 865.7
0.33642, 866.5
0.33737, 866.3
0.33831, 866.0
0.33929, 865.1
0.34027, 866.3
0.34125, 865.4
0.34222, 866.2
0.34319, 864.5
0.34413, 865.1
0.34510, 864.4
0.34606, 865.5
0.34702, 865.0
0.34800, 864.6
0.34896, 865.3
0.34991, 865.4
0.35085, 865.3
0.35180, 865.7
0.35279, 865.1
0.35377, 865.6
0.35471, 864.7
0.35569, 865.7
0.35666, 865.1
0.35763, 865.7
0.35860, 864.9
0.35955, 864.9
0.36051, 864.5
0.36148, 865.0
0.36243, 865.5
0.36340, 864.8
0.36437, 865.6
0.36533, 866.4
0.36632, 864.6
0.36726, 864.8
0.36823, 864.2
0.36921, 865.5
0.37019, 865.2
0.37117, 865.4
0.37214, 864.6
0.37311, 864.3
0.37409, 864.8
0.37507, 865.1
0.37601, 866.4
0.37662, 865.0
0.37705, 865.3
0.37739, 866.1
0.37769, 865.9
0.37792, 867.4
0.37815, 867.1
0.37830, 866.5
0.37839, 867.2
0.37850, 868.3
0.37856, 868.3
0.37866, 869.9
0.37873, 870.4
0.37892, 869.0
0.37943, 868.0
0.38018, 866.9
0.38108, 866.6
0.38203, 867.1
0.38296, 866.9
0.38394, 866.4
0.38490, 866.2
0.38589, 865.5
0.38688, 865.8
0.38786, 866.7
0.38884, 865.9
0.38979, 865.9
0.39075, 865.8
0.39175, 865.1
0.39270, 865.0
0.39368, 864.8
0.39465, 865.8
0.39564, 865.0
0.39662, 863.6
0.39759, 864.9
0.39855, 864.1
0.39952, 864.9
0.40046, 865.3
0.40148, 864.1
0.40244, 864.3
0.40341, 865.1
0.40436, 865.5
0.40531, 864.4
0.40630, 864.7
0.40729, 864.6
0.40825, 865.1
0.40920, 865.4
0.41019, 864.1
0.41116, 864.0
0.41214, 865.1
0.41309, 864.9
0.41408, 864.3
0.41506, 865.5
0.41605, 865.1
0.41704, 864.6
0.41802, 865.7
0.41899, 864.9
0.41996, 865.2
0.42091, 864.8
0.42190, 864.8
0.42287, 864.4
0.42385, 864.4
0.42482, 864.7
0.42580, 865.2
0.42676, 864.6
0.42774, 866.4
0.42874, 865.7
0.42971, 865.3
0.43070, 864.6
0.43167, 866.3
0.43264, 866.3
0.43361, 867.1
0.43459, 865.8
0.43556, 866.1
0.43651, 866.8
0.43750, 866.2
0.43846, 865.7
0.43945, 866.4
0.44042, 867.6
0.44139, 867.3
0.44234, 866.8
0.44331, 866.2
0.44431, 866.9
0.44530, 866.7
0.44628, 864.7
0.44727, 863.6
0.44822, 864.6
0.44920, 863.4
0.45019, 863.4
0.45118, 863.1
0.45218, 862.9
0.45317, 861.6
0.45413, 863.0
0.45508, 862.5
0.45606, 862.3
0.45707, 862.1
0.45804, 861.9
0.45904, 862.2
0.46001, 862.4
0.46099, 861.5
0.46196, 861.2
0.46293, 862.3
0.46391, 861.2
0.46486, 861.7
0.46585, 860.5
0.46683, 861.5
0.46782, 861.1
0.46878, 861.3
0.46975, 860.3
0.47075, 860.0
0.47171, 859.9
0.47269, 858.8
0.47368, 858.3
0.47466, 858.4
0.47566, 858.3
0.47661, 859.0
0.47757, 857.1
0.47858, 856.8
0.47957, 855.5
0.48054, 856.1
0.48153, 855.4
0.48249, 854.3
0.48346, 855.4
0.48446, 854.5
0.48545, 854.2
0.48641, 854.4
0.48740, 853.7
0.48838, 853.0
0.48935, 852.7
0.49030, 850.8
0.49129, 850.6
0.49229, 850.6
0.49327, 851.1
0.49424, 850.4
0.49523, 849.4
0.49623, 847.7
0.49719, 847.0
0.49817, 846.7
0.49914, 845.2
0.50011, 845.2
0.50108, 844.4
0.50202, 843.8
0.50294, 842.4
0.50384, 842.4
0.50480, 841.2
0.50566, 840.3
0.50657, 838.4
0.50749, 838.0
0.50838, 837.7
0.50926, 837.3
0.51014, 835.8
0.51103, 835.5
0.51192, 833.7
0.51279, 833.3
0.51367, 831.4
0.51455, 830.9
0.51536, 829.7
0.51618, 828.8
0.51698, 827.7
0.51780, 826.5
0.51860, 825.6
0.51940, 824.6
0.52015, 824.3
0.52099, 823.9
0.52181, 821.8
0.52262, 820.5
0.52341, 819.6
0.52422, 818.2
0.52502, 816.9
0.52585, 815.5
0.52662, 815.6
0.52743, 813.2
0.52824, 812.0
0.52907, 810.8
0.52988, 809.0
0.53070, 807.9
0.53154, 806.6
0.53233, 804.9
0.53314, 803.7
0.53394, 801.8
0.53472, 800.7
0.53553, 798.5
0.53635, 798.2
0.53716, 796.7
0.53797, 794.7
0.53878, 791.7
0.53958, 791.5
0.54036, 789.0
0.54113, 787.3
0.54189, 786.0
0.54265, 783.2
0.54339, 781.4
0.54412, 780.4
0.54487, 778.3
0.54561, 776.6
0.54636, 775.2
0.54711, 774.6
0.54781, 771.4
0.54860, 769.9
0.54930, 767.2
0.55001, 765.9
0.55073, 763.1
0.55146, 762.0
0.55218, 759.2
0.55291, 758.0
0.55361, 755.6
0.55431, 753.6
0.55501, 752.2
0.55571, 750.0
0.55646, 747.5
0.55714, 744.4
0.55785, 743.1
0.55855, 739.8
0.55925, 737.3
0.55996, 736.5
0.56066, 732.5
0.56140, 730.5
0.56211, 727.0
0.56282, 726.0
0.56351, 722.1
0.56425, 720.3
0.56498, 717.2
0.56572, 713.6
0.56643, 711.1
0.56715, 707.8
0.56783, 705.4
0.56855, 701.4
0.56923, 699.1
0.56992, 696.0
0.57062, 692.6
0.57134, 688.9
0.57205, 685.8
0.57275, 682.8
0.57346, 678.1
0.57418, 675.2
0.57487, 670.8
0.57557, 667.4
0.57626, 663.6
0.57695, 659.1
0.57768, 654.8
0.57838, 650.3
0.57913, 645.5
0.57986, 640.8
0.58061, 635.0
0.58134, 629.7
0.58210, 622.8
0.58296, 609.2
0.58433, 568.0
0.58570, 530.9
0.58942, 409.0
0.59116, 367.4
0.59364, 315.0
0.59535, 285.1
0.59673, 264.2
0.59804, 245.5
0.59939, 223.3
0.60069, 204.8
0.60202, 184.8
0.60350, 164.9
0.60490, 146.0
0.60624, 131.7
0.60757, 116.3
0.60889, 101.8
0.61021,  88.7
0.61147,  76.3
0.61273,  64.5
0.61389,  55.5
0.61490,  49.8
0.61582,  44.1
0.61678,  38.2
0.61905,  27.0
0.62060,  16.1
0.62879,   1.2
0.63470,   1.8
0.63449,   2.2
0.63465,   1.5
0.63467,   2.0
0.63461,   2.4
0.63458,   2.3
0.63462,   2.0
0.63466,   2.1
0.63468,   2.4
0.63475,   2.4
0.63477,   1.9
0.63479,   1.5
0.63481,   1.3
0.63482,   1.4
0.63484,   2.2
0.63488,   2.5
0.63493,   2.8
0.63493,   2.0
0.63495,   2.2
0.63494,   1.8
0.63494,   2.5
0.63495,   2.2
0.63497,   1.8
0.63497,   2.6
0.63495,   2.7
0.63495,   2.5
0.63497,   2.0
0.63497,   2.8
0.63495,   2.5
0.63496,   2.0
0.63498,   2.7
0.63496,   2.7
0.63499,   2.6
0.63497,   2.0
0.63498,   2.9
0.63499,   2.9
0.63498,   3.5
0.63497,   2.2
0.63499,   1.8
0.63499,   2.7
0.63498,   2.7
0.63498,   3.5
0.63498,   3.1
0.63497,   3.1
0.63498,   1.1
0.63498,   2.4
0.63499,   2.8
0.63497,   3.2
0.63498,   2.6
0.63498,   2.7
0.63498,   2.0
0.63498,   2.2
0.63498,   2.1
0.63499,   2.0
0.63498,   3.2
0.63501,   2.3