File: MAE_3272/Module_1/Group1-1018 Cold Rolled_5.csv
2/12/2016
3:34 PM
Sampling Frequency:,10Hz
Group:,Group1
Extensometer:,E85191
Sample:,1018 Cold Rolled
Sample width [inch]:,0.497000
Sample thickness [inch]:,0.124000
--------,--------

Extensometer,Load
[Inches],[Lbs]
0.00002,  -0.0
0.00002,  -0.6
0.00002,   0.6
0.00001,  -0.0
0.00001,  -0.5
0.00002,   0.4
0.00001,   0.4
0.00001,   3.6
0.00001,   3.5
0.00003,   4.1
0.00001,   3.4
0.00001,   4.4
0.00002,   3.7
0.00001,   3.5
0.00003,   3.6
0.00002,   3.8
0.00001,   3.1
0.00003,   3.4
-0.00000,   3.2
0.00003,   2.2
0.00003,   2.3
0.00001,   4.2
0.00003,   3.7
0.00002,   1.9
0.00002,   3.3
0.00002,   2.9
0.00001,   2.3
0.00001,   2.2
0.00002,   3.1
0.00001,   2.3
-0.00333,   2.4
-0.00334,   6.5
-0.00334,  10.7
-0.00335,  16.6
-0.00335,  22.3
-0.00334,  27.8
-0.00334,  16.7
-0.00322,  12.7
-0.00319,  31.3
-0.00317,  36.2
-0.00314,  38.8
-0.00313,  41.7
-0.00313,  43.0
-0.00316,  44.6
-0.00314,  45.2
-0.00313,  43.6
-0.00314,  42.1
-0.00313,  42.4
-0.00314,  42.8
-0.00316,  41.5
-0.00314,  43.4
-0.00314,  43.7
-0.00314,  42.5
-0.00313,  44.3
-0.00311,  43.7
-0.00311,  49.5
-0.00339,  54.5
-0.00339,  63.2
-0.00340,  70.8
-0.00338,  80.4
-0.00337,  90.6
-0.00336, 101.0
-0.00335, 113.2
-0.00334, 126.1
-0.00332, 140.3
-0.00330, 154.0
-0.00327, 169.4
-0.00325, 183.2
-0.00323, 198.5
-0.00322, 214.0
-0.04852, 228.6
-0.04847, 245.3
-0.04845, 264.0
-0.04842, 282.3
-0.04842, 301.2
-0.04838, 318.4
-0.04836, 336.6
-0.04832, 356.9
-0.04831, 377.7
-0.04828, 401.7
-0.04826, 422.0
-0.04821, 443.9
-0.04820, 465.6
-0.04818, 489.1
-0.04813, 513.7
-0.04809, 539.0
-0.04805, 572.1
-0.04801, 605.5
-0.04797, 640.4
-0.04794, 674.6
-0.04786, 708.5
-0.04782, 747.7
-0.04777, 786.3
-0.04771, 827.3
-0.04764, 868.6
-0.04759, 910.8
-0.04754, 954.3
-0.04747, 998.6
-0.04740,1044.6
-0.04735,1089.9
-0.04730,1136.8
-0.04720,1184.7
-0.04714,1234.4
-0.04707,1284.1
-0.04700,1334.6
-0.04693,1384.7
-0.04685,1436.0
-0.04679,1487.8
-0.04669,1539.9
-0.04662,1592.5
-0.04654,1645.9
-0.04647,1699.4
-0.04638,1754.0
-0.04631,1808.2
-0.04624,1863.7
-0.04614,1919.6
-0.04607,1976.4
-0.04598,2032.6
-0.04587,2089.7
-0.04580,2147.2
-0.04570,2205.8
-0.04560,2261.2
-0.04552,2320.1
-0.04542,2380.9
-0.04533,2439.0
-0.04522,2497.5
-0.04514,2556.1
-0.04503,2615.1
-0.04491,2675.6
-0.04481,2734.8
-0.04470,2796.2
-0.04457,2857.6
-0.04445,2916.1
-0.04433,2977.0
-0.04423,3037.8
-0.04410,3098.4
-0.04399,3156.4
-0.04384,3218.9
-0.04373,3280.3
-0.04359,3341.9
-0.04345,3400.5
-0.04329,3461.1
-0.04317,3520.8
-0.04300,3581.5
-0.04285,3639.6
-0.04271,3696.6
-0.04254,3755.6
-0.04237,3814.8
-0.04218,3871.3
-0.04201,3928.3
-0.04183,3984.8
-0.04163,4043.6
-0.04142,4098.9
-0.04120,4155.1
-0.04097,4211.6
-0.04071,4267.6
-0.04048,4320.2
-0.04022,4371.1
-0.03994,4422.9
-0.03962,4473.2
-0.03929,4522.6
-0.03896,4569.7
-0.03859,4613.0
-0.03817,4657.4
-0.03772,4698.1
-0.03722,4733.1
-0.03668,4766.7
-0.03607,4796.6
-0.03540,4822.1
-0.03465,4846.7
-0.03386,4861.8
-0.03300,4877.1
-0.03205,4888.6
-0.03111,4896.7
-0.03008,4904.6
-0.02900,4908.2
-0.02788,4910.5
-0.02676,4914.2
-0.02557,4915.5
-0.02439,4916.5
-0.02319,4915.9
-0.02197,4914.5
-0.02074,4913.0
-0.01950,4912.0
-0.01826,4909.0
-0.01704,4905.3
-0.01578,4905.3
-0.01450,4902.8
-0.01322,4900.6
-0.01196,4897.4
-0.01065,4895.7
-0.00932,4892.8
-0.00801,4889.3
-0.00669,4888.1
-0.00538,4883.5
-0.00406,4881.4
-0.00275,4876.8
-0.00144,4873.7
-0.00011,4870.2
0.00125,4867.4
0.00258,4863.3
0.00396,4859.6
0.00534,4857.4
0.00674,4855.8
0.00826,4853.4
0.00987,4848.4
0.01150,4844.9
0.01311,4838.3
0.01476,4834.9
0.01643,4828.1
0.01811,4822.1
0.01980,4816.4
0.02148,4811.0
0.02317,4803.9
0.02485,4797.5
0.02656,4791.1
0.02829,4783.1
0.02999,4774.2
0.03166,4768.6
0.03336,4760.3
0.03503,4750.3
0.03673,4742.9
0.03845,4734.9
0.04019,4726.3
0.04187,4716.2
0.04363,4707.4
0.04534,4697.8
0.04704,4689.2
0.04877,4680.1
0.05047,4668.8
0.05220,4658.7
0.05392,4647.2
0.05567,4638.1
0.05742,4625.5
0.05911,4613.7
0.06085,4603.0
0.06262,4591.4
0.06438,4578.3
0.06610,4566.3
0.06784,4554.1
0.06959,4539.7
0.07135,4527.0
0.07312,4514.2
0.07490,4498.8
0.07667,4484.2
0.07843,4468.9
0.08023,4453.4
0.08201,4438.1
0.08380,4421.4
0.08559,4404.5
0.08739,4386.2
0.08921,4367.6
0.09098,4349.0
0.09280,4330.1
0.09463,4309.2
0.09643,4288.8
0.09824,4266.6
0.10006,4245.4
0.10190,4221.4
0.10376,4197.7
0.10560,4172.3
0.10745,4145.7
0.10933,4118.3
0.11121,4088.7
0.11307,4058.5
0.11495,4027.2
0.11684,3996.4
0.11878,3961.8
0.12068,3924.6
0.12259,3886.6
0.12452,3848.0
0.12649,3805.3
0.12827,3757.8
0.12972,3721.6
0.13118,3685.0
0.13261,3647.4
0.13411,3608.0
0.13559,3564.7
0.13710,3517.4
0.14167,3226.8
0.32670, -18.1
0.31063, -15.8
0.31178, -14.9
0.31281, -14.6
0.31282, -13.5
0.31283, -13.6
0.31283, -12.0
0.31282, -11.7
0.31371, -11.2
0.31143, -11.0
0.27841, -12.2
0.25088, -10.3
0.21336, -10.3
0.24825, -10.6
0.22236,  -8.8
-0.62501,  -8.6
-0.16438,  -9.1
-0.05640,  -9.7
-0.09171,  -9.3
-0.11639,  -9.9
-0.44397,  -9.2
-0.42791,  -9.0
-0.48153,  -8.9
-0.51487,  -8.5
-0.59626,  -9.1
-0.67602,  -8.9
-0.67553,  -8.3
-0.29574,  -6.2
0.11075,  -6.1
0.08554,  -6.8
0.03281,  -7.5
0.01343,  -8.6
0.00877,  -7.4
0.00561,  -8.2
0.00606,  -8.1
0.00630,  -7.3
0.00669,  -8.7
0.00676,  -7.4
0.00675,  -7.3
0.00675,  -7.0
0.00675,  -7.1
0.00675,  -7.5
0.00675,  -7.6
0.00674,  -7.1
0.00675,  -7.7
0.00675,  -8.8
0.00674,  -7.6
0.00675,  -7.7
0.00674,  -7.8
0.00674,  -7.8
0.00673,  -7.2
0.00674,  -6.9
0.00673,  -7.7
0.00673,  -8.2
0.00675,  -7.8
0.00673,  -7.6
0.00673,  -6.7
0.00673,  -6.9
0.00673,  -7.3
0.00674,  -6.2
0.00673,  -6.1
0.00672,  -5.9
0.00673,  -6.9
0.00673,  -6.9
0.00672,  -6.9
0.00672,  -7.0
0.00671,  -7.0
0.00671,  -6.7
0.00673,  -6.8
0.00672,  -7.5
0.00672,  -7.1
0.00673,  -6.5
0.00672,  -6.6
0.00671,  -6.9
0.00671,  -6.9
0.00670,  -7.5
0.00670,  -7.3
0.00671,  -6.9
0.00671,  -7.0
0.00670,  -6.7
0.00672,  -6.4
0.00671,  -6.5
0.00672,  -7.1
0.00673,  -6.7
0.00671,  -6.7
0.00670,  -7.3
0.00670,  -6.5
0.00670,  -7.1
0.00672,  -6.2
0.00671,  -6.5
0.00670,  -6.6
0.00670,  -6.1
0.00671,  -7.2
0.00670,  -5.4
0.00671,  -7.1
0.00670,  -6.5
0.00669,  -6.4
0.00671,  -7.6
0.00671,  -6.6
0.00669,  -6.6
0.00669,  -6.4
0.00670,  -6.3
0.00669,  -5.5
0.00671,  -6.1
0.00669,  -6.3
0.00670,  -6.9
0.00671,  -7.5
0.00672,  -6.7
0.00671,  -6.9
0.00669,  -6.5
0.00669,  -5.4
0.00669,  -5.9
0.00669,  -6.6
0.00671,  -7.2
0.00670,  -6.3
0.00669,  -5.9
0.00670,  -6.2
0.00668,  -5.5
0.00669,  -6.4
0.00670,  -6.8
0.00667,  -7.7
0.00670,  -7.0
0.00670,  -7.3
0.00669,  -6.9
0.00671,  -7.2
0.00669,  -5.6
0.00670,  -7.4
0.00669,  -6.7
0.00670,  -6.9
0.00668,  -7.1
0.00669,  -7.7
0.00669,  -7.1
0.00669,  -7.2
0.00669,  -7.4
0.00668,  -6.8
0.00668,  -6.1
0.00668,  -7.7
0.00669,  -5.7
0.00668,  -6.4
0.00669,  -6.0
0.00667,  -6.6
0.00669,  -5.9
0.00669,  -6.7
0.00671,  -6.6
0.00670,  -6.5
0.00670,  -4.9
0.00669,  -6.5
0.00671,  -6.4
0.00670,  -7.3
0.00671,  -6.9
0.00668,  -6.1
0.00669,  -6.0
0.00670,  -6.8
0.00669,  -8.0
0.00670,  -6.6
0.00669,  -6.9
0.00669,  -6.1
0.00671,  -7.6
0.00669,  -6.1
0.00669,  -6.6
0.00669,  -6.5
0.00670,  -5.9
0.00668,  -6.9
0.00668,  -6.5
0.00668,  -6.0
0.00671,  -6.7
0.00668,  -5.9
0.00669,  -6.1
0.00669,  -6.2
0.00668,  -6.6
0.00667,  -5.8
0.00669,  -6.4
0.00668,  -6.2
0.00669,  -5.9
0.00670,  -6.7
0.00670,  -5.3
0.00668,  -6.4
0.00668,  -5.7
0.00668,  -6.4
0.00669,  -6.5
0.00667,  -6.2
0.00668,  -6.0
0.00669,  -6.4
0.00669,  -5.9
0.00667,  -6.5
0.00669,  -6.1
0.00668,  -5.0
0.00668,  -6.2
0.00668,  -6.7
0.00668,  -6.4
0.00667,  -5.8
0.00668,  -6.2
0.00668,  -6.0
0.00666,  -6.1
0.00670,  -6.4
0.00668,  -6.0
0.00668,  -5.7
0.00668,  -7.3
0.00668,  -5.0
0.00666,  -6.0
0.00669,  -7.2
0.00667,  -6.5
0.00667,  -6.7
0.00668,  -6.6
0.00666,  -7.1
0.00665,  -6.3
0.00665,  -7.0
0.00666,  -5.7
0.00666,  -5.6
0.00665,  -6.9
0.00666,  -6.6
0.00665,  -5.8
0.00667,  -5.3
0.00665,  -6.5
0.00666,  -5.9
0.00668,  -6.5
0.00666,  -5.8
0.00667,  -5.9
0.00665,  -7.3
0.00666,  -5.6
0.00666,  -5.9
0.00666,  -5.9
0.00666,  -6.4
0.00666,  -6.0
0.00667,  -5.9
0.00667,  -5.4
0.00665,  -7.1
0.00665,  -6.3
0.00665,  -6.8
0.00664,  -6.1
0.00665,  -5.3
0.00665,  -6.2
0.00665,  -6.0
0.00666,  -6.1
0.00666,  -5.8
0.00666,  -6.1
0.00666,  -6.2
0.00667,  -6.4
0.00664,  -4.4
0.00666,  -6.5
0.00666,  -7.2
0.00666,  -6.3
0.00665,  -6.1
0.00665,  -5.9
0.00664,  -5.6
0.00666,  -6.3
0.00665,  -5.2
0.00666,  -5.1
0.00665,  -5.8
0.00665,  -6.2
0.00664,  -5.6
0.00663,  -6.1
0.00665,  -6.7
0.00665,  -5.3
0.00666,  -5.6
0.00665,  -5.3
0.00666,  -5.8
0.00666,  -5.0
0.00665,  -5.8
0.00664,  -5.3
0.00665,  -6.5
0.00664,  -6.1
0.00664,  -6.2
0.00665,  -5.9
0.00666,  -5.9
0.00665,  -6.4
0.00664,  -6.4
0.00665,  -6.1
0.00664,  -5.9
0.00666,  -6.2
0.00665,  -5.3
0.00665,  -6.9
0.00665,  -5.4
0.00664,  -5.6
0.00664,  -6.0
0.00665,  -5.8
0.00665,  -6.0
0.00665,  -6.5
0.00665,  -6.8
0.00665,  -6.4
0.00664,  -6.9
0.00664,  -6.4
0.00663,  -5.7
0.00665,  -6.5
0.00664,  -6.1
0.00663,  -6.4
0.00664,  -5.9
0.00662,  -6.0
0.00664,  -6.5
0.00665,  -6.8
0.00666,  -6.5
0.00665,  -5.6
0.00664,  -7.0
0.00665,  -6.6
0.00663,  -7.2
0.00663,  -5.9
0.00663,  -4.9
0.00664,  -5.8
0.00664,  -4.8
0.00664,  -6.4
0.00664,  -6.2
0.00663,  -5.9
0.00663,  -5.7
0.00665,  -5.6
0.00666,  -5.9
0.00664,  -6.7
0.00663,  -5.9
0.00664,  -5.6
0.00664,  -6.9
0.00664,  -6.4
0.00663,  -5.8
0.00664,  -5.7
0.00665,  -5.5
0.00664,  -6.7
0.00664,  -5.1
0.00665,  -5.4
0.00662,  -5.6
0.00664,  -5.4
0.00666,  -5.7
0.00665,  -6.0
0.00664,  -5.4
0.00664,  -6.0
0.00664,  -6.9
0.00664,  -5.6
0.00664,  -6.9
0.00663,  -6.0
0.00663,  -5.8
0.00663,  -5.1
0.00664,  -5.9
0.00662,  -6.1
0.00664,  -6.1
0.00666,  -7.0
0.00664,  -5.9
0.00662,  -6.7
0.00662,  -6.6
0.00663,  -6.3
0.00664,  -6.1
0.00664,  -7.2
0.00664,  -6.5
0.00666,  -6.9
0.00665,  -5.8
0.00664,  -6.6
0.00665,  -5.7
0.00665,  -5.3
0.00664,  -4.3
0.00664,  -6.7
0.00666,  -6.0
0.00665,  -6.1
0.00664,  -6.8
0.00662,  -6.3
0.00663,  -7.1
0.00663,  -6.7
0.00664,  -6.5
0.00664,  -5.8
0.00664,  -6.5
0.00664,  -6.6
0.00664,  -7.0
0.00663,  -7.0
0.00664,  -5.6
0.00664,  -6.7
0.00664,  -6.1
0.00665,  -6.6
0.00664,  -5.6
0.00664,  -5.5
0.00664,  -5.4
0.00664,  -5.8
0.00666,  -5.8
0.00663,  -5.7
0.00665,  -5.5
0.00664,  -5.9
0.00666,  -5.2
0.00665,  -6.3
0.00664,  -5.0
0.00664,  -6.4
0.00663,  -5.9
0.00664,  -5.7
0.00664,  -5.3
0.00664,  -6.7
0.00665,  -5.9
0.00664,  -6.1
0.00665,  -5.8
0.00664,  -5.6
0.00662,  -5.8
0.00663,  -6.1
0.00663,  -5.7
0.00665,  -5.1
0.00662,  -5.8
0.00662,  -5.3
0.00662,  -6.3
0.00663,  -5.5
0.00664,  -4.9
0.00663,  -6.7
0.00665,  -6.1
0.00664,  -6.0
0.00663,  -5.8
0.00664,  -5.8
0.00665,  -6.5
0.00665,  -5.5
0.00664,  -5.9
0.00664,  -6.2
0.00664,  -6.2
0.00664,  -7.4
0.00663,  -6.8
0.00663,  -6.9
0.00666,  -6.2
0.00662,  -6.0
0.00663,  -5.2
0.00662,  -5.6
0.00663,  -5.5
0.00662,  -4.9
0.00662,  -5.8
0.00663,  -5.5
0.00662,  -4.7
0.00664,  -4.6
0.00664,  -4.6
0.00662,  -5.6
0.00663,  -6.0
0.00664,  -5.4
0.00665,  -6.1
0.00663,  -6.9
0.00663,  -5.6
0.00662,  -6.5
0.00663,  -5.8
0.00664,  -6.2
0.00665,  -5.1
0.00663,  -5.6
0.00664,  -5.8
0.00662,  -6.8
0.00661,  -6.7
0.00664,  -5.8
0.00664,  -6.8
0.00664,  -7.8
0.00664,  -6.5
0.00662,  -5.8
0.00663,  -5.7
0.00663,  -6.0
0.00663,  -6.4
0.00663,  -5.2
0.00662,  -5.9
0.00664,  -5.5
0.00661,  -5.6
0.00663,  -6.5
0.00662,  -5.6
0.00664,  -6.5
0.00663,  -4.9
0.00663,  -5.5
0.00663,  -5.9
0.00664,  -6.3
0.00661,  -5.5
0.00663,  -5.2
0.00662,  -6.0
0.00664,  -5.5
0.00664,  -5.9
0.00662,  -6.2
0.00664,  -5.3
0.00663,  -6.2
0.00661,  -4.9
0.00664,  -5.8
0.00664,  -6.0
0.00664,  -5.7
0.00662,  -5.6
0.00663,  -6.6
0.00665,  -5.4
0.00663,  -4.2
0.00663,  -5.7
0.00663,  -6.2
0.00663,  -5.6
0.00662,  -5.5
0.00663,  -5.7
0.00662,  -6.1
0.00664,  -6.1
0.00664,  -5.4
0.00663,  -4.9
0.00664,  -5.3
0.00662,  -6.2
0.00663,  -5.6
0.00664,  -5.3
0.00664,  -5.4
0.00663,  -4.7
0.00662,  -5.6
0.00662,  -5.4
0.00663,  -5.6
0.00662,  -5.6
0.00663,  -4.6
0.00663,  -4.6
0.00662,  -4.4
0.00662,  -5.8
0.00663,  -5.6
0.00662,  -4.9
0.00664,  -4.7
0.00662,  -4.7
0.00663,  -4.5
0.00663,  -5.4
0.00663,  -5.7
0.00663,  -5.5
0.00662,  -5.2
0.00664,  -6.3
0.00662,  -5.3
0.00663,  -5.7
0.00662,  -4.7
0.00663,  -5.9
0.00663,  -4.2
0.00664,  -4.9
0.00663,  -5.5
0.00663,  -5.5
0.00661,  -4.9
0.00663,  -6.4
0.00662,  -4.4
0.00662,  -5.3
0.00663,  -6.1
0.00662,  -4.6
0.00663,  -5.3
0.00664,  -5.0
0.00665,  -5.4
0.00662,  -5.6
0.00662,  -5.5
0.00662,  -5.3
0.00661,  -5.4
0.00663,  -4.6
0.00662,  -5.1
0.00662,  -5.2
0.00660,  -5.0
0.00661,  -5.4
0.00662,  -5.8
0.00661,  -5.5
0.00664,  -4.7
0.00662,  -5.5
0.00663,  -5.7
0.00661,  -5.1
0.00662,  -4.9
0.00662,  -4.8
0.00662,  -4.8
0.00663,  -5.1
0.00663,  -5.6
0.00663,  -6.1
0.00663,  -4.8
0.00662,  -5.7
0.00662,  -5.5
0.00662,  -6.5
0.00663,  -6.1
0.00661,  -6.2
0.00662,  -6.5
0.00661,  -5.7
0.00662,  -4.4
0.00662,  -6.1
0.00663,  -5.8
0.00662,  -6.0
0.00663,  -6.2
0.00663,  -6.0
0.00662,  -5.8
0.00664,  -6.9
0.00663,  -5.9
0.00661,  -5.1
0.00661,  -5.9
0.00663,  -5.2
0.00663,  -6.2
0.00663,  -5.0
0.00662,  -4.6
0.00664,  -5.5
0.00661,  -5.4
0.00661,  -4.7
0.00663,  -4.8
0.00662,  -5.0
0.00662,  -5.3
0.00660,  -4.4
0.00661,  -5.5
0.00664,  -4.7
0.00661,  -5.3
0.00663,  -5.5
0.00661,  -4.4
0.00662,  -5.8
0.00662,  -5.3
0.00661,  -5.2
0.00661,  -4.7
0.00661,  -6.4
0.00662,  -5.5
0.00662,  -6.7
0.00662,  -5.2
0.00662,  -5.7
0.00660,  -5.7
0.00661,  -5.1
0.00661,  -6.0
0.00663,  -6.0
0.00661,  -5.6
0.00662,  -5.0
0.00661,  -6.0
0.00662,  -4.6
0.00661,  -5.4
0.00661,  -5.5
0.00662,  -5.8
0.00661,  -4.9
0.00663,  -4.4
0.00662,  -4.0
0.00661,  -3.9
0.00661,  -5.2
0.00662,  -5.5
0.00662,  -5.0
0.00662,  -5.6
0.00661,  -5.4
0.00662,  -4.7
0.00661,  -5.4
0.00662,  -4.8
0.00661,  -5.4
0.00660,  -4.8
0.00662,  -5.5
0.00662,  -6.1
0.00662,  -4.9
0.00663,  -4.8
0.00662,  -4.5
0.00661,  -5.3
0.00660,  -5.4
0.00661,  -5.2
0.00661,  -5.1
0.00661,  -5.5
0.00660,  -4.5
0.00660,  -5.0
0.00661,  -5.5
0.00661,  -5.1
0.00661,  -4.1
0.00662,  -5.1
0.00662,  -5.0
0.00662,  -5.7
0.00662,  -5.1
0.00664,  -5.7
0.00662,  -7.0
0.00663,  -4.5
0.00662,  -6.2
0.00664,  -5.6
0.00662,  -6.1
0.00661,  -6.2
0.00662,  -5.7
0.00662,  -5.3
0.00662,  -5.5
0.00660,  -5.6
0.00663,  -5.5
0.00662,  -5.2
0.00662,  -5.7
0.00662,  -5.4
0.00663,  -4.6
0.00663,  -5.0
0.00662,  -5.3
0.00661,  -4.4
0.00663,  -4.4
0.00659,  -4.9
0.00663,  -5.0
0.00663,  -4.8
0.00663,  -4.4
0.00664,  -3.8
0.00663,  -5.1
0.00663,  -5.7
0.00661,  -5.1
0.00662,  -5.8
0.00663,  -5.0
0.00664,  -5.5
0.00662,  -5.0
0.00663,  -5.3
0.00663,  -5.3
0.00662,  -5.0
0.00664,  -5.4
0.00662,  -5.1
0.00662,  -4.6
0.00662,  -5.1
0.00663,  -4.6
0.00663,  -5.1
0.00663,  -5.5
0.00664,  -5.2
0.00662,  -4.7
0.00662,  -6.4
0.00663,  -5.6
0.00663,  -5.1
0.00662,  -5.6
0.00661,  -5.3
0.00661,  -5.7
0.00663,  -4.9
0.00662,  -5.0
0.00661,  -5.2
0.00661,  -5.7
0.00663,  -5.6
0.00663,  -5.3
0.00660,  -6.0
0.00662,  -4.8
0.00662,  -5.8
0.00660,  -4.6
0.00662,  -4.8
0.00662,  -5.5
0.00662,  -5.6
0.00662,  -5.3
0.00661,  -5.2
0.00662,  -5.6
0.00661,  -5.4
0.00661,  -4.9
0.00661,  -6.0
0.00662,  -5.5
0.00662,  -6.0
0.00661,  -4.4
0.00661,  -5.0
0.00661,  -5.0
0.00662,  -4.2
0.00662,  -5.3
0.00661,  -4.7
0.00661,  -5.2
0.00662,  -5.3
0.00662,  -4.3
0.00661,  -5.1
0.00660,  -4.2
0.00662,  -5.9
0.00662,  -4.9
0.00662,  -5.7
0.00661,  -5.8
0.00661,  -6.0
0.00663,  -4.5
0.00662,  -4.8
0.00663,  -5.6
0.00661,  -5.2
0.00663,  -5.7
0.00661,  -4.9
0.00661,  -4.8
0.00661,  -4.1
0.00663,  -4.4
0.00662,  -5.4
0.00660,  -6.1
0.00662,  -6.6
0.00662,  -4.8
0.00662,  -5.4
0.00660,  -4.7
0.00660,  -5.2
0.00662,  -4.9
0.00660,  -4.4
0.00664,  -5.6
0.00661,  -5.5
0.00659,  -5.1
0.00661,  -5.4
0.00661,  -5.2
0.00663,  -5.0
0.00662,  -4.8
0.00661,  -5.0
0.00661,  -5.5
0.00662,  -5.3
0.00663,  -4.9
0.00661,  -6.5
0.00662,  -5.6
0.00663,  -5.6
0.00663,  -5.8
0.00661,  -5.1
0.00660,  -5.7
0.00661,  -4.6
0.00663,  -5.5
0.00662,  -4.4
0.00661,  -4.9
0.00663,  -4.9
0.00663,  -5.5
0.00661,  -5.1
0.00662,  -5.6
0.00662,  -6.3
0.00661,  -5.1
0.00660,  -5.2
0.00660,  -4.5
0.00659,  -4.8
0.00660,  -3.9
0.00661,  -4.4
0.00661,  -5.3
0.00658,  -4.2
0.00660,  -4.8
0.00658,  -5.6
0.00659,  -4.9
0.00659,  -4.6
0.00659,  -4.8
0.00660,  -3.9
0.00660,  -4.9
0.00660,  -4.5
0.00659,  -4.9
0.00659,  -2.1
0.00659,  -1.8
0.00658,  -3.5
0.00660,  -4.5
0.00658,  -5.1
0.00659,  -5.1
0.00659,  -4.8
0.00659,  -5.0
0.00660,  -4.6
0.00658,  -4.7
0.00658,  -4.2
0.00660,  -5.5
0.00659,  -4.3
0.00659,  -5.6
0.00661,  -6.1
0.00661,  -5.7
0.00661,  -5.7
0.00660,  -5.7
0.00659,  -6.5
0.00661,  -5.2
0.00659,  -6.1
0.00661,  -4.9
0.00660,  -5.6
0.00660,  -5.0
0.00661,  -6.5
0.00660,  -5.2
0.00661,  -2.3
0.00660,  -1.2
0.00660,  -1.9
0.00660,  -0.4
0.00661,   0.6
0.00658,   2.0
0.00660,   2.6
0.00661,   0.4
0.00661,   0.7
0.00661,  -0.2
0.00660,  -0.9
0.00662,   0.3
0.00658,  -1.1
0.00660,  -0.5
0.00660,  -0.6
0.00660,  -3.0
0.00658,  -0.2
0.00658,  -2.0
0.00660,  -3.6
0.00659,  -1.1
0.00659,  -1.4
0.00659,  -5.1
0.00661,  -6.0
0.00661,  -6.2
0.00660,  -7.0
0.00659,  -5.5
0.00661,  -5.4
0.00659,  -5.4
0.00660,  -6.0
0.00659,  -5.9
0.00658,  -4.6
0.00660,  -5.5
0.00661,  -4.9
0.00661,  -4.8
0.00660,  -5.5
0.00660,  -5.5
0.00660,  -6.2
0.00659,  -6.5
0.00661,  -5.6
0.00660,  -5.8
0.00661,  -5.1
0.00660,  -5.9
0.00660,  -6.2
0.00661,  -4.1
0.00659,  -6.2
0.00661,  -6.3
0.00662,  -6.3
0.00661,  -5.7
0.00663,  -5.6
0.00662,  -5.1
0.00661,  -5.8
0.00660,  -5.3
0.00660,  -4.3
0.00661,  -5.8
0.00660,  -6.2
0.00661,  -5.5
0.00660,  -6.1
0.00660,  -4.8
0.00660,  -6.2
0.00662,  -5.0
0.00660,  -4.5
0.00661,  -5.4
0.00660,  -4.1
0.00662,  -5.3
0.00660,  -3.6
0.00660,  -3.9
0.00659,  -2.9
0.00661,  -6.0
0.00659,  -5.2
0.00661,  -5.7
0.00661,  -5.3
0.00661,  -5.3
0.00660,  -5.0
0.00661,  -6.0
0.00659,  -4.7
0.00660,  -5.1
0.00662,  -5.5
0.00660,  -5.9
0.00658,  -5.2
0.00661,  -5.8
0.00661,  -5.8
0.00660,  -5.9
0.00660,  -5.8
0.00660,  -5.5
0.00660,  -4.6
0.00663,  -5.5
0.00661,  -4.1
0.00660,  -4.3
0.00660,  -3.8
0.00661,  -5.1
0.00660,  -4.8
0.00660,  -1.8
0.00661,  -3.7
0.00661,  -6.2
0.00659, -10.2
0.00661,  -3.6
0.00661,  -9.9
0.00659,  -1.7
0.00659,  -1.9
0.00660,  -2.8
0.00660,  -3.8
0.00662,  -4.6
0.00659,  -3.8
0.00659,  -5.3
0.00659,  -5.4
0.00659,  -4.1
0.00661,  -4.5
0.00660,  -4.1
0.00660,  -5.7
0.00663,  -4.6
0.00660,  -4.2
0.00661,  -4.9
0.00662,  -4.7
0.00661,  -5.2
0.00660,  -4.4
0.00660,  -3.3
0.00660,  -5.1
0.00660,  -4.0
0.00661,  -5.7
0.00659,  -5.8
0.00661,  -5.1
0.00659,  -4.0
0.00659,  -4.6
0.00658,  -0.8
0.00660,  -2.4
0.00661,  -2.8
0.00660,  -4.3
0.00661,  -5.3
0.00659,  -5.0
0.00660,  -4.4
0.00660,  -5.1
0.00658,  -4.9
0.00659,  -4.1
0.00660,  -3.5
0.00659,  -9.8
0.00659,  -4.6
0.00660, -10.6
0.00659,  -4.1
0.00659,  -3.1
0.00661,  -4.3
0.00662,  -2.1
0.00661,  -3.3
0.00660,  -3.6
0.00659,  -4.8
0.00659,  -3.2
0.00661,  -3.2
0.00659,  -2.6
0.00660,  -2.3
0.00659,  -2.2
0.00659,  -2.5
0.00659,  -2.5
0.00659,  -2.2
0.00659,  -2.5
0.00660,  -1.4
0.00657,  -1.6
0.00658,  -2.9
0.00659,  -1.9
0.00659,  -2.8
0.00659,  -1.2
0.00658,  -2.4
0.00660,  -2.6
0.00660,  -1.7
0.00661,  -2.5
0.00660,  -1.2
0.00659,  -1.7
0.00660,  -2.5
0.00659,  -2.0
0.00659,  -1.9
0.00658,  -0.8
0.00660,  -1.2
0.00741,  -1.9
0.00710,  -2.1
0.00645,  -1.6
0.00690,  -2.3
0.00680,  -2.7
0.00565,  -1.1
0.00566,  -2.1
0.00630,  -1.3
0.00681,  -1.0
0.00661,  -1.7
0.00649,  -2.0
0.00774,  -2.0
0.00766,  -0.8
0.00644,  -1.5
0.00596,  -0.9
0.00565,  -0.7
0.00426,  -1.1
0.00389,  -1.8
0.00295,  -1.9
0.00385,  -2.2
0.00443,  -2.1
0.00437,  -1.4
0.00334,  -0.7
0.00361,  -1.1
0.00277,  -2.2
0.00093,  -1.5
-0.00788,  -2.5
0.00431,  -1.8
-0.00834,  -0.4
-0.01248,  -1.0
-0.01094,  -0.1
-0.01009,  -0.8
-0.00908,   0.0
-0.00823,  -0.7
-0.00786,  -0.8
-0.00750,  -1.3
-0.00679,  -0.7
-0.00891,  -1.2
-0.00822,  -0.3
-0.00766,  -2.1
-0.00679,  -1.0
-0.00415,  -2.0
-0.00180,  -1.7
0.00013,  -2.7
-0.00070,  -1.0
0.00014,  -1.2
0.00015,  -2.4
0.00018,  -1.5
0.00018,  -2.3
0.00018,  -1.6
0.00091,  -1.5
-0.01424,  -1.8
-0.01530,  -1.7
-0.01527,  -0.4
-0.01529,  -2.0
-0.01527,  -1.8
-0.01525,  -0.7
-0.01527,  -1.2
-0.01527,  -0.7
-0.01527,  -1.9
-0.01528,  -1.2