File: MAE_3272/Module_1/Group1-T6 Aluminum.csv
2/12/2016
3:45 PM
Sampling Frequency:,10Hz
Group:,Group1
Extensometer:,E85191
Sample:,T6 Aluminum
Sample width [inch]:,0.499000
Sample thickness [inch]:,0.124000
--------,--------

Extensometer,Load
[Inches],[Lbs]
0.00001,   0.3
0.00001,  -0.5
0.00001,   0.6
0.00001,   1.7
0.00001,  -0.4
0.00001,   1.0
0.00001,   0.2
0.00001,  -1.3
0.00002,  -1.0
0.00002,  -0.8
0.00002,   0.0
0.00001,  -0.5
0.00003,   0.4
0.00000,  -0.3
0.00002,   1.3
0.00003,   0.4
0.00001,   0.8
0.00003,   3.2
0.00006,   4.5
0.00004,   7.4
0.00003,   6.1
0.00003,   7.8
0.00004,   7.6
0.00004,   7.8
0.00005,   7.0
0.00004,   7.8
0.00004,   7.7
0.00003,   7.6
0.00004,   8.0
0.00004,   7.1
0.00004,   7.4
0.00004,   8.4
0.00004,   8.7
0.00003,   7.5
0.00004,   8.5
0.00004,   8.3
0.00004,  10.1
0.00004,   9.0
0.00003,   9.4
0.00004,   8.6
0.00004,   9.9
0.00004,   8.8
0.00004,   9.5
0.00004,   8.7
0.00005,  10.1
0.00005,   9.5
0.00002,   8.6
0.00004,   8.7
0.00003,   9.7
0.00004,  10.9
0.00003,   9.2
0.00003,  10.6
0.00002,   9.4
0.00003,  12.2
0.00003,  11.5
0.00001,  12.0
0.00001,  13.0
0.00001,  13.2
0.00002,  14.6
0.00002,  14.1
-0.00000,  14.9
0.00002,  14.7
0.00002,  15.4
0.00004,  15.5
0.00004,  15.7
0.00002,  17.1
0.00003,  18.6
0.00002,  17.5
0.00003,  19.2
0.00004,  19.1
0.00005,  21.7
0.00005,  22.6
0.00006,  24.7
0.00007,  26.0
0.00006,  27.9
0.00008,  29.3
0.00008,  31.0
0.00011,  33.2
0.00011,  34.8
0.00011,  38.1
0.00012,  39.5
0.00013,  41.4
0.00016,  44.7
0.00016,  48.3
0.00016,  50.5
0.00017,  53.3
0.00018,  57.3
0.00020,  59.8
0.00021,  64.0
0.00021,  67.1
0.00023,  71.3
0.00025,  75.7
0.00027,  80.6
0.00027,  84.9
0.00029,  90.1
0.00032,  95.4
0.00033, 100.6
0.00035, 106.7
0.00036, 112.4
0.00039, 118.7
0.00042, 124.9
0.00044, 132.2
0.00045, 137.9
0.00049, 144.6
0.00050, 151.8
0.00052, 158.5
0.00053, 165.8
0.00056, 171.7
0.00058, 180.6
0.00062, 185.9
0.00065, 195.6
0.00065, 202.6
0.00069, 209.9
0.00071, 219.2
0.00073, 227.7
0.00079, 234.7
0.00080, 245.2
0.00082, 255.3
0.00086, 263.1
0.00089, 273.2
0.00092, 283.6
0.00095, 292.5
0.00099, 301.6
0.00103, 310.9
0.00106, 321.0
0.00110, 332.4
0.00114, 341.8
0.00116, 350.8
0.00121, 361.4
0.00123, 370.9
0.00126, 381.4
0.00131, 390.5
0.00132, 403.0
0.00136, 412.7
0.00141, 427.0
0.00144, 436.9
0.00149, 447.7
0.00153, 458.6
0.00158, 470.6
0.00161, 482.9
0.00165, 495.3
0.00170, 508.3
0.00176, 521.7
0.00179, 535.8
0.00182, 548.7
0.00189, 561.9
0.00194, 576.5
0.00197, 592.2
0.00204, 607.7
0.00209, 622.2
0.00214, 636.5
0.00217, 651.2
0.00224, 664.7
0.00227, 678.9
0.00233, 692.6
0.00234, 706.0
0.00239, 718.6
0.00245, 732.6
0.00250, 748.3
0.00255, 763.2
0.00260, 779.3
0.00265, 794.5
0.00271, 810.2
0.00277, 826.3
0.00280, 842.2
0.00285, 857.2
0.00291, 874.2
0.00297, 889.6
0.00301, 906.5
0.00308, 923.6
0.00314, 940.0
0.00320, 956.0
0.00326, 972.0
0.00332, 990.5
0.00338,1007.5
0.00344,1024.6
0.00349,1042.3
0.00355,1059.4
0.00362,1079.3
0.00369,1100.8
0.00376,1123.0
0.00384,1145.6
0.00394,1169.0
0.00400,1194.0
0.00406,1217.2
0.00414,1241.1
0.00423,1264.7
0.00431,1289.6
0.00438,1313.7
0.00448,1338.4
0.00458,1365.4
0.00465,1391.6
0.00474,1419.2
0.00484,1449.1
0.00493,1476.8
0.00504,1504.8
0.00511,1531.8
0.00522,1560.9
0.00532,1591.3
0.00544,1619.4
0.00552,1648.5
0.00563,1677.7
0.00573,1706.9
0.00584,1736.9
0.00593,1764.8
0.00605,1797.0
0.00616,1825.0
0.00626,1855.8
0.00638,1886.4
0.00650,1915.2
0.00659,1944.2
0.00671,1973.9
0.00683,2004.2
0.00694,2033.2
0.00708,2064.3
0.00719,2093.7
0.00731,2124.1
0.00743,2154.3
0.00760,2182.5
0.00774,2212.2
0.00787,2242.0
0.00803,2270.4
0.00819,2298.5
0.00838,2325.1
0.00860,2351.8
0.00882,2376.1
0.00910,2398.5
0.00947,2415.5
0.00988,2433.8
0.01036,2446.6
0.01088,2460.1
0.01142,2471.6
0.01201,2481.6
0.01263,2491.5
0.01329,2498.7
0.01398,2505.6
0.01469,2511.4
0.01541,2515.9
0.01619,2521.1
0.01701,2524.2
0.01783,2526.5
0.01870,2529.2
0.01957,2530.8
0.02047,2533.4
0.02137,2534.5
0.02228,2536.6
0.02319,2536.9
0.02408,2539.1
0.02500,2541.2
0.02595,2543.2
0.02689,2543.6
0.02780,2544.1
0.02872,2546.8
0.02963,2547.1
0.03050,2546.9
0.03126,2548.2
0.03192,2547.1
0.03252,2548.0
0.03310,2548.2
0.03364,2550.9
0.03420,2552.1
0.03475,2552.7
0.03532,2553.9
0.03584,2554.2
0.03642,2556.7
0.03696,2557.0
0.03751,2559.0
0.03808,2558.9
0.03860,2559.2
0.03915,2561.4
0.03971,2562.1
0.04023,2561.6
0.04077,2563.0
0.04132,2564.3
0.04186,2565.3
0.04241,2566.2
0.04292,2566.9
0.04346,2567.3
0.04402,2568.7
0.04453,2569.7
0.04508,2569.7
0.04560,2570.0
0.04611,2571.9
0.04667,2574.7
0.04727,2576.5
0.04792,2577.2
0.04858,2577.6
0.04922,2578.4
0.04991,2578.8
0.05055,2580.4
0.05121,2581.5
0.05186,2582.5
0.05251,2583.7
0.05313,2584.5
0.05380,2584.9
0.05443,2585.9
0.05509,2586.4
0.05572,2589.4
0.05636,2590.0
0.05703,2590.7
0.05767,2592.4
0.05830,2592.9
0.05896,2594.5
0.05959,2595.8
0.06021,2596.3
0.06086,2597.0
0.06150,2598.1
0.06211,2599.1
0.06275,2600.7
0.06337,2600.9
0.06400,2603.8
0.06464,2603.0
0.06525,2604.5
0.06587,2606.0
0.06651,2606.3
0.06714,2607.4
0.06776,2609.1
0.06840,2611.3
0.06902,2611.2
0.06964,2612.8
0.07026,2612.9
0.07088,2615.0
0.07151,2616.2
0.07213,2615.9
0.07273,2616.7
0.07334,2618.3
0.07396,2620.5
0.07458,2621.1
0.07519,2621.2
0.07580,2621.9
0.07642,2623.2
0.07703,2624.3
0.07765,2624.8
0.07826,2625.2
0.07889,2627.5
0.07949,2628.8
0.08011,2629.0
0.08072,2629.7
0.08135,2629.8
0.08196,2632.3
0.08261,2633.3
0.08321,2633.5
0.08382,2634.0
0.08446,2635.6
0.08507,2635.9
0.08567,2636.5
0.08630,2637.6
0.08688,2639.2
0.08751,2640.3
0.08812,2640.2
0.08873,2640.4
0.08934,2642.1
0.08995,2643.2
0.09056,2642.9
0.09118,2644.5
0.09183,2645.5
0.09242,2646.9
0.09303,2647.0
0.09367,2648.6
0.09429,2648.8
0.09494,2649.4
0.09556,2649.2
0.09616,2652.1
0.09678,2652.1
0.09741,2652.2
0.09803,2654.6
0.09865,2653.1
0.09926,2655.3
0.09989,2654.7
0.10052,2655.3
0.10115,2657.2
0.10175,2657.5
0.10237,2659.2
0.10299,2659.3
0.10360,2660.2
0.10422,2660.2
0.10484,2661.3
0.10548,2661.6
0.10609,2661.2
0.10671,2663.1
0.10738,2662.8
0.10800,2664.5
0.10862,2664.7
0.10925,2665.4
0.10988,2666.3
0.11052,2667.0
0.11116,2667.1
0.11179,2667.9
0.11240,2669.0
0.11305,2668.0
0.11366,2669.1
0.11431,2670.5
0.11495,2670.7
0.11560,2671.7
0.11622,2672.3
0.11685,2672.3
0.11748,2673.2
0.11810,2672.7
0.11872,2673.5
0.11935,2675.0
0.11999,2674.5
0.12065,2675.9
0.12130,2676.5
0.12193,2676.4
0.12255,2676.9
0.12320,2677.6
0.12386,2677.8
0.12449,2677.6
0.12512,2679.3
0.12575,2678.0
0.12640,2679.4
0.12702,2679.0
0.12764,2680.4
0.12827,2681.4
0.12892,2681.6
0.12953,2681.5
0.13016,2681.2
0.13081,2681.5
0.13143,2683.5
0.13208,2684.1
0.13274,2682.9
0.13339,2684.0
0.13405,2683.6
0.13470,2684.4
0.13533,2683.5
0.13598,2684.3
0.13663,2684.6
0.13729,2684.7
0.13794,2685.4
0.13859,2685.3
0.13924,2684.4
0.13991,2685.8
0.14055,2686.0
0.14121,2687.3
0.14187,2687.2
0.14251,2686.2
0.14316,2686.7
0.14383,2688.6
0.14449,2686.1
0.14514,2687.4
0.14581,2686.4
0.14647,2687.7
0.14714,2688.7
0.14781,2688.4
0.14850,2688.9
0.14915,2688.9
0.14980,2688.6
0.15048,2689.3
0.15116,2687.8
0.15183,2688.7
0.15251,2688.5
0.15320,2689.1
0.15385,2688.4
0.15453,2689.5
0.15521,2689.6
0.15589,2689.3
0.15657,2689.0
0.15725,2689.5
0.15793,2689.1
0.15860,2689.9
0.15931,2689.6
0.16000,2689.4
0.16071,2688.9
0.16141,2689.6
0.16213,2688.9
0.16282,2688.9
0.16353,2689.1
0.16423,2688.3
0.16494,2688.0
0.16568,2688.5
0.16637,2688.3
0.16707,2689.0
0.16780,2687.0
0.16852,2687.8
0.16922,2687.5
0.16994,2686.7
0.17070,2687.7
0.17142,2686.1
0.17215,2685.6
0.17285,2686.3
0.17360,2685.7
0.17435,2685.8
0.17509,2684.4
0.17586,2684.8
0.17662,2684.2
0.17737,2682.6
0.17813,2681.9
0.17887,2680.4
0.17962,2679.7
0.18038,2679.4
0.18116,2678.0
0.18194,2676.9
0.18275,2674.4
0.18354,2673.7
0.18432,2672.3
0.18510,2670.4
0.18586,2668.4
0.18667,2665.3
0.18747,2663.8
0.18829,2660.5
0.18914,2657.4
0.18993,2654.1
0.19074,2650.4
0.19157,2646.7
0.19240,2641.9
0.19322,2637.2
0.19407,2632.7
0.19489,2628.0
0.19576,2622.3
0.19661,2615.8
0.19744,2610.3
0.19829,2604.5
0.19914,2596.6
0.19998,2590.6
0.20084,2583.3
0.20168,2577.0
0.20253,2569.0
0.20339,2561.0
0.20426,2553.3
0.20513,2545.0
0.20601,2537.3
0.20689,2528.9
0.20776,2518.9
0.20863,2509.8
0.20953,2501.0
0.21043,2490.3
0.21131,2481.4
0.21220,2471.9
0.21308,2462.4
0.21398,2450.5
0.21488,2440.3
0.21575,2428.8
0.21666,2416.9
0.21755,2405.9
0.21846,2394.2
0.21936,2382.8
0.22023,2369.5
0.22115,2358.4
0.22208,2344.4
0.22299,2331.1
0.22391,2316.5
0.22481,2304.3
0.22575,2288.8
0.22670,2274.0
0.22753,2259.4
0.22828,2245.6
0.22901,2233.5
0.22973,2220.5
0.23044,2206.8
0.23120,2194.3
0.23192,2179.0
0.23268,2162.4
0.23343,2147.1
0.23419,2131.4
0.23496,2113.6
0.23576,2096.4
0.23656,2076.6
0.23737,2053.9
0.23870,1979.2
0.32581, -10.1
0.35837,  -9.2
0.35582,  -8.3
0.35626,  -7.6
0.35689,  -7.2
0.35748,  -6.9
0.35807,  -6.0
0.35843,  -6.6
0.35843,  -6.2
0.35844,  -5.5
0.35842,  -4.9
0.35843,  -5.0
0.35841,  -5.7
0.35843,  -5.5
0.35843,  -4.4
0.35842,  -4.4
0.35842,  -5.0
0.35840,  -4.1
0.35840,  -4.5
0.35838,  -4.6
0.35839,  -4.1
0.35839,  -3.6
0.35839,  -4.9
0.35837,  -4.0
0.35836,  -3.4
0.35838,  -3.2
0.35838,  -2.7
0.35837,  -4.6
0.35837,  -4.4
0.35838,  -3.4
0.35837,  -4.0
0.35835,  -3.5
0.35835,  -2.6
0.35834,  -3.1
0.35835,  -2.5
0.35769,  -3.4
0.35814,  -3.6
0.35852,  -3.3
0.34116,  -3.7
0.23275,  -3.2
-0.36249,  -3.7
-0.35482,  -3.7
-0.34043,  -3.5
-0.34206,  -3.5
-0.33857,  -4.3
-0.34405,  -3.0
-0.34186,  -3.2
-0.34110,  -3.8
-0.32432,  -3.3
-0.11079,  -4.5
-0.11614,  -3.6
-0.11513,  -3.2
-0.11839,  -2.5
-0.11004,  -2.8
-0.11000,  -3.1
-0.08531,  -2.5
-0.08067,  -2.8
-0.07731,  -2.6
-0.08802,  -3.3
-0.18252,  -2.7
-0.20292,  -3.3
-0.24768,  -2.4
-0.03357,  -2.0
0.07467,  -3.3
0.05763,  -3.4
0.08304,  -3.9
0.06907,  -3.9
0.00570,  -3.1
-0.01149,  -2.1
-0.02618,  -2.5
-0.05300,  -3.3
-0.07441,  -3.6
-0.07691,  -3.7
-0.08559,  -3.2
-0.05798,  -3.4
-0.05414,  -2.5
-0.05835,  -2.6
-0.17943,  -2.6
-0.17075,  -3.0
-0.08932,  -2.0
0.01684,  -3.2
0.01558,  -2.9
0.01896,  -2.9
0.00986,  -3.4
0.01052,  -2.4
0.01363,  -2.8
0.01649,  -3.1
0.01432,  -2.8
0.01585,  -4.1
0.01626,  -3.1
0.01555,  -3.0
0.01556,  -2.9
0.01558,  -2.3
0.01558,  -3.3
0.01557,  -2.6
0.01558,  -1.5
0.01558,  -0.7
0.01557,   1.6
0.01558,   1.4
0.01557,   1.6
0.01557,  -1.2
0.01556,  -3.3
0.01556,  -2.9
0.01558,  -2.0
0.01557,  -2.1
0.01558,  -2.5
0.01558,  -2.3
0.01556,  -2.4
0.01558,  -2.0
0.01558,  -3.0
0.01556,  -1.2
0.01556,  -2.5
0.01557,  -1.8
0.01557,  -2.0
0.01556,  -2.7
0.01558,  -1.8
0.01557,  -3.1
0.01558,  -2.4
0.01559,  -2.1
0.01558,  -1.9
0.01557,  -2.3
0.01556,  -1.8
0.01556,  -2.6
0.01557,  -2.0
0.01557,  -2.1
0.01556,  -2.2
0.01556,  -2.0
0.01557,  -2.6
0.01558,  -1.8
0.01557,  -1.7
0.01556,  -2.0
0.01559,  -2.1
0.01557,  -2.1
0.01558,  -1.8
0.01556,  -1.7
0.01557,  -3.3
0.01557,  -1.5
0.01557,  -2.8
0.01557,  -1.8
0.01556,  -2.2
0.01556,  -2.1
0.01555,  -1.3
0.01558,  -1.7
0.01556,  -1.4
0.01556,  -1.8
0.01557,  -2.9
0.01557,  -1.5
0.01558,  -1.8
0.01556,  -1.7
0.01558,  -2.4
0.01556,  -3.0
0.01557,  -1.9
0.01556,  -2.5
0.01555,  -1.7
0.01556,  -3.0
0.01558,  -2.1
0.01557,  -2.1
0.01557,  -2.3
0.01557,  -2.4
0.01556,  -2.0
0.01557,  -2.0
0.01556,  -2.8
0.01556,  -2.3
0.01556,  -2.9
0.01556,  -2.5
0.01558,  -2.8
0.01556,  -2.2
0.01556,  -2.4
0.01557,  -1.6
0.01556,  -2.4
0.01557,  -2.3
0.01557,  -2.1
0.01556,  -1.8
0.01556,  -1.9
0.01557,  -1.3
0.01556,  -1.5
0.01557,  -1.3
0.01557,  -2.3
0.01558,  -1.7
0.01556,  -1.4
0.01557,  -2.3
0.01556,  -1.1
0.01556,  -2.7
0.01556,  -1.2
0.01555,  -2.1
0.01555,  -1.9
0.01556,  -1.6
0.01556,  -0.8
0.01557,  -2.3
0.01556,  -2.7
0.01554,  -1.6
0.01555,  -2.0
0.01556,  -1.7
0.01556,  -1.8
0.01555,  -1.1
0.01555,  -1.1
0.01555,  -2.6
0.01557,  -2.0
0.01556,  -1.0
0.01555,  -1.1
0.01556,  -1.1
0.01558,  -2.6
0.01556,  -2.7
0.01556,  -1.8
0.01556,  -1.0
0.01557,  -1.8
0.01554,  -2.0
0.01555,  -1.8
0.01555,  -1.6
0.01555,  -1.4
0.01556,  -3.7
0.01556,  -2.6
0.01557,  -2.4
0.01556,  -1.2
0.01555,  -1.9
0.01557,  -1.4
0.01558,  -2.2
0.01556,  -0.9
0.01555,  -2.2
0.01556,  -2.1
0.01556,  -1.3
0.01556,  -1.6
0.01555,  -0.7
0.01556,  -1.5
0.01556,  -2.6
0.01555,  -1.0
0.01555,  -2.5
0.01556,  -2.3
0.01555,  -1.4
0.01556,  -0.4
0.01556,  -1.6
0.01557,  -2.5
0.01557,  -1.0
0.01555,  -2.4
0.01556,  -1.3
0.01555,  -1.3
0.01555,  -1.7
0.01556,  -1.6
0.01556,  -2.4
0.01556,  -2.0
0.01555,  -1.9
0.01557,  -2.3
0.01556,  -2.2
0.01556,  -1.9
0.01556,  -1.9
0.01556,  -1.6
0.01554,  -1.7
0.01556,  -1.6
0.01555,  -1.0
0.01557,  -2.6
0.01554,  -1.5
0.01555,  -0.6
0.01553,  -0.3
0.01557,  -1.5
0.01556,  -1.5
0.01554,  -1.1
0.01555,  -0.5
0.01555,  -1.2
0.01555,  -0.6
0.01554,  -0.9
0.01557,  -2.3
0.01557,  -1.5
0.01556,  -0.6
0.01556,  -1.9
0.01554,  -1.1
0.01557,  -1.2
0.01555,  -1.9
0.01556,  -1.3
0.01556,  -1.5
0.01555,  -2.3
0.01556,  -2.1
0.01554,  -1.8
0.01554,  -1.0
0.01556,  -1.5
0.01557,  -1.8
0.01555,  -1.8
0.01554,  -1.6
0.01555,  -1.1
0.01556,  -1.0
0.01557,  -1.8
0.01555,  -1.3
0.01555,  -1.1
0.01556,  -1.3
0.01555,  -1.5
0.01557,  -2.0
0.01557,  -2.6
0.01556,  -1.4
0.01555,  -1.5
0.01556,  -1.8
0.01556,  -2.0
0.01556,  -1.7
0.01555,  -1.9
0.01556,  -1.2
0.01555,  -1.2
0.01556,  -1.4
0.01558,  -0.8
0.01555,  -1.6
0.01556,  -0.5
0.01555,  -1.1
0.01557,  -2.0
0.01556,  -1.5
0.01557,  -2.0
0.01555,  -1.1
0.01556,  -0.8
0.01556,  -1.2
0.01556,  -1.8
0.01556,  -2.0
0.01556,  -1.9
0.01555,  -2.8
0.01555,  -1.5
0.01555,  -2.5
0.01555,  -1.9
0.01555,  -2.3
0.01555,  -1.3
0.01555,  -1.3
0.01555,  -1.8
0.01555,  -1.0
0.01555,  -1.4
0.01556,  -2.5
0.01553,  -2.5
0.01556,  -1.3
0.01555,  -0.7
0.01556,  -1.9
0.01555,  -2.5
0.01555,  -1.4
0.01555,  -0.7
0.01557,  -2.3
0.01555,  -2.2
0.01554,  -1.8
0.01557,  -1.2
0.01559,  -1.4
0.01561,  -1.1
0.01560,  -1.0
0.01559,  -0.8
0.01558,  -0.6
0.01558,   0.4
0.01560,  -1.8
0.01559,  -1.8
0.01560,  -1.3
0.01559,  -1.5
0.01559,  -1.2
0.01560,  -1.4
0.01560,  -0.7
0.01561,  -0.9
0.01559,  -1.7
0.01560,  -1.0
0.01561,  -1.5
0.01559,  -1.3
0.01559,  -2.0
0.01560,  -1.6
0.01559,  -1.0
0.01561,  -0.6
0.01559,  -1.1
0.01559,  -0.9
0.01560,  -1.2
0.01560,  -2.0
0.01561,  -1.7
0.01560,  -1.6
0.01560,  -2.8
0.01560,  -1.2
0.01559,  -1.9
0.01560,  -1.3
0.01560,  -1.7
0.01560,  -2.4
0.01560,  -1.8
0.01560,  -1.9
0.01560,  -1.3
0.01558,  -1.3
0.01560,  -2.1
0.01559,  -0.9
0.01561,  -1.1
0.01559,  -1.9
0.01561,  -1.2
0.01558,  -1.1
0.01559,  -1.2
0.01560,  -1.4
0.01559,  -1.0
0.01558,  -1.3
0.01560,  -1.6
0.01559,  -0.6
0.01561,  -1.8
0.01560,  -1.6
0.01560,  -0.9
0.01559,  -1.6
0.01558,  -1.8
0.01560,  -0.4
0.01559,  -2.3
0.01558,  -2.0
0.01559,  -0.8
0.01559,  -1.2
0.01559,  -1.6
0.01559,  -1.5
0.01559,  -1.6
0.01558,  -1.1
0.01559,  -0.8
0.01561,  -1.4
0.01559,  -0.9
0.01560,  -1.7
0.01560,  -0.9
0.01559,  -0.8
0.01559,  -1.1
0.01558,  -1.2
0.01559,  -1.0
0.01559,  -1.6
0.01559,  -2.9
0.01561,  -1.8
0.01559,  -2.2
0.01558,  -1.6
0.01558,  -1.8
0.01558,  -1.2
0.01558,  -1.5
0.01559,  -2.9
0.01559,  -3.2
0.01559,  -1.0
0.01558,  -1.5
0.01559,  -1.0
0.01558,  -1.8
0.01561,  -1.3
0.01558,  -1.3
0.01559,  -0.4
0.01558,  -1.9
0.01558,  -0.5
0.01559,  -1.4
0.01559,  -1.3
0.01559,  -0.7
0.01561,  -1.1
0.01560,  -0.5
0.01560,  -0.8
0.01559,  -1.3
0.01560,  -1.6
0.01560,  -2.6
0.01560,  -0.9
0.01560,  -1.4
0.01559,  -1.5
0.01560,  -0.6
0.01560,  -0.9
0.01558,  -0.5
0.01560,  -1.7
0.01560,  -2.6
0.01558,  -1.1
0.01558,  -1.2
0.01560,  -0.9
0.01559,  -1.8
0.01559,  -1.5
0.01559,  -1.9
0.01558,  -2.0
0.01558,  -1.0
0.01558,  -1.0
0.01559,  -2.2
0.01558,  -1.9
0.01559,  -1.4
0.01559,  -1.7
0.01558,  -1.6
0.01558,  -0.5
0.01559,  -1.5
0.01558,  -2.2
0.01558,  -1.1
0.01558,  -1.1
0.01559,  -1.6
0.01557,  -1.1
0.01560,  -0.8
0.01558,  -0.9
0.01558,  -1.7
0.01558,  -1.5
0.01557,  -1.0
0.01555,  -1.6
0.01557,  -0.9
0.01560,  -1.1
0.01559,  -1.3
0.01558,  -1.5
0.01558,  -1.3
0.01559,  -0.9
0.01559,  -0.6
0.01560,  -1.0
0.01559,  -1.6
0.01558,  -1.5
0.01558,  -1.3
0.01558,  -2.3
0.01561,  -1.8
0.01561,  -2.1
0.01561,  -2.1
0.01560,  -1.9
0.01560,  -1.1
0.01558,  -2.2
0.01560,  -1.5
0.01558,  -1.7
0.01560,  -1.9
0.01559,  -1.4
0.01560,  -0.8
0.01559,  -1.6
0.01558,  -1.0
0.01560,  -1.9
0.01561,  -1.5
0.01559,  -1.0
0.01559,  -0.9
0.01556,  -1.3
0.01560,  -0.8
0.01560,  -0.8
0.01559,  -1.5
0.01559,  -1.2
0.01559,  -2.3
0.01559,  -1.2
0.01560,  -1.0
0.01561,  -2.5
0.01561,  -0.3
0.01559,  -0.6
0.01561,  -1.5
0.01560,  -0.6
0.01561,  -1.5
0.01560,  -1.2
0.01561,  -1.7
0.01561,  -1.6
0.01561,  -1.3
0.01557,  -1.9
0.01560,  -1.3
0.01560,  -2.4
0.01560,  -1.6
0.01560,  -2.2
0.01557,  -2.7
0.01559,  -1.9
0.01558,  -1.4
0.01560,  -1.5
0.01559,  -1.3
0.01560,  -2.5
0.01560,  -2.1
0.01556,  -2.0
0.01558,  -1.6
0.01558,  -1.7
0.01558,  -1.6
0.01559,  -0.4
0.01558,  -1.4
0.01557,  -2.5
0.01558,  -1.3
0.01560,  -2.1
0.01558,  -1.4
0.01559,  -2.1
0.01561,  -0.4
0.01558,  -1.5
0.01559,  -1.3
0.01558,  -1.1
0.01558,  -3.1
0.01558,  -2.1
0.01558,  -1.1
0.01559,  -1.4
0.01560,  -0.8
0.01560,  -1.8
0.01558,  -1.1
0.01560,  -1.5
0.01560,  -3.0
0.01559,  -2.6
0.01559,  -0.9
0.01558,  -0.9
0.01558,  -0.5
0.01558,  -1.5
0.01559,  -1.5
0.01560,  -1.4
0.01559,  -1.4
0.01559,  -1.1
0.01560,  -1.1
0.01559,  -2.1
0.01559,  -1.8
0.01558,  -1.8
0.01558,  -2.2
0.01557,  -0.6
0.01556,  -1.9
0.01558,  -0.1
0.01557,  -1.8
0.01556,  -2.1
0.01558,  -1.1
0.01559,  -0.4
0.01560,  -1.3
0.01558,  -1.6
0.01558,  -0.5
0.01559,  -1.4
0.01559,  -1.0
0.01559,  -1.1
0.01557,  -0.6
0.01558,  -1.3
0.01559,  -2.1
0.01559,  -1.9
0.01559,  -1.9
0.01560,  -1.0
0.01558,  -0.7
0.01557,  -1.2
0.01558,  -0.3
0.01557,  -1.3
0.01559,  -1.8
0.01557,  -2.3
0.01558,  -1.6
0.01558,  -1.5
0.01558,  -0.3
0.01558,  -1.1
0.01558,  -0.4
0.01559,  -1.6
0.01559,  -2.1
0.01558,  -0.6
0.01558,  -1.8
0.01559,  -1.3
0.01558,  -0.8
0.01558,  -1.0
0.01559,  -1.2
0.01558,  -1.5
0.01558,  -2.0
0.01558,  -1.9
0.01557,  -1.9
0.01559,  -1.4
0.01559,  -1.4
0.01559,  -1.1
0.01558,  -2.0
0.01559,  -1.7
0.01559,  -0.7
0.01559,  -1.5
0.01559,  -1.9
0.01558,  -0.8
0.01558,  -1.7
0.01557,  -1.2
0.01556,  -0.3
0.01557,  -0.8
0.01557,  -0.1
0.01559,  -1.2
0.01558,  -1.3
0.01558,  -0.7
0.01558,  -0.7
0.01556,  -1.4
0.01557,  -0.3
0.01558,  -1.4
0.01557,  -1.6
0.01556,  -1.8
0.01556,  -1.3
0.01556,  -2.9
0.01556,  -1.4
0.01557,  -1.1
0.01557,  -1.8
0.01557,  -0.9
0.01557,  -0.8
0.01558,  -1.5
0.01557,  -3.1
0.01557,  -0.6
0.01557,  -2.0
0.01558,  -1.3
0.01557,  -1.5
0.01559,  -1.1
0.01558,  -0.3
0.01557,   0.2
0.01559,  -1.1
0.01559,  -0.1
0.01557,  -0.5
0.01555,  -0.7
0.01558,  -1.0
0.01557,  -1.1
0.01559,  -1.5
0.01559,  -0.0
0.01557,  -1.1
0.01558,  -1.3
0.01557,  -1.3
0.01556,  -1.3
0.01558,  -1.6
0.01558,  -0.2
0.01558,  -1.9
0.01558,  -2.3
0.01557,  -2.3
0.01558,  -1.8
0.01557,  -0.2
0.01558,  -0.8
0.01557,  -0.5
0.01557,  -0.9
0.01559,  -1.0
0.01559,  -1.9
0.01557,  -1.1
0.01557,  -1.5
0.01558,  -1.4
0.01557,  -1.6
0.01557,  -0.9
0.01555,  -0.6
0.01559,  -0.2
0.01557,  -1.2
0.01559,  -1.1
0.01557,  -2.1
0.01558,  -2.0
0.01556,  -0.9
0.01557,  -1.6
0.01558,  -1.1
0.01557,  -1.9
0.01558,  -2.0
0.01557,  -2.2
0.01557,  -1.3
0.01557,  -2.7
0.01559,  -0.4
0.01557,  -2.4
0.01558,  -1.9
0.01556,  -1.5
0.01557,  -1.4
0.01558,  -2.2
0.01557,  -1.3
0.01557,  -1.7
0.01558,  -1.6
0.01558,  -1.7
0.01556,  -1.2
0.01558,  -1.8
0.01557,  -1.7
0.01556,  -1.1
0.01557,  -0.6
0.01557,  -1.7
0.01558,  -0.5
0.01557,  -1.3
0.01559,  -1.3
0.01559,  -0.7
0.01558,  -1.4
0.01557,  -1.3
0.01557,  -0.9
0.01559,  -2.0
0.01558,  -1.1
0.01558,  -2.3
0.01558,  -2.2
0.01558,  -1.2
0.01558,  -2.8
0.01559,  -1.6
0.01558,  -1.8
0.01558,  -1.9
0.01558,  -1.5
0.01559,  -1.1
0.01559,  -1.8
0.01557,  -1.8
0.01558,  -1.6
0.01557,  -0.3
0.01558,  -1.0
0.01557,  -1.2
0.01557,  -0.9
0.01557,  -1.4
0.01557,  -0.6
0.01559,  -1.6
0.01560,  -2.0
0.01556,  -1.3
0.01556,  -0.9
0.01558,  -1.8
0.01559,  -1.2
0.01559,  -1.6
0.01557,  -1.5
0.01558,  -2.3
0.01557,  -1.2
0.01557,  -1.1
0.01558,  -0.4
0.01556,  -1.2
0.01559,  -1.0
0.01557,  -2.0
0.01556,  -1.1
0.01557,  -2.1
0.01558,  -1.2
0.01558,  -2.5
0.01557,  -1.5
0.01557,  -1.6
0.01558,  -1.7
0.01559,  -1.6
0.01558,  -2.1
0.01558,  -1.6
0.01558,  -2.0
0.01558,  -1.0
0.01558,  -0.7
0.01559,  -1.5
0.01559,  -0.9
0.01558,  -1.2
0.01558,  -0.4
0.01557,  -1.3
0.01559,  -1.9
0.01560,  -1.1
0.01559,  -0.4
0.01560,  -1.3
0.01562,  -1.5
0.01559,  -1.8
0.01560,  -2.4
0.01560,  -1.0
0.01559,  -1.4
0.01558,  -1.1
0.01560,  -1.4
0.01559,  -0.5
0.01559,  -0.7
0.01560,  -1.9
0.01560,  -0.9
0.01559,  -1.2
0.01559,  -1.4
0.01560,  -2.5
0.01559,  -0.7
0.01560,  -1.5
0.01558,  -1.5
0.01559,  -1.3
0.01557,  -0.5
0.01558,  -0.8
0.01560,  -1.4
0.01558,  -0.4
0.01559,  -0.0
0.01559,  -0.8
0.01559,  -0.7
0.01560,  -1.0
0.01559,  -1.2
0.01560,  -1.2
0.01559,  -0.8
0.01559,  -1.1
0.01557,  -0.5
0.01557,  -1.7
0.01558,  -0.9
0.01559,  -1.9
0.01559,  -2.1
0.01557,  -1.3
0.01559,  -1.2
0.01560,  -0.6
0.01559,  -1.7
0.01557,  -1.4
0.01558,  -0.8
0.01558,  -1.0
0.01560,  -1.3
0.01559,  -1.1
0.01559,  -0.5
0.01560,  -1.5
0.01559,  -1.2
0.01559,  -1.9
0.01559,  -2.4
0.01558,  -1.3
0.01558,  -1.2
0.01559,  -2.5
0.01559,  -2.1
0.01558,  -1.0
0.01558,  -1.2
0.01558,  -1.8
0.01559,  -1.2
0.01559,  -0.9
0.01559,  -0.4
0.01558,  -1.5